{
  "version": 8,
  "blockIdVersion": 11,
  "anchorX": 0,
  "anchorY": -4,
  "anchorZ": -4,
  "blocks": [
    {
      "x": -4,
      "y": -4,
      "z": -4,
      "name": "Rock_Marble"
    },
    {
      "x": -4,
      "y": -3,
      "z": -4,
      "name": "Rock_Marble"
    },
    {
      "x": -4,
      "y": -2,
      "z": -4,
      "name": "Rock_Marble"
    },
    {
      "x": -4,
      "y": -1,
      "z": -4,
      "name": "Rock_Marble"
    },
    {
      "x": -4,
      "y": 0,
      "z": -4,
      "name": "Rock_Marble"
    },
    {
      "x": -4,
      "y": 1,
      "z": -4,
      "name": "Rock_Marble"
    },
    {
      "x": -4,
      "y": 2,
      "z": -4,
      "name": "Rock_Marble"
    },
    {
      "x": -4,
      "y": 3,
      "z": -4,
      "name": "Rock_Marble"
    },
    {
      "x": -4,
      "y": 4,
      "z": -4,
      "name": "Rock_Marble"
    },
    {
      "x": -4,
      "y": -4,
      "z": -3,
      "name": "Rock_Stone"
    },
    {
      "x": -4,
      "y": -3,
      "z": -3,
      "name": "Rock_Stone"
    },
    {
      "x": -4,
      "y": -2,
      "z": -3,
      "name": "Rock_Stone"
    },
    {
      "x": -4,
      "y": -1,
      "z": -3,
      "name": "Rock_Stone"
    },
    {
      "x": -4,
      "y": 0,
      "z": -3,
      "name": "Rock_Stone"
    },
    {
      "x": -4,
      "y": 1,
      "z": -3,
      "name": "Rock_Stone"
    },
    {
      "x": -4,
      "y": 2,
      "z": -3,
      "name": "Rock_Stone"
    },
    {
      "x": -4,
      "y": 3,
      "z": -3,
      "name": "Rock_Stone"
    },
    {
      "x": -4,
      "y": 4,
      "z": -3,
      "name": "Rock_Stone"
    },
    {
      "x": -4,
      "y": -4,
      "z": -2,
      "name": "Rock_Stone"
    },
    {
      "x": -4,
      "y": -3,
      "z": -2,
      "name": "Rock_Stone"
    },
    {
      "x": -4,
      "y": -2,
      "z": -2,
      "name": "Rock_Stone"
    },
    {
      "x": -4,
      "y": -1,
      "z": -2,
      "name": "Rock_Stone"
    },
    {
      "x": -4,
      "y": 0,
      "z": -2,
      "name": "Rock_Stone"
    },
    {
      "x": -4,
      "y": 1,
      "z": -2,
      "name": "Rock_Stone"
    },
    {
      "x": -4,
      "y": 2,
      "z": -2,
      "name": "Rock_Stone"
    },
    {
      "x": -4,
      "y": 3,
      "z": -2,
      "name": "Rock_Stone"
    },
    {
      "x": -4,
      "y": 4,
      "z": -2,
      "name": "Rock_Stone"
    },
    {
      "x": -4,
      "y": -4,
      "z": -1,
      "name": "Rock_Stone"
    },
    {
      "x": -4,
      "y": -3,
      "z": -1,
      "name": "Rock_Stone"
    },
    {
      "x": -4,
      "y": -2,
      "z": -1,
      "name": "Rock_Stone"
    },
    {
      "x": -4,
      "y": -1,
      "z": -1,
      "name": "Rock_Stone"
    },
    {
      "x": -4,
      "y": 0,
      "z": -1,
      "name": "Rock_Stone"
    },
    {
      "x": -4,
      "y": 1,
      "z": -1,
      "name": "Rock_Stone"
    },
    {
      "x": -4,
      "y": 2,
      "z": -1,
      "name": "Rock_Stone"
    },
    {
      "x": -4,
      "y": 3,
      "z": -1,
      "name": "Rock_Stone"
    },
    {
      "x": -4,
      "y": 4,
      "z": -1,
      "name": "Rock_Stone"
    },
    {
      "x": -4,
      "y": -4,
      "z": 0,
      "name": "Rock_Stone"
    },
    {
      "x": -4,
      "y": -3,
      "z": 0,
      "name": "Rock_Stone"
    },
    {
      "x": -4,
      "y": -2,
      "z": 0,
      "name": "Rock_Stone"
    },
    {
      "x": -4,
      "y": -1,
      "z": 0,
      "name": "Rock_Stone"
    },
    {
      "x": -4,
      "y": 0,
      "z": 0,
      "name": "Rock_Stone"
    },
    {
      "x": -4,
      "y": 1,
      "z": 0,
      "name": "Rock_Stone"
    },
    {
      "x": -4,
      "y": 2,
      "z": 0,
      "name": "Rock_Stone"
    },
    {
      "x": -4,
      "y": 3,
      "z": 0,
      "name": "Rock_Stone"
    },
    {
      "x": -4,
      "y": 4,
      "z": 0,
      "name": "Rock_Stone"
    },
    {
      "x": -4,
      "y": -4,
      "z": 1,
      "name": "Rock_Stone"
    },
    {
      "x": -4,
      "y": -3,
      "z": 1,
      "name": "Rock_Stone"
    },
    {
      "x": -4,
      "y": -2,
      "z": 1,
      "name": "Rock_Stone"
    },
    {
      "x": -4,
      "y": -1,
      "z": 1,
      "name": "Rock_Stone"
    },
    {
      "x": -4,
      "y": 0,
      "z": 1,
      "name": "Rock_Stone"
    },
    {
      "x": -4,
      "y": 1,
      "z": 1,
      "name": "Rock_Stone"
    },
    {
      "x": -4,
      "y": 2,
      "z": 1,
      "name": "Rock_Stone"
    },
    {
      "x": -4,
      "y": 3,
      "z": 1,
      "name": "Rock_Stone"
    },
    {
      "x": -4,
      "y": 4,
      "z": 1,
      "name": "Rock_Stone"
    },
    {
      "x": -4,
      "y": -4,
      "z": 2,
      "name": "Rock_Stone"
    },
    {
      "x": -4,
      "y": -3,
      "z": 2,
      "name": "Rock_Stone"
    },
    {
      "x": -4,
      "y": -2,
      "z": 2,
      "name": "Rock_Stone"
    },
    {
      "x": -4,
      "y": -1,
      "z": 2,
      "name": "Rock_Stone"
    },
    {
      "x": -4,
      "y": 0,
      "z": 2,
      "name": "Rock_Stone"
    },
    {
      "x": -4,
      "y": 1,
      "z": 2,
      "name": "Rock_Stone"
    },
    {
      "x": -4,
      "y": 2,
      "z": 2,
      "name": "Rock_Stone"
    },
    {
      "x": -4,
      "y": 3,
      "z": 2,
      "name": "Rock_Stone"
    },
    {
      "x": -4,
      "y": 4,
      "z": 2,
      "name": "Rock_Stone"
    },
    {
      "x": -4,
      "y": -4,
      "z": 3,
      "name": "Rock_Stone"
    },
    {
      "x": -4,
      "y": -3,
      "z": 3,
      "name": "Rock_Stone"
    },
    {
      "x": -4,
      "y": -2,
      "z": 3,
      "name": "Rock_Stone"
    },
    {
      "x": -4,
      "y": -1,
      "z": 3,
      "name": "Rock_Stone"
    },
    {
      "x": -4,
      "y": 0,
      "z": 3,
      "name": "Rock_Stone"
    },
    {
      "x": -4,
      "y": 1,
      "z": 3,
      "name": "Rock_Stone"
    },
    {
      "x": -4,
      "y": 2,
      "z": 3,
      "name": "Rock_Stone"
    },
    {
      "x": -4,
      "y": 3,
      "z": 3,
      "name": "Rock_Stone"
    },
    {
      "x": -4,
      "y": 4,
      "z": 3,
      "name": "Rock_Stone"
    },
    {
      "x": -4,
      "y": -4,
      "z": 4,
      "name": "Rock_Stone"
    },
    {
      "x": -4,
      "y": -3,
      "z": 4,
      "name": "Rock_Stone"
    },
    {
      "x": -4,
      "y": -2,
      "z": 4,
      "name": "Rock_Stone"
    },
    {
      "x": -4,
      "y": -1,
      "z": 4,
      "name": "Rock_Stone"
    },
    {
      "x": -4,
      "y": 0,
      "z": 4,
      "name": "Rock_Stone"
    },
    {
      "x": -4,
      "y": 1,
      "z": 4,
      "name": "Rock_Stone"
    },
    {
      "x": -4,
      "y": 2,
      "z": 4,
      "name": "Rock_Stone"
    },
    {
      "x": -4,
      "y": 3,
      "z": 4,
      "name": "Rock_Stone"
    },
    {
      "x": -4,
      "y": 4,
      "z": 4,
      "name": "Rock_Stone"
    },
    {
      "x": -3,
      "y": -4,
      "z": -4,
      "name": "Rock_Marble"
    },
    {
      "x": -3,
      "y": -3,
      "z": -4,
      "name": "Rock_Marble"
    },
    {
      "x": -3,
      "y": -2,
      "z": -4,
      "name": "Rock_Marble"
    },
    {
      "x": -3,
      "y": -1,
      "z": -4,
      "name": "Rock_Marble"
    },
    {
      "x": -3,
      "y": 0,
      "z": -4,
      "name": "Rock_Marble"
    },
    {
      "x": -3,
      "y": 1,
      "z": -4,
      "name": "Rock_Marble"
    },
    {
      "x": -3,
      "y": 2,
      "z": -4,
      "name": "Rock_Marble"
    },
    {
      "x": -3,
      "y": 3,
      "z": -4,
      "name": "Rock_Marble"
    },
    {
      "x": -3,
      "y": 4,
      "z": -4,
      "name": "Rock_Marble"
    },
    {
      "x": -3,
      "y": -4,
      "z": -3,
      "name": "Rock_Stone"
    },
    {
      "x": -3,
      "y": 4,
      "z": -3,
      "name": "Rock_Stone"
    },
    {
      "x": -3,
      "y": -4,
      "z": -2,
      "name": "Rock_Stone"
    },
    {
      "x": -3,
      "y": 4,
      "z": -2,
      "name": "Rock_Stone"
    },
    {
      "x": -3,
      "y": -4,
      "z": -1,
      "name": "Rock_Stone"
    },
    {
      "x": -3,
      "y": 4,
      "z": -1,
      "name": "Rock_Stone"
    },
    {
      "x": -3,
      "y": -4,
      "z": 0,
      "name": "Rock_Stone"
    },
    {
      "x": -3,
      "y": 4,
      "z": 0,
      "name": "Rock_Stone"
    },
    {
      "x": -3,
      "y": -4,
      "z": 1,
      "name": "Rock_Stone"
    },
    {
      "x": -3,
      "y": 4,
      "z": 1,
      "name": "Rock_Stone"
    },
    {
      "x": -3,
      "y": -4,
      "z": 2,
      "name": "Rock_Stone"
    },
    {
      "x": -3,
      "y": 4,
      "z": 2,
      "name": "Rock_Stone"
    },
    {
      "x": -3,
      "y": -4,
      "z": 3,
      "name": "Rock_Stone"
    },
    {
      "x": -3,
      "y": 4,
      "z": 3,
      "name": "Rock_Stone"
    },
    {
      "x": -3,
      "y": -4,
      "z": 4,
      "name": "Rock_Stone"
    },
    {
      "x": -3,
      "y": -3,
      "z": 4,
      "name": "Rock_Stone"
    },
    {
      "x": -3,
      "y": -2,
      "z": 4,
      "name": "Rock_Stone"
    },
    {
      "x": -3,
      "y": -1,
      "z": 4,
      "name": "Rock_Stone"
    },
    {
      "x": -3,
      "y": 0,
      "z": 4,
      "name": "Rock_Stone"
    },
    {
      "x": -3,
      "y": 1,
      "z": 4,
      "name": "Rock_Stone"
    },
    {
      "x": -3,
      "y": 2,
      "z": 4,
      "name": "Rock_Stone"
    },
    {
      "x": -3,
      "y": 3,
      "z": 4,
      "name": "Rock_Stone"
    },
    {
      "x": -3,
      "y": 4,
      "z": 4,
      "name": "Rock_Stone"
    },
    {
      "x": -2,
      "y": -4,
      "z": -4,
      "name": "Rock_Marble"
    },
    {
      "x": -2,
      "y": -3,
      "z": -4,
      "name": "Rock_Marble"
    },
    {
      "x": -2,
      "y": -2,
      "z": -4,
      "name": "Rock_Marble"
    },
    {
      "x": -2,
      "y": -1,
      "z": -4,
      "name": "Rock_Marble"
    },
    {
      "x": -2,
      "y": 0,
      "z": -4,
      "name": "Rock_Marble"
    },
    {
      "x": -2,
      "y": 1,
      "z": -4,
      "name": "Rock_Marble"
    },
    {
      "x": -2,
      "y": 2,
      "z": -4,
      "name": "Rock_Marble"
    },
    {
      "x": -2,
      "y": 3,
      "z": -4,
      "name": "Rock_Marble"
    },
    {
      "x": -2,
      "y": 4,
      "z": -4,
      "name": "Rock_Marble"
    },
    {
      "x": -2,
      "y": -4,
      "z": -3,
      "name": "Rock_Stone"
    },
    {
      "x": -2,
      "y": 4,
      "z": -3,
      "name": "Rock_Stone"
    },
    {
      "x": -2,
      "y": -4,
      "z": -2,
      "name": "Rock_Stone"
    },
    {
      "x": -2,
      "y": 4,
      "z": -2,
      "name": "Rock_Stone"
    },
    {
      "x": -2,
      "y": -4,
      "z": -1,
      "name": "Rock_Stone"
    },
    {
      "x": -2,
      "y": 4,
      "z": -1,
      "name": "Rock_Stone"
    },
    {
      "x": -2,
      "y": -4,
      "z": 0,
      "name": "Rock_Stone"
    },
    {
      "x": -2,
      "y": 4,
      "z": 0,
      "name": "Rock_Stone"
    },
    {
      "x": -2,
      "y": -4,
      "z": 1,
      "name": "Rock_Stone"
    },
    {
      "x": -2,
      "y": 4,
      "z": 1,
      "name": "Rock_Stone"
    },
    {
      "x": -2,
      "y": -4,
      "z": 2,
      "name": "Rock_Stone"
    },
    {
      "x": -2,
      "y": 4,
      "z": 2,
      "name": "Rock_Stone"
    },
    {
      "x": -2,
      "y": -4,
      "z": 3,
      "name": "Rock_Stone"
    },
    {
      "x": -2,
      "y": 4,
      "z": 3,
      "name": "Rock_Stone"
    },
    {
      "x": -2,
      "y": -4,
      "z": 4,
      "name": "Rock_Stone"
    },
    {
      "x": -2,
      "y": -3,
      "z": 4,
      "name": "Rock_Stone"
    },
    {
      "x": -2,
      "y": -2,
      "z": 4,
      "name": "Rock_Stone"
    },
    {
      "x": -2,
      "y": -1,
      "z": 4,
      "name": "Rock_Stone"
    },
    {
      "x": -2,
      "y": 0,
      "z": 4,
      "name": "Rock_Stone"
    },
    {
      "x": -2,
      "y": 1,
      "z": 4,
      "name": "Rock_Stone"
    },
    {
      "x": -2,
      "y": 2,
      "z": 4,
      "name": "Rock_Stone"
    },
    {
      "x": -2,
      "y": 3,
      "z": 4,
      "name": "Rock_Stone"
    },
    {
      "x": -2,
      "y": 4,
      "z": 4,
      "name": "Rock_Stone"
    },
    {
      "x": -1,
      "y": -4,
      "z": -4,
      "name": "Rock_Marble"
    },
    {
      "x": -1,
      "y": -3,
      "z": -4,
      "name": "Rock_Marble"
    },
    {
      "x": -1,
      "y": -2,
      "z": -4,
      "name": "Rock_Marble"
    },
    {
      "x": -1,
      "y": -1,
      "z": -4,
      "name": "Rock_Marble"
    },
    {
      "x": -1,
      "y": 0,
      "z": -4,
      "name": "Rock_Marble"
    },
    {
      "x": -1,
      "y": 1,
      "z": -4,
      "name": "Rock_Marble"
    },
    {
      "x": -1,
      "y": 2,
      "z": -4,
      "name": "Rock_Marble"
    },
    {
      "x": -1,
      "y": 3,
      "z": -4,
      "name": "Rock_Marble"
    },
    {
      "x": -1,
      "y": 4,
      "z": -4,
      "name": "Rock_Marble"
    },
    {
      "x": -1,
      "y": -4,
      "z": -3,
      "name": "Rock_Stone"
    },
    {
      "x": -1,
      "y": 4,
      "z": -3,
      "name": "Rock_Stone"
    },
    {
      "x": -1,
      "y": -4,
      "z": -2,
      "name": "Rock_Stone"
    },
    {
      "x": -1,
      "y": 4,
      "z": -2,
      "name": "Rock_Stone"
    },
    {
      "x": -1,
      "y": -4,
      "z": -1,
      "name": "Rock_Stone"
    },
    {
      "x": -1,
      "y": 4,
      "z": -1,
      "name": "Rock_Stone"
    },
    {
      "x": -1,
      "y": -4,
      "z": 0,
      "name": "Rock_Stone"
    },
    {
      "x": -1,
      "y": 4,
      "z": 0,
      "name": "Rock_Stone"
    },
    {
      "x": -1,
      "y": -4,
      "z": 1,
      "name": "Rock_Stone"
    },
    {
      "x": -1,
      "y": 4,
      "z": 1,
      "name": "Rock_Stone"
    },
    {
      "x": -1,
      "y": -4,
      "z": 2,
      "name": "Rock_Stone"
    },
    {
      "x": -1,
      "y": 4,
      "z": 2,
      "name": "Rock_Stone"
    },
    {
      "x": -1,
      "y": -4,
      "z": 3,
      "name": "Rock_Stone"
    },
    {
      "x": -1,
      "y": 4,
      "z": 3,
      "name": "Rock_Stone"
    },
    {
      "x": -1,
      "y": -4,
      "z": 4,
      "name": "Rock_Stone"
    },
    {
      "x": -1,
      "y": -3,
      "z": 4,
      "name": "Rock_Stone"
    },
    {
      "x": -1,
      "y": -2,
      "z": 4,
      "name": "Rock_Stone"
    },
    {
      "x": -1,
      "y": -1,
      "z": 4,
      "name": "Rock_Stone"
    },
    {
      "x": -1,
      "y": 0,
      "z": 4,
      "name": "Rock_Stone"
    },
    {
      "x": -1,
      "y": 1,
      "z": 4,
      "name": "Rock_Stone"
    },
    {
      "x": -1,
      "y": 2,
      "z": 4,
      "name": "Rock_Stone"
    },
    {
      "x": -1,
      "y": 3,
      "z": 4,
      "name": "Rock_Stone"
    },
    {
      "x": -1,
      "y": 4,
      "z": 4,
      "name": "Rock_Stone"
    },
    {
      "x": 0,
      "y": -4,
      "z": -4,
      "name": "Rock_Marble"
    },
    {
      "x": 0,
      "y": -3,
      "z": -4,
      "name": "Rock_Marble"
    },
    {
      "x": 0,
      "y": -2,
      "z": -4,
      "name": "Rock_Marble"
    },
    {
      "x": 0,
      "y": -1,
      "z": -4,
      "name": "Rock_Marble"
    },
    {
      "x": 0,
      "y": 0,
      "z": -4,
      "name": "Rock_Marble"
    },
    {
      "x": 0,
      "y": 1,
      "z": -4,
      "name": "Rock_Marble"
    },
    {
      "x": 0,
      "y": 2,
      "z": -4,
      "name": "Rock_Marble"
    },
    {
      "x": 0,
      "y": 3,
      "z": -4,
      "name": "Rock_Marble"
    },
    {
      "x": 0,
      "y": 4,
      "z": -4,
      "name": "Rock_Marble"
    },
    {
      "x": 0,
      "y": -4,
      "z": -3,
      "name": "Rock_Stone"
    },
    {
      "x": 0,
      "y": 4,
      "z": -3,
      "name": "Rock_Stone"
    },
    {
      "x": 0,
      "y": -4,
      "z": -2,
      "name": "Rock_Stone"
    },
    {
      "x": 0,
      "y": 4,
      "z": -2,
      "name": "Rock_Stone"
    },
    {
      "x": 0,
      "y": -4,
      "z": -1,
      "name": "Rock_Stone"
    },
    {
      "x": 0,
      "y": 4,
      "z": -1,
      "name": "Rock_Stone"
    },
    {
      "x": 0,
      "y": -4,
      "z": 0,
      "name": "Rock_Stone"
    },
    {
      "x": 0,
      "y": 4,
      "z": 0,
      "name": "Rock_Stone"
    },
    {
      "x": 0,
      "y": -4,
      "z": 1,
      "name": "Rock_Stone"
    },
    {
      "x": 0,
      "y": 4,
      "z": 1,
      "name": "Rock_Stone"
    },
    {
      "x": 0,
      "y": -4,
      "z": 2,
      "name": "Rock_Stone"
    },
    {
      "x": 0,
      "y": 4,
      "z": 2,
      "name": "Rock_Stone"
    },
    {
      "x": 0,
      "y": -4,
      "z": 3,
      "name": "Rock_Stone"
    },
    {
      "x": 0,
      "y": 4,
      "z": 3,
      "name": "Rock_Stone"
    },
    {
      "x": 0,
      "y": -4,
      "z": 4,
      "name": "Rock_Stone"
    },
    {
      "x": 0,
      "y": -3,
      "z": 4,
      "name": "Rock_Stone"
    },
    {
      "x": 0,
      "y": -2,
      "z": 4,
      "name": "Rock_Stone"
    },
    {
      "x": 0,
      "y": -1,
      "z": 4,
      "name": "Rock_Stone"
    },
    {
      "x": 0,
      "y": 0,
      "z": 4,
      "name": "Rock_Stone"
    },
    {
      "x": 0,
      "y": 1,
      "z": 4,
      "name": "Rock_Stone"
    },
    {
      "x": 0,
      "y": 2,
      "z": 4,
      "name": "Rock_Stone"
    },
    {
      "x": 0,
      "y": 3,
      "z": 4,
      "name": "Rock_Stone"
    },
    {
      "x": 0,
      "y": 4,
      "z": 4,
      "name": "Rock_Stone"
    },
    {
      "x": 1,
      "y": -4,
      "z": -4,
      "name": "Rock_Marble"
    },
    {
      "x": 1,
      "y": -3,
      "z": -4,
      "name": "Rock_Marble"
    },
    {
      "x": 1,
      "y": -2,
      "z": -4,
      "name": "Rock_Marble"
    },
    {
      "x": 1,
      "y": -1,
      "z": -4,
      "name": "Rock_Marble"
    },
    {
      "x": 1,
      "y": 0,
      "z": -4,
      "name": "Rock_Marble"
    },
    {
      "x": 1,
      "y": 1,
      "z": -4,
      "name": "Rock_Marble"
    },
    {
      "x": 1,
      "y": 2,
      "z": -4,
      "name": "Rock_Marble"
    },
    {
      "x": 1,
      "y": 3,
      "z": -4,
      "name": "Rock_Marble"
    },
    {
      "x": 1,
      "y": 4,
      "z": -4,
      "name": "Rock_Marble"
    },
    {
      "x": 1,
      "y": -4,
      "z": -3,
      "name": "Rock_Stone"
    },
    {
      "x": 1,
      "y": 4,
      "z": -3,
      "name": "Rock_Stone"
    },
    {
      "x": 1,
      "y": -4,
      "z": -2,
      "name": "Rock_Stone"
    },
    {
      "x": 1,
      "y": 4,
      "z": -2,
      "name": "Rock_Stone"
    },
    {
      "x": 1,
      "y": -4,
      "z": -1,
      "name": "Rock_Stone"
    },
    {
      "x": 1,
      "y": 4,
      "z": -1,
      "name": "Rock_Stone"
    },
    {
      "x": 1,
      "y": -4,
      "z": 0,
      "name": "Rock_Stone"
    },
    {
      "x": 1,
      "y": 4,
      "z": 0,
      "name": "Rock_Stone"
    },
    {
      "x": 1,
      "y": -4,
      "z": 1,
      "name": "Rock_Stone"
    },
    {
      "x": 1,
      "y": 4,
      "z": 1,
      "name": "Rock_Stone"
    },
    {
      "x": 1,
      "y": -4,
      "z": 2,
      "name": "Rock_Stone"
    },
    {
      "x": 1,
      "y": 4,
      "z": 2,
      "name": "Rock_Stone"
    },
    {
      "x": 1,
      "y": -4,
      "z": 3,
      "name": "Rock_Stone"
    },
    {
      "x": 1,
      "y": 4,
      "z": 3,
      "name": "Rock_Stone"
    },
    {
      "x": 1,
      "y": -4,
      "z": 4,
      "name": "Rock_Stone"
    },
    {
      "x": 1,
      "y": -3,
      "z": 4,
      "name": "Rock_Stone"
    },
    {
      "x": 1,
      "y": -2,
      "z": 4,
      "name": "Rock_Stone"
    },
    {
      "x": 1,
      "y": -1,
      "z": 4,
      "name": "Rock_Stone"
    },
    {
      "x": 1,
      "y": 0,
      "z": 4,
      "name": "Rock_Stone"
    },
    {
      "x": 1,
      "y": 1,
      "z": 4,
      "name": "Rock_Stone"
    },
    {
      "x": 1,
      "y": 2,
      "z": 4,
      "name": "Rock_Stone"
    },
    {
      "x": 1,
      "y": 3,
      "z": 4,
      "name": "Rock_Stone"
    },
    {
      "x": 1,
      "y": 4,
      "z": 4,
      "name": "Rock_Stone"
    },
    {
      "x": 2,
      "y": -4,
      "z": -4,
      "name": "Rock_Marble"
    },
    {
      "x": 2,
      "y": -3,
      "z": -4,
      "name": "Rock_Marble"
    },
    {
      "x": 2,
      "y": -2,
      "z": -4,
      "name": "Rock_Marble"
    },
    {
      "x": 2,
      "y": -1,
      "z": -4,
      "name": "Rock_Marble"
    },
    {
      "x": 2,
      "y": 0,
      "z": -4,
      "name": "Rock_Marble"
    },
    {
      "x": 2,
      "y": 1,
      "z": -4,
      "name": "Rock_Marble"
    },
    {
      "x": 2,
      "y": 2,
      "z": -4,
      "name": "Rock_Marble"
    },
    {
      "x": 2,
      "y": 3,
      "z": -4,
      "name": "Rock_Marble"
    },
    {
      "x": 2,
      "y": 4,
      "z": -4,
      "name": "Rock_Marble"
    },
    {
      "x": 2,
      "y": -4,
      "z": -3,
      "name": "Rock_Stone"
    },
    {
      "x": 2,
      "y": 4,
      "z": -3,
      "name": "Rock_Stone"
    },
    {
      "x": 2,
      "y": -4,
      "z": -2,
      "name": "Rock_Stone"
    },
    {
      "x": 2,
      "y": 4,
      "z": -2,
      "name": "Rock_Stone"
    },
    {
      "x": 2,
      "y": -4,
      "z": -1,
      "name": "Rock_Stone"
    },
    {
      "x": 2,
      "y": 4,
      "z": -1,
      "name": "Rock_Stone"
    },
    {
      "x": 2,
      "y": -4,
      "z": 0,
      "name": "Rock_Stone"
    },
    {
      "x": 2,
      "y": 4,
      "z": 0,
      "name": "Rock_Stone"
    },
    {
      "x": 2,
      "y": -4,
      "z": 1,
      "name": "Rock_Stone"
    },
    {
      "x": 2,
      "y": 4,
      "z": 1,
      "name": "Rock_Stone"
    },
    {
      "x": 2,
      "y": -4,
      "z": 2,
      "name": "Rock_Stone"
    },
    {
      "x": 2,
      "y": 4,
      "z": 2,
      "name": "Rock_Stone"
    },
    {
      "x": 2,
      "y": -4,
      "z": 3,
      "name": "Rock_Stone"
    },
    {
      "x": 2,
      "y": 4,
      "z": 3,
      "name": "Rock_Stone"
    },
    {
      "x": 2,
      "y": -4,
      "z": 4,
      "name": "Rock_Stone"
    },
    {
      "x": 2,
      "y": -3,
      "z": 4,
      "name": "Rock_Stone"
    },
    {
      "x": 2,
      "y": -2,
      "z": 4,
      "name": "Rock_Stone"
    },
    {
      "x": 2,
      "y": -1,
      "z": 4,
      "name": "Rock_Stone"
    },
    {
      "x": 2,
      "y": 0,
      "z": 4,
      "name": "Rock_Stone"
    },
    {
      "x": 2,
      "y": 1,
      "z": 4,
      "name": "Rock_Stone"
    },
    {
      "x": 2,
      "y": 2,
      "z": 4,
      "name": "Rock_Stone"
    },
    {
      "x": 2,
      "y": 3,
      "z": 4,
      "name": "Rock_Stone"
    },
    {
      "x": 2,
      "y": 4,
      "z": 4,
      "name": "Rock_Stone"
    },
    {
      "x": 3,
      "y": -4,
      "z": -4,
      "name": "Rock_Marble"
    },
    {
      "x": 3,
      "y": -3,
      "z": -4,
      "name": "Rock_Marble"
    },
    {
      "x": 3,
      "y": -2,
      "z": -4,
      "name": "Rock_Marble"
    },
    {
      "x": 3,
      "y": -1,
      "z": -4,
      "name": "Rock_Marble"
    },
    {
      "x": 3,
      "y": 0,
      "z": -4,
      "name": "Rock_Marble"
    },
    {
      "x": 3,
      "y": 1,
      "z": -4,
      "name": "Rock_Marble"
    },
    {
      "x": 3,
      "y": 2,
      "z": -4,
      "name": "Rock_Marble"
    },
    {
      "x": 3,
      "y": 3,
      "z": -4,
      "name": "Rock_Marble"
    },
    {
      "x": 3,
      "y": 4,
      "z": -4,
      "name": "Rock_Marble"
    },
    {
      "x": 3,
      "y": -4,
      "z": -3,
      "name": "Rock_Stone"
    },
    {
      "x": 3,
      "y": 4,
      "z": -3,
      "name": "Rock_Stone"
    },
    {
      "x": 3,
      "y": -4,
      "z": -2,
      "name": "Rock_Stone"
    },
    {
      "x": 3,
      "y": 4,
      "z": -2,
      "name": "Rock_Stone"
    },
    {
      "x": 3,
      "y": -4,
      "z": -1,
      "name": "Rock_Stone"
    },
    {
      "x": 3,
      "y": 4,
      "z": -1,
      "name": "Rock_Stone"
    },
    {
      "x": 3,
      "y": -4,
      "z": 0,
      "name": "Rock_Stone"
    },
    {
      "x": 3,
      "y": 4,
      "z": 0,
      "name": "Rock_Stone"
    },
    {
      "x": 3,
      "y": -4,
      "z": 1,
      "name": "Rock_Stone"
    },
    {
      "x": 3,
      "y": 4,
      "z": 1,
      "name": "Rock_Stone"
    },
    {
      "x": 3,
      "y": -4,
      "z": 2,
      "name": "Rock_Stone"
    },
    {
      "x": 3,
      "y": 4,
      "z": 2,
      "name": "Rock_Stone"
    },
    {
      "x": 3,
      "y": -4,
      "z": 3,
      "name": "Rock_Stone"
    },
    {
      "x": 3,
      "y": 4,
      "z": 3,
      "name": "Rock_Stone"
    },
    {
      "x": 3,
      "y": -4,
      "z": 4,
      "name": "Rock_Stone"
    },
    {
      "x": 3,
      "y": -3,
      "z": 4,
      "name": "Rock_Stone"
    },
    {
      "x": 3,
      "y": -2,
      "z": 4,
      "name": "Rock_Stone"
    },
    {
      "x": 3,
      "y": -1,
      "z": 4,
      "name": "Rock_Stone"
    },
    {
      "x": 3,
      "y": 0,
      "z": 4,
      "name": "Rock_Stone"
    },
    {
      "x": 3,
      "y": 1,
      "z": 4,
      "name": "Rock_Stone"
    },
    {
      "x": 3,
      "y": 2,
      "z": 4,
      "name": "Rock_Stone"
    },
    {
      "x": 3,
      "y": 3,
      "z": 4,
      "name": "Rock_Stone"
    },
    {
      "x": 3,
      "y": 4,
      "z": 4,
      "name": "Rock_Stone"
    },
    {
      "x": 4,
      "y": -4,
      "z": -4,
      "name": "Rock_Marble"
    },
    {
      "x": 4,
      "y": -3,
      "z": -4,
      "name": "Rock_Marble"
    },
    {
      "x": 4,
      "y": -2,
      "z": -4,
      "name": "Rock_Marble"
    },
    {
      "x": 4,
      "y": -1,
      "z": -4,
      "name": "Rock_Marble"
    },
    {
      "x": 4,
      "y": 0,
      "z": -4,
      "name": "Rock_Marble"
    },
    {
      "x": 4,
      "y": 1,
      "z": -4,
      "name": "Rock_Marble"
    },
    {
      "x": 4,
      "y": 2,
      "z": -4,
      "name": "Rock_Marble"
    },
    {
      "x": 4,
      "y": 3,
      "z": -4,
      "name": "Rock_Marble"
    },
    {
      "x": 4,
      "y": 4,
      "z": -4,
      "name": "Rock_Marble"
    },
    {
      "x": 4,
      "y": -4,
      "z": -3,
      "name": "Rock_Stone"
    },
    {
      "x": 4,
      "y": -3,
      "z": -3,
      "name": "Rock_Stone"
    },
    {
      "x": 4,
      "y": -2,
      "z": -3,
      "name": "Rock_Stone"
    },
    {
      "x": 4,
      "y": -1,
      "z": -3,
      "name": "Rock_Stone"
    },
    {
      "x": 4,
      "y": 0,
      "z": -3,
      "name": "Rock_Stone"
    },
    {
      "x": 4,
      "y": 1,
      "z": -3,
      "name": "Rock_Stone"
    },
    {
      "x": 4,
      "y": 2,
      "z": -3,
      "name": "Rock_Stone"
    },
    {
      "x": 4,
      "y": 3,
      "z": -3,
      "name": "Rock_Stone"
    },
    {
      "x": 4,
      "y": 4,
      "z": -3,
      "name": "Rock_Stone"
    },
    {
      "x": 4,
      "y": -4,
      "z": -2,
      "name": "Rock_Stone"
    },
    {
      "x": 4,
      "y": -3,
      "z": -2,
      "name": "Rock_Stone"
    },
    {
      "x": 4,
      "y": -2,
      "z": -2,
      "name": "Rock_Stone"
    },
    {
      "x": 4,
      "y": -1,
      "z": -2,
      "name": "Rock_Stone"
    },
    {
      "x": 4,
      "y": 0,
      "z": -2,
      "name": "Rock_Stone"
    },
    {
      "x": 4,
      "y": 1,
      "z": -2,
      "name": "Rock_Stone"
    },
    {
      "x": 4,
      "y": 2,
      "z": -2,
      "name": "Rock_Stone"
    },
    {
      "x": 4,
      "y": 3,
      "z": -2,
      "name": "Rock_Stone"
    },
    {
      "x": 4,
      "y": 4,
      "z": -2,
      "name": "Rock_Stone"
    },
    {
      "x": 4,
      "y": -4,
      "z": -1,
      "name": "Rock_Stone"
    },
    {
      "x": 4,
      "y": -3,
      "z": -1,
      "name": "Rock_Stone"
    },
    {
      "x": 4,
      "y": -2,
      "z": -1,
      "name": "Rock_Stone"
    },
    {
      "x": 4,
      "y": -1,
      "z": -1,
      "name": "Rock_Stone"
    },
    {
      "x": 4,
      "y": 0,
      "z": -1,
      "name": "Rock_Stone"
    },
    {
      "x": 4,
      "y": 1,
      "z": -1,
      "name": "Rock_Stone"
    },
    {
      "x": 4,
      "y": 2,
      "z": -1,
      "name": "Rock_Stone"
    },
    {
      "x": 4,
      "y": 3,
      "z": -1,
      "name": "Rock_Stone"
    },
    {
      "x": 4,
      "y": 4,
      "z": -1,
      "name": "Rock_Stone"
    },
    {
      "x": 4,
      "y": -4,
      "z": 0,
      "name": "Rock_Stone"
    },
    {
      "x": 4,
      "y": -3,
      "z": 0,
      "name": "Rock_Stone"
    },
    {
      "x": 4,
      "y": -2,
      "z": 0,
      "name": "Rock_Stone"
    },
    {
      "x": 4,
      "y": -1,
      "z": 0,
      "name": "Rock_Stone"
    },
    {
      "x": 4,
      "y": 0,
      "z": 0,
      "name": "Rock_Stone"
    },
    {
      "x": 4,
      "y": 1,
      "z": 0,
      "name": "Rock_Stone"
    },
    {
      "x": 4,
      "y": 2,
      "z": 0,
      "name": "Rock_Stone"
    },
    {
      "x": 4,
      "y": 3,
      "z": 0,
      "name": "Rock_Stone"
    },
    {
      "x": 4,
      "y": 4,
      "z": 0,
      "name": "Rock_Stone"
    },
    {
      "x": 4,
      "y": -4,
      "z": 1,
      "name": "Rock_Stone"
    },
    {
      "x": 4,
      "y": -3,
      "z": 1,
      "name": "Rock_Stone"
    },
    {
      "x": 4,
      "y": -2,
      "z": 1,
      "name": "Rock_Stone"
    },
    {
      "x": 4,
      "y": -1,
      "z": 1,
      "name": "Rock_Stone"
    },
    {
      "x": 4,
      "y": 0,
      "z": 1,
      "name": "Rock_Stone"
    },
    {
      "x": 4,
      "y": 1,
      "z": 1,
      "name": "Rock_Stone"
    },
    {
      "x": 4,
      "y": 2,
      "z": 1,
      "name": "Rock_Stone"
    },
    {
      "x": 4,
      "y": 3,
      "z": 1,
      "name": "Rock_Stone"
    },
    {
      "x": 4,
      "y": 4,
      "z": 1,
      "name": "Rock_Stone"
    },
    {
      "x": 4,
      "y": -4,
      "z": 2,
      "name": "Rock_Stone"
    },
    {
      "x": 4,
      "y": -3,
      "z": 2,
      "name": "Rock_Stone"
    },
    {
      "x": 4,
      "y": -2,
      "z": 2,
      "name": "Rock_Stone"
    },
    {
      "x": 4,
      "y": -1,
      "z": 2,
      "name": "Rock_Stone"
    },
    {
      "x": 4,
      "y": 0,
      "z": 2,
      "name": "Rock_Stone"
    },
    {
      "x": 4,
      "y": 1,
      "z": 2,
      "name": "Rock_Stone"
    },
    {
      "x": 4,
      "y": 2,
      "z": 2,
      "name": "Rock_Stone"
    },
    {
      "x": 4,
      "y": 3,
      "z": 2,
      "name": "Rock_Stone"
    },
    {
      "x": 4,
      "y": 4,
      "z": 2,
      "name": "Rock_Stone"
    },
    {
      "x": 4,
      "y": -4,
      "z": 3,
      "name": "Rock_Stone"
    },
    {
      "x": 4,
      "y": -3,
      "z": 3,
      "name": "Rock_Stone"
    },
    {
      "x": 4,
      "y": -2,
      "z": 3,
      "name": "Rock_Stone"
    },
    {
      "x": 4,
      "y": -1,
      "z": 3,
      "name": "Rock_Stone"
    },
    {
      "x": 4,
      "y": 0,
      "z": 3,
      "name": "Rock_Stone"
    },
    {
      "x": 4,
      "y": 1,
      "z": 3,
      "name": "Rock_Stone"
    },
    {
      "x": 4,
      "y": 2,
      "z": 3,
      "name": "Rock_Stone"
    },
    {
      "x": 4,
      "y": 3,
      "z": 3,
      "name": "Rock_Stone"
    },
    {
      "x": 4,
      "y": 4,
      "z": 3,
      "name": "Rock_Stone"
    },
    {
      "x": 4,
      "y": -4,
      "z": 4,
      "name": "Rock_Stone"
    },
    {
      "x": 4,
      "y": -3,
      "z": 4,
      "name": "Rock_Stone"
    },
    {
      "x": 4,
      "y": -2,
      "z": 4,
      "name": "Rock_Stone"
    },
    {
      "x": 4,
      "y": -1,
      "z": 4,
      "name": "Rock_Stone"
    },
    {
      "x": 4,
      "y": 0,
      "z": 4,
      "name": "Rock_Stone"
    },
    {
      "x": 4,
      "y": 1,
      "z": 4,
      "name": "Rock_Stone"
    },
    {
      "x": 4,
      "y": 2,
      "z": 4,
      "name": "Rock_Stone"
    },
    {
      "x": 4,
      "y": 3,
      "z": 4,
      "name": "Rock_Stone"
    },
    {
      "x": 4,
      "y": 4,
      "z": 4,
      "name": "Rock_Stone"
    }
  ]
}