{
  "version": 8,
  "blockIdVersion": 11,
  "anchorX": 0,
  "anchorY": -12,
  "anchorZ": -4,
  "blocks": [
    {
      "x": -5,
      "y": 12,
      "z": 5,
      "name": "Empty"
    },
    {
      "x": -4,
      "y": -12,
      "z": -4,
      "name": "Rock_Marble"
    },
    {
      "x": -4,
      "y": -11,
      "z": -4,
      "name": "Rock_Marble"
    },
    {
      "x": -4,
      "y": -10,
      "z": -4,
      "name": "Rock_Marble"
    },
    {
      "x": -4,
      "y": -9,
      "z": -4,
      "name": "Rock_Marble"
    },
    {
      "x": -4,
      "y": -8,
      "z": -4,
      "name": "Rock_Marble"
    },
    {
      "x": -4,
      "y": -7,
      "z": -4,
      "name": "Rock_Marble"
    },
    {
      "x": -4,
      "y": -6,
      "z": -4,
      "name": "Rock_Marble"
    },
    {
      "x": -4,
      "y": -5,
      "z": -4,
      "name": "Rock_Marble"
    },
    {
      "x": -4,
      "y": -4,
      "z": -4,
      "name": "Rock_Marble"
    },
    {
      "x": -4,
      "y": -3,
      "z": -4,
      "name": "Rock_Marble"
    },
    {
      "x": -4,
      "y": -2,
      "z": -4,
      "name": "Rock_Marble"
    },
    {
      "x": -4,
      "y": -1,
      "z": -4,
      "name": "Rock_Marble"
    },
    {
      "x": -4,
      "y": 0,
      "z": -4,
      "name": "Rock_Marble"
    },
    {
      "x": -4,
      "y": 1,
      "z": -4,
      "name": "Rock_Marble"
    },
    {
      "x": -4,
      "y": 2,
      "z": -4,
      "name": "Rock_Marble"
    },
    {
      "x": -4,
      "y": 3,
      "z": -4,
      "name": "Rock_Marble"
    },
    {
      "x": -4,
      "y": 4,
      "z": -4,
      "name": "Rock_Marble"
    },
    {
      "x": -4,
      "y": 5,
      "z": -4,
      "name": "Rock_Marble"
    },
    {
      "x": -4,
      "y": 6,
      "z": -4,
      "name": "Rock_Marble"
    },
    {
      "x": -4,
      "y": 7,
      "z": -4,
      "name": "Rock_Marble"
    },
    {
      "x": -4,
      "y": 8,
      "z": -4,
      "name": "Rock_Marble"
    },
    {
      "x": -4,
      "y": 9,
      "z": -4,
      "name": "Rock_Marble"
    },
    {
      "x": -4,
      "y": 10,
      "z": -4,
      "name": "Rock_Marble"
    },
    {
      "x": -4,
      "y": 11,
      "z": -4,
      "name": "Rock_Marble"
    },
    {
      "x": -4,
      "y": 12,
      "z": -4,
      "name": "Rock_Marble"
    },
    {
      "x": -4,
      "y": -12,
      "z": -3,
      "name": "Cloth_Block_Wool_Blue_Light"
    },
    {
      "x": -4,
      "y": -11,
      "z": -3,
      "name": "Cloth_Block_Wool_Blue_Light"
    },
    {
      "x": -4,
      "y": -10,
      "z": -3,
      "name": "Cloth_Block_Wool_Blue_Light"
    },
    {
      "x": -4,
      "y": -9,
      "z": -3,
      "name": "Cloth_Block_Wool_Blue_Light"
    },
    {
      "x": -4,
      "y": -8,
      "z": -3,
      "name": "Cloth_Block_Wool_Blue_Light"
    },
    {
      "x": -4,
      "y": -7,
      "z": -3,
      "name": "Cloth_Block_Wool_Blue_Light"
    },
    {
      "x": -4,
      "y": -6,
      "z": -3,
      "name": "Cloth_Block_Wool_Blue_Light"
    },
    {
      "x": -4,
      "y": -5,
      "z": -3,
      "name": "Cloth_Block_Wool_Blue_Light"
    },
    {
      "x": -4,
      "y": -4,
      "z": -3,
      "name": "Cloth_Block_Wool_Blue_Light"
    },
    {
      "x": -4,
      "y": -3,
      "z": -3,
      "name": "Cloth_Block_Wool_Blue_Light"
    },
    {
      "x": -4,
      "y": -2,
      "z": -3,
      "name": "Cloth_Block_Wool_Blue_Light"
    },
    {
      "x": -4,
      "y": -1,
      "z": -3,
      "name": "Cloth_Block_Wool_Blue_Light"
    },
    {
      "x": -4,
      "y": 0,
      "z": -3,
      "name": "Cloth_Block_Wool_Blue_Light"
    },
    {
      "x": -4,
      "y": 1,
      "z": -3,
      "name": "Cloth_Block_Wool_Blue_Light"
    },
    {
      "x": -4,
      "y": 2,
      "z": -3,
      "name": "Cloth_Block_Wool_Blue_Light"
    },
    {
      "x": -4,
      "y": 3,
      "z": -3,
      "name": "Cloth_Block_Wool_Blue_Light"
    },
    {
      "x": -4,
      "y": 4,
      "z": -3,
      "name": "Cloth_Block_Wool_Blue_Light"
    },
    {
      "x": -4,
      "y": 5,
      "z": -3,
      "name": "Cloth_Block_Wool_Blue_Light"
    },
    {
      "x": -4,
      "y": 6,
      "z": -3,
      "name": "Cloth_Block_Wool_Blue_Light"
    },
    {
      "x": -4,
      "y": 7,
      "z": -3,
      "name": "Cloth_Block_Wool_Blue_Light"
    },
    {
      "x": -4,
      "y": 8,
      "z": -3,
      "name": "Cloth_Block_Wool_Blue_Light"
    },
    {
      "x": -4,
      "y": 9,
      "z": -3,
      "name": "Cloth_Block_Wool_Blue_Light"
    },
    {
      "x": -4,
      "y": 10,
      "z": -3,
      "name": "Cloth_Block_Wool_Blue_Light"
    },
    {
      "x": -4,
      "y": 11,
      "z": -3,
      "name": "Cloth_Block_Wool_Blue_Light"
    },
    {
      "x": -4,
      "y": 12,
      "z": -3,
      "name": "Cloth_Block_Wool_Blue_Light"
    },
    {
      "x": -4,
      "y": -12,
      "z": -2,
      "name": "Cloth_Block_Wool_Blue_Light"
    },
    {
      "x": -4,
      "y": -11,
      "z": -2,
      "name": "Cloth_Block_Wool_Blue_Light"
    },
    {
      "x": -4,
      "y": -10,
      "z": -2,
      "name": "Cloth_Block_Wool_Blue_Light"
    },
    {
      "x": -4,
      "y": -9,
      "z": -2,
      "name": "Cloth_Block_Wool_Blue_Light"
    },
    {
      "x": -4,
      "y": -8,
      "z": -2,
      "name": "Cloth_Block_Wool_Blue_Light"
    },
    {
      "x": -4,
      "y": -7,
      "z": -2,
      "name": "Cloth_Block_Wool_Blue_Light"
    },
    {
      "x": -4,
      "y": -6,
      "z": -2,
      "name": "Cloth_Block_Wool_Blue_Light"
    },
    {
      "x": -4,
      "y": -5,
      "z": -2,
      "name": "Cloth_Block_Wool_Blue_Light"
    },
    {
      "x": -4,
      "y": -4,
      "z": -2,
      "name": "Cloth_Block_Wool_Blue_Light"
    },
    {
      "x": -4,
      "y": -3,
      "z": -2,
      "name": "Cloth_Block_Wool_Blue_Light"
    },
    {
      "x": -4,
      "y": -2,
      "z": -2,
      "name": "Cloth_Block_Wool_Blue_Light"
    },
    {
      "x": -4,
      "y": -1,
      "z": -2,
      "name": "Cloth_Block_Wool_Blue_Light"
    },
    {
      "x": -4,
      "y": 0,
      "z": -2,
      "name": "Cloth_Block_Wool_Blue_Light"
    },
    {
      "x": -4,
      "y": 1,
      "z": -2,
      "name": "Cloth_Block_Wool_Blue_Light"
    },
    {
      "x": -4,
      "y": 2,
      "z": -2,
      "name": "Cloth_Block_Wool_Blue_Light"
    },
    {
      "x": -4,
      "y": 3,
      "z": -2,
      "name": "Cloth_Block_Wool_Blue_Light"
    },
    {
      "x": -4,
      "y": 4,
      "z": -2,
      "name": "Cloth_Block_Wool_Blue_Light"
    },
    {
      "x": -4,
      "y": 5,
      "z": -2,
      "name": "Cloth_Block_Wool_Blue_Light"
    },
    {
      "x": -4,
      "y": 6,
      "z": -2,
      "name": "Cloth_Block_Wool_Blue_Light"
    },
    {
      "x": -4,
      "y": 7,
      "z": -2,
      "name": "Cloth_Block_Wool_Blue_Light"
    },
    {
      "x": -4,
      "y": 8,
      "z": -2,
      "name": "Cloth_Block_Wool_Blue_Light"
    },
    {
      "x": -4,
      "y": 9,
      "z": -2,
      "name": "Cloth_Block_Wool_Blue_Light"
    },
    {
      "x": -4,
      "y": 10,
      "z": -2,
      "name": "Cloth_Block_Wool_Blue_Light"
    },
    {
      "x": -4,
      "y": 11,
      "z": -2,
      "name": "Cloth_Block_Wool_Blue_Light"
    },
    {
      "x": -4,
      "y": 12,
      "z": -2,
      "name": "Cloth_Block_Wool_Blue_Light"
    },
    {
      "x": -4,
      "y": -12,
      "z": -1,
      "name": "Cloth_Block_Wool_Blue_Light"
    },
    {
      "x": -4,
      "y": -11,
      "z": -1,
      "name": "Cloth_Block_Wool_Blue_Light"
    },
    {
      "x": -4,
      "y": -10,
      "z": -1,
      "name": "Cloth_Block_Wool_Blue_Light"
    },
    {
      "x": -4,
      "y": -9,
      "z": -1,
      "name": "Cloth_Block_Wool_Blue_Light"
    },
    {
      "x": -4,
      "y": -8,
      "z": -1,
      "name": "Cloth_Block_Wool_Blue_Light"
    },
    {
      "x": -4,
      "y": -7,
      "z": -1,
      "name": "Cloth_Block_Wool_Blue_Light"
    },
    {
      "x": -4,
      "y": -6,
      "z": -1,
      "name": "Cloth_Block_Wool_Blue_Light"
    },
    {
      "x": -4,
      "y": -5,
      "z": -1,
      "name": "Cloth_Block_Wool_Blue_Light"
    },
    {
      "x": -4,
      "y": -4,
      "z": -1,
      "name": "Cloth_Block_Wool_Blue_Light"
    },
    {
      "x": -4,
      "y": -3,
      "z": -1,
      "name": "Cloth_Block_Wool_Blue_Light"
    },
    {
      "x": -4,
      "y": -2,
      "z": -1,
      "name": "Cloth_Block_Wool_Blue_Light"
    },
    {
      "x": -4,
      "y": -1,
      "z": -1,
      "name": "Cloth_Block_Wool_Blue_Light"
    },
    {
      "x": -4,
      "y": 0,
      "z": -1,
      "name": "Cloth_Block_Wool_Blue_Light"
    },
    {
      "x": -4,
      "y": 1,
      "z": -1,
      "name": "Cloth_Block_Wool_Blue_Light"
    },
    {
      "x": -4,
      "y": 2,
      "z": -1,
      "name": "Cloth_Block_Wool_Blue_Light"
    },
    {
      "x": -4,
      "y": 3,
      "z": -1,
      "name": "Cloth_Block_Wool_Blue_Light"
    },
    {
      "x": -4,
      "y": 4,
      "z": -1,
      "name": "Cloth_Block_Wool_Blue_Light"
    },
    {
      "x": -4,
      "y": 5,
      "z": -1,
      "name": "Cloth_Block_Wool_Blue_Light"
    },
    {
      "x": -4,
      "y": 6,
      "z": -1,
      "name": "Cloth_Block_Wool_Blue_Light"
    },
    {
      "x": -4,
      "y": 7,
      "z": -1,
      "name": "Cloth_Block_Wool_Blue_Light"
    },
    {
      "x": -4,
      "y": 8,
      "z": -1,
      "name": "Cloth_Block_Wool_Blue_Light"
    },
    {
      "x": -4,
      "y": 9,
      "z": -1,
      "name": "Cloth_Block_Wool_Blue_Light"
    },
    {
      "x": -4,
      "y": 10,
      "z": -1,
      "name": "Cloth_Block_Wool_Blue_Light"
    },
    {
      "x": -4,
      "y": 11,
      "z": -1,
      "name": "Cloth_Block_Wool_Blue_Light"
    },
    {
      "x": -4,
      "y": 12,
      "z": -1,
      "name": "Cloth_Block_Wool_Blue_Light"
    },
    {
      "x": -4,
      "y": -12,
      "z": 0,
      "name": "Cloth_Block_Wool_Blue_Light"
    },
    {
      "x": -4,
      "y": -11,
      "z": 0,
      "name": "Cloth_Block_Wool_Blue_Light"
    },
    {
      "x": -4,
      "y": -10,
      "z": 0,
      "name": "Cloth_Block_Wool_Blue_Light"
    },
    {
      "x": -4,
      "y": -9,
      "z": 0,
      "name": "Cloth_Block_Wool_Blue_Light"
    },
    {
      "x": -4,
      "y": -8,
      "z": 0,
      "name": "Cloth_Block_Wool_Blue_Light"
    },
    {
      "x": -4,
      "y": -7,
      "z": 0,
      "name": "Cloth_Block_Wool_Blue_Light"
    },
    {
      "x": -4,
      "y": -6,
      "z": 0,
      "name": "Cloth_Block_Wool_Blue_Light"
    },
    {
      "x": -4,
      "y": -5,
      "z": 0,
      "name": "Cloth_Block_Wool_Blue_Light"
    },
    {
      "x": -4,
      "y": -4,
      "z": 0,
      "name": "Cloth_Block_Wool_Blue_Light"
    },
    {
      "x": -4,
      "y": -3,
      "z": 0,
      "name": "Cloth_Block_Wool_Blue_Light"
    },
    {
      "x": -4,
      "y": -2,
      "z": 0,
      "name": "Cloth_Block_Wool_Blue_Light"
    },
    {
      "x": -4,
      "y": -1,
      "z": 0,
      "name": "Cloth_Block_Wool_Blue_Light"
    },
    {
      "x": -4,
      "y": 0,
      "z": 0,
      "name": "Cloth_Block_Wool_Blue_Light"
    },
    {
      "x": -4,
      "y": 1,
      "z": 0,
      "name": "Cloth_Block_Wool_Blue_Light"
    },
    {
      "x": -4,
      "y": 2,
      "z": 0,
      "name": "Cloth_Block_Wool_Blue_Light"
    },
    {
      "x": -4,
      "y": 3,
      "z": 0,
      "name": "Cloth_Block_Wool_Blue_Light"
    },
    {
      "x": -4,
      "y": 4,
      "z": 0,
      "name": "Cloth_Block_Wool_Blue_Light"
    },
    {
      "x": -4,
      "y": 5,
      "z": 0,
      "name": "Cloth_Block_Wool_Blue_Light"
    },
    {
      "x": -4,
      "y": 6,
      "z": 0,
      "name": "Cloth_Block_Wool_Blue_Light"
    },
    {
      "x": -4,
      "y": 7,
      "z": 0,
      "name": "Cloth_Block_Wool_Blue_Light"
    },
    {
      "x": -4,
      "y": 8,
      "z": 0,
      "name": "Cloth_Block_Wool_Blue_Light"
    },
    {
      "x": -4,
      "y": 9,
      "z": 0,
      "name": "Cloth_Block_Wool_Blue_Light"
    },
    {
      "x": -4,
      "y": 10,
      "z": 0,
      "name": "Cloth_Block_Wool_Blue_Light"
    },
    {
      "x": -4,
      "y": 11,
      "z": 0,
      "name": "Cloth_Block_Wool_Blue_Light"
    },
    {
      "x": -4,
      "y": 12,
      "z": 0,
      "name": "Cloth_Block_Wool_Blue_Light"
    },
    {
      "x": -4,
      "y": -12,
      "z": 1,
      "name": "Cloth_Block_Wool_Blue_Light"
    },
    {
      "x": -4,
      "y": -11,
      "z": 1,
      "name": "Cloth_Block_Wool_Blue_Light"
    },
    {
      "x": -4,
      "y": -10,
      "z": 1,
      "name": "Cloth_Block_Wool_Blue_Light"
    },
    {
      "x": -4,
      "y": -9,
      "z": 1,
      "name": "Cloth_Block_Wool_Blue_Light"
    },
    {
      "x": -4,
      "y": -8,
      "z": 1,
      "name": "Cloth_Block_Wool_Blue_Light"
    },
    {
      "x": -4,
      "y": -7,
      "z": 1,
      "name": "Cloth_Block_Wool_Blue_Light"
    },
    {
      "x": -4,
      "y": -6,
      "z": 1,
      "name": "Cloth_Block_Wool_Blue_Light"
    },
    {
      "x": -4,
      "y": -5,
      "z": 1,
      "name": "Cloth_Block_Wool_Blue_Light"
    },
    {
      "x": -4,
      "y": -4,
      "z": 1,
      "name": "Cloth_Block_Wool_Blue_Light"
    },
    {
      "x": -4,
      "y": -3,
      "z": 1,
      "name": "Cloth_Block_Wool_Blue_Light"
    },
    {
      "x": -4,
      "y": -2,
      "z": 1,
      "name": "Cloth_Block_Wool_Blue_Light"
    },
    {
      "x": -4,
      "y": -1,
      "z": 1,
      "name": "Cloth_Block_Wool_Blue_Light"
    },
    {
      "x": -4,
      "y": 0,
      "z": 1,
      "name": "Cloth_Block_Wool_Blue_Light"
    },
    {
      "x": -4,
      "y": 1,
      "z": 1,
      "name": "Cloth_Block_Wool_Blue_Light"
    },
    {
      "x": -4,
      "y": 2,
      "z": 1,
      "name": "Cloth_Block_Wool_Blue_Light"
    },
    {
      "x": -4,
      "y": 3,
      "z": 1,
      "name": "Cloth_Block_Wool_Blue_Light"
    },
    {
      "x": -4,
      "y": 4,
      "z": 1,
      "name": "Cloth_Block_Wool_Blue_Light"
    },
    {
      "x": -4,
      "y": 5,
      "z": 1,
      "name": "Cloth_Block_Wool_Blue_Light"
    },
    {
      "x": -4,
      "y": 6,
      "z": 1,
      "name": "Cloth_Block_Wool_Blue_Light"
    },
    {
      "x": -4,
      "y": 7,
      "z": 1,
      "name": "Cloth_Block_Wool_Blue_Light"
    },
    {
      "x": -4,
      "y": 8,
      "z": 1,
      "name": "Cloth_Block_Wool_Blue_Light"
    },
    {
      "x": -4,
      "y": 9,
      "z": 1,
      "name": "Cloth_Block_Wool_Blue_Light"
    },
    {
      "x": -4,
      "y": 10,
      "z": 1,
      "name": "Cloth_Block_Wool_Blue_Light"
    },
    {
      "x": -4,
      "y": 11,
      "z": 1,
      "name": "Cloth_Block_Wool_Blue_Light"
    },
    {
      "x": -4,
      "y": 12,
      "z": 1,
      "name": "Cloth_Block_Wool_Blue_Light"
    },
    {
      "x": -4,
      "y": -12,
      "z": 2,
      "name": "Cloth_Block_Wool_Blue_Light"
    },
    {
      "x": -4,
      "y": -11,
      "z": 2,
      "name": "Cloth_Block_Wool_Blue_Light"
    },
    {
      "x": -4,
      "y": -10,
      "z": 2,
      "name": "Cloth_Block_Wool_Blue_Light"
    },
    {
      "x": -4,
      "y": -9,
      "z": 2,
      "name": "Cloth_Block_Wool_Blue_Light"
    },
    {
      "x": -4,
      "y": -8,
      "z": 2,
      "name": "Cloth_Block_Wool_Blue_Light"
    },
    {
      "x": -4,
      "y": -7,
      "z": 2,
      "name": "Cloth_Block_Wool_Blue_Light"
    },
    {
      "x": -4,
      "y": -6,
      "z": 2,
      "name": "Cloth_Block_Wool_Blue_Light"
    },
    {
      "x": -4,
      "y": -5,
      "z": 2,
      "name": "Cloth_Block_Wool_Blue_Light"
    },
    {
      "x": -4,
      "y": -4,
      "z": 2,
      "name": "Cloth_Block_Wool_Blue_Light"
    },
    {
      "x": -4,
      "y": -3,
      "z": 2,
      "name": "Cloth_Block_Wool_Blue_Light"
    },
    {
      "x": -4,
      "y": -2,
      "z": 2,
      "name": "Cloth_Block_Wool_Blue_Light"
    },
    {
      "x": -4,
      "y": -1,
      "z": 2,
      "name": "Cloth_Block_Wool_Blue_Light"
    },
    {
      "x": -4,
      "y": 0,
      "z": 2,
      "name": "Cloth_Block_Wool_Blue_Light"
    },
    {
      "x": -4,
      "y": 1,
      "z": 2,
      "name": "Cloth_Block_Wool_Blue_Light"
    },
    {
      "x": -4,
      "y": 2,
      "z": 2,
      "name": "Cloth_Block_Wool_Blue_Light"
    },
    {
      "x": -4,
      "y": 3,
      "z": 2,
      "name": "Cloth_Block_Wool_Blue_Light"
    },
    {
      "x": -4,
      "y": 4,
      "z": 2,
      "name": "Cloth_Block_Wool_Blue_Light"
    },
    {
      "x": -4,
      "y": 5,
      "z": 2,
      "name": "Cloth_Block_Wool_Blue_Light"
    },
    {
      "x": -4,
      "y": 6,
      "z": 2,
      "name": "Cloth_Block_Wool_Blue_Light"
    },
    {
      "x": -4,
      "y": 7,
      "z": 2,
      "name": "Cloth_Block_Wool_Blue_Light"
    },
    {
      "x": -4,
      "y": 8,
      "z": 2,
      "name": "Cloth_Block_Wool_Blue_Light"
    },
    {
      "x": -4,
      "y": 9,
      "z": 2,
      "name": "Cloth_Block_Wool_Blue_Light"
    },
    {
      "x": -4,
      "y": 10,
      "z": 2,
      "name": "Cloth_Block_Wool_Blue_Light"
    },
    {
      "x": -4,
      "y": 11,
      "z": 2,
      "name": "Cloth_Block_Wool_Blue_Light"
    },
    {
      "x": -4,
      "y": 12,
      "z": 2,
      "name": "Cloth_Block_Wool_Blue_Light"
    },
    {
      "x": -4,
      "y": -12,
      "z": 3,
      "name": "Cloth_Block_Wool_Blue_Light"
    },
    {
      "x": -4,
      "y": -11,
      "z": 3,
      "name": "Cloth_Block_Wool_Blue_Light"
    },
    {
      "x": -4,
      "y": -10,
      "z": 3,
      "name": "Cloth_Block_Wool_Blue_Light"
    },
    {
      "x": -4,
      "y": -9,
      "z": 3,
      "name": "Cloth_Block_Wool_Blue_Light"
    },
    {
      "x": -4,
      "y": -8,
      "z": 3,
      "name": "Cloth_Block_Wool_Blue_Light"
    },
    {
      "x": -4,
      "y": -7,
      "z": 3,
      "name": "Cloth_Block_Wool_Blue_Light"
    },
    {
      "x": -4,
      "y": -6,
      "z": 3,
      "name": "Cloth_Block_Wool_Blue_Light"
    },
    {
      "x": -4,
      "y": -5,
      "z": 3,
      "name": "Cloth_Block_Wool_Blue_Light"
    },
    {
      "x": -4,
      "y": -4,
      "z": 3,
      "name": "Cloth_Block_Wool_Blue_Light"
    },
    {
      "x": -4,
      "y": -3,
      "z": 3,
      "name": "Cloth_Block_Wool_Blue_Light"
    },
    {
      "x": -4,
      "y": -2,
      "z": 3,
      "name": "Cloth_Block_Wool_Blue_Light"
    },
    {
      "x": -4,
      "y": -1,
      "z": 3,
      "name": "Cloth_Block_Wool_Blue_Light"
    },
    {
      "x": -4,
      "y": 0,
      "z": 3,
      "name": "Cloth_Block_Wool_Blue_Light"
    },
    {
      "x": -4,
      "y": 1,
      "z": 3,
      "name": "Cloth_Block_Wool_Blue_Light"
    },
    {
      "x": -4,
      "y": 2,
      "z": 3,
      "name": "Cloth_Block_Wool_Blue_Light"
    },
    {
      "x": -4,
      "y": 3,
      "z": 3,
      "name": "Cloth_Block_Wool_Blue_Light"
    },
    {
      "x": -4,
      "y": 4,
      "z": 3,
      "name": "Cloth_Block_Wool_Blue_Light"
    },
    {
      "x": -4,
      "y": 5,
      "z": 3,
      "name": "Cloth_Block_Wool_Blue_Light"
    },
    {
      "x": -4,
      "y": 6,
      "z": 3,
      "name": "Cloth_Block_Wool_Blue_Light"
    },
    {
      "x": -4,
      "y": 7,
      "z": 3,
      "name": "Cloth_Block_Wool_Blue_Light"
    },
    {
      "x": -4,
      "y": 8,
      "z": 3,
      "name": "Cloth_Block_Wool_Blue_Light"
    },
    {
      "x": -4,
      "y": 9,
      "z": 3,
      "name": "Cloth_Block_Wool_Blue_Light"
    },
    {
      "x": -4,
      "y": 10,
      "z": 3,
      "name": "Cloth_Block_Wool_Blue_Light"
    },
    {
      "x": -4,
      "y": 11,
      "z": 3,
      "name": "Cloth_Block_Wool_Blue_Light"
    },
    {
      "x": -4,
      "y": 12,
      "z": 3,
      "name": "Cloth_Block_Wool_Blue_Light"
    },
    {
      "x": -4,
      "y": -12,
      "z": 4,
      "name": "Cloth_Block_Wool_Blue_Light"
    },
    {
      "x": -4,
      "y": -11,
      "z": 4,
      "name": "Cloth_Block_Wool_Blue_Light"
    },
    {
      "x": -4,
      "y": -10,
      "z": 4,
      "name": "Cloth_Block_Wool_Blue_Light"
    },
    {
      "x": -4,
      "y": -9,
      "z": 4,
      "name": "Cloth_Block_Wool_Blue_Light"
    },
    {
      "x": -4,
      "y": -8,
      "z": 4,
      "name": "Cloth_Block_Wool_Blue_Light"
    },
    {
      "x": -4,
      "y": -7,
      "z": 4,
      "name": "Cloth_Block_Wool_Blue_Light"
    },
    {
      "x": -4,
      "y": -6,
      "z": 4,
      "name": "Cloth_Block_Wool_Blue_Light"
    },
    {
      "x": -4,
      "y": -5,
      "z": 4,
      "name": "Cloth_Block_Wool_Blue_Light"
    },
    {
      "x": -4,
      "y": -4,
      "z": 4,
      "name": "Cloth_Block_Wool_Blue_Light"
    },
    {
      "x": -4,
      "y": -3,
      "z": 4,
      "name": "Cloth_Block_Wool_Blue_Light"
    },
    {
      "x": -4,
      "y": -2,
      "z": 4,
      "name": "Cloth_Block_Wool_Blue_Light"
    },
    {
      "x": -4,
      "y": -1,
      "z": 4,
      "name": "Cloth_Block_Wool_Blue_Light"
    },
    {
      "x": -4,
      "y": 0,
      "z": 4,
      "name": "Cloth_Block_Wool_Blue_Light"
    },
    {
      "x": -4,
      "y": 1,
      "z": 4,
      "name": "Cloth_Block_Wool_Blue_Light"
    },
    {
      "x": -4,
      "y": 2,
      "z": 4,
      "name": "Cloth_Block_Wool_Blue_Light"
    },
    {
      "x": -4,
      "y": 3,
      "z": 4,
      "name": "Cloth_Block_Wool_Blue_Light"
    },
    {
      "x": -4,
      "y": 4,
      "z": 4,
      "name": "Cloth_Block_Wool_Blue_Light"
    },
    {
      "x": -4,
      "y": 5,
      "z": 4,
      "name": "Cloth_Block_Wool_Blue_Light"
    },
    {
      "x": -4,
      "y": 6,
      "z": 4,
      "name": "Cloth_Block_Wool_Blue_Light"
    },
    {
      "x": -4,
      "y": 7,
      "z": 4,
      "name": "Cloth_Block_Wool_Blue_Light"
    },
    {
      "x": -4,
      "y": 8,
      "z": 4,
      "name": "Cloth_Block_Wool_Blue_Light"
    },
    {
      "x": -4,
      "y": 9,
      "z": 4,
      "name": "Cloth_Block_Wool_Blue_Light"
    },
    {
      "x": -4,
      "y": 10,
      "z": 4,
      "name": "Cloth_Block_Wool_Blue_Light"
    },
    {
      "x": -4,
      "y": 11,
      "z": 4,
      "name": "Cloth_Block_Wool_Blue_Light"
    },
    {
      "x": -4,
      "y": 12,
      "z": 4,
      "name": "Cloth_Block_Wool_Blue_Light"
    },
    {
      "x": -3,
      "y": -12,
      "z": -4,
      "name": "Rock_Marble"
    },
    {
      "x": -3,
      "y": -11,
      "z": -4,
      "name": "Rock_Marble"
    },
    {
      "x": -3,
      "y": -10,
      "z": -4,
      "name": "Rock_Marble"
    },
    {
      "x": -3,
      "y": -9,
      "z": -4,
      "name": "Rock_Marble"
    },
    {
      "x": -3,
      "y": -8,
      "z": -4,
      "name": "Rock_Marble"
    },
    {
      "x": -3,
      "y": -7,
      "z": -4,
      "name": "Rock_Marble"
    },
    {
      "x": -3,
      "y": -6,
      "z": -4,
      "name": "Rock_Marble"
    },
    {
      "x": -3,
      "y": -5,
      "z": -4,
      "name": "Rock_Marble"
    },
    {
      "x": -3,
      "y": -4,
      "z": -4,
      "name": "Rock_Marble"
    },
    {
      "x": -3,
      "y": -3,
      "z": -4,
      "name": "Rock_Marble"
    },
    {
      "x": -3,
      "y": -2,
      "z": -4,
      "name": "Rock_Marble"
    },
    {
      "x": -3,
      "y": -1,
      "z": -4,
      "name": "Rock_Marble"
    },
    {
      "x": -3,
      "y": 0,
      "z": -4,
      "name": "Rock_Marble"
    },
    {
      "x": -3,
      "y": 1,
      "z": -4,
      "name": "Rock_Marble"
    },
    {
      "x": -3,
      "y": 2,
      "z": -4,
      "name": "Rock_Marble"
    },
    {
      "x": -3,
      "y": 3,
      "z": -4,
      "name": "Rock_Marble"
    },
    {
      "x": -3,
      "y": 4,
      "z": -4,
      "name": "Rock_Marble"
    },
    {
      "x": -3,
      "y": 5,
      "z": -4,
      "name": "Rock_Marble"
    },
    {
      "x": -3,
      "y": 6,
      "z": -4,
      "name": "Rock_Marble"
    },
    {
      "x": -3,
      "y": 7,
      "z": -4,
      "name": "Rock_Marble"
    },
    {
      "x": -3,
      "y": 8,
      "z": -4,
      "name": "Rock_Marble"
    },
    {
      "x": -3,
      "y": 9,
      "z": -4,
      "name": "Rock_Marble"
    },
    {
      "x": -3,
      "y": 10,
      "z": -4,
      "name": "Rock_Marble"
    },
    {
      "x": -3,
      "y": 11,
      "z": -4,
      "name": "Rock_Marble"
    },
    {
      "x": -3,
      "y": 12,
      "z": -4,
      "name": "Rock_Marble"
    },
    {
      "x": -3,
      "y": -12,
      "z": -3,
      "name": "Cloth_Block_Wool_Blue_Light"
    },
    {
      "x": -3,
      "y": 12,
      "z": -3,
      "name": "Cloth_Block_Wool_Blue_Light"
    },
    {
      "x": -3,
      "y": -12,
      "z": -2,
      "name": "Cloth_Block_Wool_Blue_Light"
    },
    {
      "x": -3,
      "y": 12,
      "z": -2,
      "name": "Cloth_Block_Wool_Blue_Light"
    },
    {
      "x": -3,
      "y": -12,
      "z": -1,
      "name": "Cloth_Block_Wool_Blue_Light"
    },
    {
      "x": -3,
      "y": 12,
      "z": -1,
      "name": "Cloth_Block_Wool_Blue_Light"
    },
    {
      "x": -3,
      "y": -12,
      "z": 0,
      "name": "Cloth_Block_Wool_Blue_Light"
    },
    {
      "x": -3,
      "y": 12,
      "z": 0,
      "name": "Cloth_Block_Wool_Blue_Light"
    },
    {
      "x": -3,
      "y": -12,
      "z": 1,
      "name": "Cloth_Block_Wool_Blue_Light"
    },
    {
      "x": -3,
      "y": 12,
      "z": 1,
      "name": "Cloth_Block_Wool_Blue_Light"
    },
    {
      "x": -3,
      "y": -12,
      "z": 2,
      "name": "Cloth_Block_Wool_Blue_Light"
    },
    {
      "x": -3,
      "y": 12,
      "z": 2,
      "name": "Cloth_Block_Wool_Blue_Light"
    },
    {
      "x": -3,
      "y": -12,
      "z": 3,
      "name": "Cloth_Block_Wool_Blue_Light"
    },
    {
      "x": -3,
      "y": 12,
      "z": 3,
      "name": "Cloth_Block_Wool_Blue_Light"
    },
    {
      "x": -3,
      "y": -12,
      "z": 4,
      "name": "Cloth_Block_Wool_Blue_Light"
    },
    {
      "x": -3,
      "y": -11,
      "z": 4,
      "name": "Cloth_Block_Wool_Blue_Light"
    },
    {
      "x": -3,
      "y": -10,
      "z": 4,
      "name": "Cloth_Block_Wool_Blue_Light"
    },
    {
      "x": -3,
      "y": -9,
      "z": 4,
      "name": "Cloth_Block_Wool_Blue_Light"
    },
    {
      "x": -3,
      "y": -8,
      "z": 4,
      "name": "Cloth_Block_Wool_Blue_Light"
    },
    {
      "x": -3,
      "y": -7,
      "z": 4,
      "name": "Cloth_Block_Wool_Blue_Light"
    },
    {
      "x": -3,
      "y": -6,
      "z": 4,
      "name": "Cloth_Block_Wool_Blue_Light"
    },
    {
      "x": -3,
      "y": -5,
      "z": 4,
      "name": "Cloth_Block_Wool_Blue_Light"
    },
    {
      "x": -3,
      "y": -4,
      "z": 4,
      "name": "Cloth_Block_Wool_Blue_Light"
    },
    {
      "x": -3,
      "y": -3,
      "z": 4,
      "name": "Cloth_Block_Wool_Blue_Light"
    },
    {
      "x": -3,
      "y": -2,
      "z": 4,
      "name": "Cloth_Block_Wool_Blue_Light"
    },
    {
      "x": -3,
      "y": -1,
      "z": 4,
      "name": "Cloth_Block_Wool_Blue_Light"
    },
    {
      "x": -3,
      "y": 0,
      "z": 4,
      "name": "Cloth_Block_Wool_Blue_Light"
    },
    {
      "x": -3,
      "y": 1,
      "z": 4,
      "name": "Cloth_Block_Wool_Blue_Light"
    },
    {
      "x": -3,
      "y": 2,
      "z": 4,
      "name": "Cloth_Block_Wool_Blue_Light"
    },
    {
      "x": -3,
      "y": 3,
      "z": 4,
      "name": "Cloth_Block_Wool_Blue_Light"
    },
    {
      "x": -3,
      "y": 4,
      "z": 4,
      "name": "Cloth_Block_Wool_Blue_Light"
    },
    {
      "x": -3,
      "y": 5,
      "z": 4,
      "name": "Cloth_Block_Wool_Blue_Light"
    },
    {
      "x": -3,
      "y": 6,
      "z": 4,
      "name": "Cloth_Block_Wool_Blue_Light"
    },
    {
      "x": -3,
      "y": 7,
      "z": 4,
      "name": "Cloth_Block_Wool_Blue_Light"
    },
    {
      "x": -3,
      "y": 8,
      "z": 4,
      "name": "Cloth_Block_Wool_Blue_Light"
    },
    {
      "x": -3,
      "y": 9,
      "z": 4,
      "name": "Cloth_Block_Wool_Blue_Light"
    },
    {
      "x": -3,
      "y": 10,
      "z": 4,
      "name": "Cloth_Block_Wool_Blue_Light"
    },
    {
      "x": -3,
      "y": 11,
      "z": 4,
      "name": "Cloth_Block_Wool_Blue_Light"
    },
    {
      "x": -3,
      "y": 12,
      "z": 4,
      "name": "Cloth_Block_Wool_Blue_Light"
    },
    {
      "x": -2,
      "y": -12,
      "z": -4,
      "name": "Rock_Marble"
    },
    {
      "x": -2,
      "y": -11,
      "z": -4,
      "name": "Rock_Marble"
    },
    {
      "x": -2,
      "y": -10,
      "z": -4,
      "name": "Rock_Marble"
    },
    {
      "x": -2,
      "y": -9,
      "z": -4,
      "name": "Rock_Marble"
    },
    {
      "x": -2,
      "y": -8,
      "z": -4,
      "name": "Rock_Marble"
    },
    {
      "x": -2,
      "y": -7,
      "z": -4,
      "name": "Rock_Marble"
    },
    {
      "x": -2,
      "y": -6,
      "z": -4,
      "name": "Rock_Marble"
    },
    {
      "x": -2,
      "y": -5,
      "z": -4,
      "name": "Rock_Marble"
    },
    {
      "x": -2,
      "y": -4,
      "z": -4,
      "name": "Rock_Marble"
    },
    {
      "x": -2,
      "y": -3,
      "z": -4,
      "name": "Rock_Marble"
    },
    {
      "x": -2,
      "y": -2,
      "z": -4,
      "name": "Rock_Marble"
    },
    {
      "x": -2,
      "y": -1,
      "z": -4,
      "name": "Rock_Marble"
    },
    {
      "x": -2,
      "y": 0,
      "z": -4,
      "name": "Rock_Marble"
    },
    {
      "x": -2,
      "y": 1,
      "z": -4,
      "name": "Rock_Marble"
    },
    {
      "x": -2,
      "y": 2,
      "z": -4,
      "name": "Rock_Marble"
    },
    {
      "x": -2,
      "y": 3,
      "z": -4,
      "name": "Rock_Marble"
    },
    {
      "x": -2,
      "y": 4,
      "z": -4,
      "name": "Rock_Marble"
    },
    {
      "x": -2,
      "y": 5,
      "z": -4,
      "name": "Rock_Marble"
    },
    {
      "x": -2,
      "y": 6,
      "z": -4,
      "name": "Rock_Marble"
    },
    {
      "x": -2,
      "y": 7,
      "z": -4,
      "name": "Rock_Marble"
    },
    {
      "x": -2,
      "y": 8,
      "z": -4,
      "name": "Rock_Marble"
    },
    {
      "x": -2,
      "y": 9,
      "z": -4,
      "name": "Rock_Marble"
    },
    {
      "x": -2,
      "y": 10,
      "z": -4,
      "name": "Rock_Marble"
    },
    {
      "x": -2,
      "y": 11,
      "z": -4,
      "name": "Rock_Marble"
    },
    {
      "x": -2,
      "y": 12,
      "z": -4,
      "name": "Rock_Marble"
    },
    {
      "x": -2,
      "y": -12,
      "z": -3,
      "name": "Cloth_Block_Wool_Blue_Light"
    },
    {
      "x": -2,
      "y": 12,
      "z": -3,
      "name": "Cloth_Block_Wool_Blue_Light"
    },
    {
      "x": -2,
      "y": -12,
      "z": -2,
      "name": "Cloth_Block_Wool_Blue_Light"
    },
    {
      "x": -2,
      "y": 12,
      "z": -2,
      "name": "Cloth_Block_Wool_Blue_Light"
    },
    {
      "x": -2,
      "y": -12,
      "z": -1,
      "name": "Cloth_Block_Wool_Blue_Light"
    },
    {
      "x": -2,
      "y": 12,
      "z": -1,
      "name": "Cloth_Block_Wool_Blue_Light"
    },
    {
      "x": -2,
      "y": -12,
      "z": 0,
      "name": "Cloth_Block_Wool_Blue_Light"
    },
    {
      "x": -2,
      "y": 12,
      "z": 0,
      "name": "Cloth_Block_Wool_Blue_Light"
    },
    {
      "x": -2,
      "y": -12,
      "z": 1,
      "name": "Cloth_Block_Wool_Blue_Light"
    },
    {
      "x": -2,
      "y": 12,
      "z": 1,
      "name": "Cloth_Block_Wool_Blue_Light"
    },
    {
      "x": -2,
      "y": -12,
      "z": 2,
      "name": "Cloth_Block_Wool_Blue_Light"
    },
    {
      "x": -2,
      "y": 12,
      "z": 2,
      "name": "Cloth_Block_Wool_Blue_Light"
    },
    {
      "x": -2,
      "y": -12,
      "z": 3,
      "name": "Cloth_Block_Wool_Blue_Light"
    },
    {
      "x": -2,
      "y": 12,
      "z": 3,
      "name": "Cloth_Block_Wool_Blue_Light"
    },
    {
      "x": -2,
      "y": -12,
      "z": 4,
      "name": "Cloth_Block_Wool_Blue_Light"
    },
    {
      "x": -2,
      "y": -11,
      "z": 4,
      "name": "Cloth_Block_Wool_Blue_Light"
    },
    {
      "x": -2,
      "y": -10,
      "z": 4,
      "name": "Cloth_Block_Wool_Blue_Light"
    },
    {
      "x": -2,
      "y": -9,
      "z": 4,
      "name": "Cloth_Block_Wool_Blue_Light"
    },
    {
      "x": -2,
      "y": -8,
      "z": 4,
      "name": "Cloth_Block_Wool_Blue_Light"
    },
    {
      "x": -2,
      "y": -7,
      "z": 4,
      "name": "Cloth_Block_Wool_Blue_Light"
    },
    {
      "x": -2,
      "y": -6,
      "z": 4,
      "name": "Cloth_Block_Wool_Blue_Light"
    },
    {
      "x": -2,
      "y": -5,
      "z": 4,
      "name": "Cloth_Block_Wool_Blue_Light"
    },
    {
      "x": -2,
      "y": -4,
      "z": 4,
      "name": "Cloth_Block_Wool_Blue_Light"
    },
    {
      "x": -2,
      "y": -3,
      "z": 4,
      "name": "Cloth_Block_Wool_Blue_Light"
    },
    {
      "x": -2,
      "y": -2,
      "z": 4,
      "name": "Cloth_Block_Wool_Blue_Light"
    },
    {
      "x": -2,
      "y": -1,
      "z": 4,
      "name": "Cloth_Block_Wool_Blue_Light"
    },
    {
      "x": -2,
      "y": 0,
      "z": 4,
      "name": "Cloth_Block_Wool_Blue_Light"
    },
    {
      "x": -2,
      "y": 1,
      "z": 4,
      "name": "Cloth_Block_Wool_Blue_Light"
    },
    {
      "x": -2,
      "y": 2,
      "z": 4,
      "name": "Cloth_Block_Wool_Blue_Light"
    },
    {
      "x": -2,
      "y": 3,
      "z": 4,
      "name": "Cloth_Block_Wool_Blue_Light"
    },
    {
      "x": -2,
      "y": 4,
      "z": 4,
      "name": "Cloth_Block_Wool_Blue_Light"
    },
    {
      "x": -2,
      "y": 5,
      "z": 4,
      "name": "Cloth_Block_Wool_Blue_Light"
    },
    {
      "x": -2,
      "y": 6,
      "z": 4,
      "name": "Cloth_Block_Wool_Blue_Light"
    },
    {
      "x": -2,
      "y": 7,
      "z": 4,
      "name": "Cloth_Block_Wool_Blue_Light"
    },
    {
      "x": -2,
      "y": 8,
      "z": 4,
      "name": "Cloth_Block_Wool_Blue_Light"
    },
    {
      "x": -2,
      "y": 9,
      "z": 4,
      "name": "Cloth_Block_Wool_Blue_Light"
    },
    {
      "x": -2,
      "y": 10,
      "z": 4,
      "name": "Cloth_Block_Wool_Blue_Light"
    },
    {
      "x": -2,
      "y": 11,
      "z": 4,
      "name": "Cloth_Block_Wool_Blue_Light"
    },
    {
      "x": -2,
      "y": 12,
      "z": 4,
      "name": "Cloth_Block_Wool_Blue_Light"
    },
    {
      "x": -1,
      "y": -12,
      "z": -4,
      "name": "Rock_Marble"
    },
    {
      "x": -1,
      "y": -11,
      "z": -4,
      "name": "Rock_Marble"
    },
    {
      "x": -1,
      "y": -10,
      "z": -4,
      "name": "Rock_Marble"
    },
    {
      "x": -1,
      "y": -9,
      "z": -4,
      "name": "Rock_Marble"
    },
    {
      "x": -1,
      "y": -8,
      "z": -4,
      "name": "Rock_Marble"
    },
    {
      "x": -1,
      "y": -7,
      "z": -4,
      "name": "Rock_Marble"
    },
    {
      "x": -1,
      "y": -6,
      "z": -4,
      "name": "Rock_Marble"
    },
    {
      "x": -1,
      "y": -5,
      "z": -4,
      "name": "Rock_Marble"
    },
    {
      "x": -1,
      "y": -4,
      "z": -4,
      "name": "Rock_Marble"
    },
    {
      "x": -1,
      "y": -3,
      "z": -4,
      "name": "Rock_Marble"
    },
    {
      "x": -1,
      "y": -2,
      "z": -4,
      "name": "Rock_Marble"
    },
    {
      "x": -1,
      "y": -1,
      "z": -4,
      "name": "Rock_Marble"
    },
    {
      "x": -1,
      "y": 0,
      "z": -4,
      "name": "Rock_Marble"
    },
    {
      "x": -1,
      "y": 1,
      "z": -4,
      "name": "Rock_Marble"
    },
    {
      "x": -1,
      "y": 2,
      "z": -4,
      "name": "Rock_Marble"
    },
    {
      "x": -1,
      "y": 3,
      "z": -4,
      "name": "Rock_Marble"
    },
    {
      "x": -1,
      "y": 4,
      "z": -4,
      "name": "Rock_Marble"
    },
    {
      "x": -1,
      "y": 5,
      "z": -4,
      "name": "Rock_Marble"
    },
    {
      "x": -1,
      "y": 6,
      "z": -4,
      "name": "Rock_Marble"
    },
    {
      "x": -1,
      "y": 7,
      "z": -4,
      "name": "Rock_Marble"
    },
    {
      "x": -1,
      "y": 8,
      "z": -4,
      "name": "Rock_Marble"
    },
    {
      "x": -1,
      "y": 9,
      "z": -4,
      "name": "Rock_Marble"
    },
    {
      "x": -1,
      "y": 10,
      "z": -4,
      "name": "Rock_Marble"
    },
    {
      "x": -1,
      "y": 11,
      "z": -4,
      "name": "Rock_Marble"
    },
    {
      "x": -1,
      "y": 12,
      "z": -4,
      "name": "Rock_Marble"
    },
    {
      "x": -1,
      "y": -12,
      "z": -3,
      "name": "Cloth_Block_Wool_Blue_Light"
    },
    {
      "x": -1,
      "y": 12,
      "z": -3,
      "name": "Cloth_Block_Wool_Blue_Light"
    },
    {
      "x": -1,
      "y": -12,
      "z": -2,
      "name": "Cloth_Block_Wool_Blue_Light"
    },
    {
      "x": -1,
      "y": 12,
      "z": -2,
      "name": "Cloth_Block_Wool_Blue_Light"
    },
    {
      "x": -1,
      "y": -12,
      "z": -1,
      "name": "Cloth_Block_Wool_Blue_Light"
    },
    {
      "x": -1,
      "y": 12,
      "z": -1,
      "name": "Cloth_Block_Wool_Blue_Light"
    },
    {
      "x": -1,
      "y": -12,
      "z": 0,
      "name": "Cloth_Block_Wool_Blue_Light"
    },
    {
      "x": -1,
      "y": 12,
      "z": 0,
      "name": "Cloth_Block_Wool_Blue_Light"
    },
    {
      "x": -1,
      "y": -12,
      "z": 1,
      "name": "Cloth_Block_Wool_Blue_Light"
    },
    {
      "x": -1,
      "y": 12,
      "z": 1,
      "name": "Cloth_Block_Wool_Blue_Light"
    },
    {
      "x": -1,
      "y": -12,
      "z": 2,
      "name": "Cloth_Block_Wool_Blue_Light"
    },
    {
      "x": -1,
      "y": 12,
      "z": 2,
      "name": "Cloth_Block_Wool_Blue_Light"
    },
    {
      "x": -1,
      "y": -12,
      "z": 3,
      "name": "Cloth_Block_Wool_Blue_Light"
    },
    {
      "x": -1,
      "y": 12,
      "z": 3,
      "name": "Cloth_Block_Wool_Blue_Light"
    },
    {
      "x": -1,
      "y": -12,
      "z": 4,
      "name": "Cloth_Block_Wool_Blue_Light"
    },
    {
      "x": -1,
      "y": -11,
      "z": 4,
      "name": "Cloth_Block_Wool_Blue_Light"
    },
    {
      "x": -1,
      "y": -10,
      "z": 4,
      "name": "Cloth_Block_Wool_Blue_Light"
    },
    {
      "x": -1,
      "y": -9,
      "z": 4,
      "name": "Cloth_Block_Wool_Blue_Light"
    },
    {
      "x": -1,
      "y": -8,
      "z": 4,
      "name": "Cloth_Block_Wool_Blue_Light"
    },
    {
      "x": -1,
      "y": -7,
      "z": 4,
      "name": "Cloth_Block_Wool_Blue_Light"
    },
    {
      "x": -1,
      "y": -6,
      "z": 4,
      "name": "Cloth_Block_Wool_Blue_Light"
    },
    {
      "x": -1,
      "y": -5,
      "z": 4,
      "name": "Cloth_Block_Wool_Blue_Light"
    },
    {
      "x": -1,
      "y": -4,
      "z": 4,
      "name": "Cloth_Block_Wool_Blue_Light"
    },
    {
      "x": -1,
      "y": -3,
      "z": 4,
      "name": "Cloth_Block_Wool_Blue_Light"
    },
    {
      "x": -1,
      "y": -2,
      "z": 4,
      "name": "Cloth_Block_Wool_Blue_Light"
    },
    {
      "x": -1,
      "y": -1,
      "z": 4,
      "name": "Cloth_Block_Wool_Blue_Light"
    },
    {
      "x": -1,
      "y": 0,
      "z": 4,
      "name": "Cloth_Block_Wool_Blue_Light"
    },
    {
      "x": -1,
      "y": 1,
      "z": 4,
      "name": "Cloth_Block_Wool_Blue_Light"
    },
    {
      "x": -1,
      "y": 2,
      "z": 4,
      "name": "Cloth_Block_Wool_Blue_Light"
    },
    {
      "x": -1,
      "y": 3,
      "z": 4,
      "name": "Cloth_Block_Wool_Blue_Light"
    },
    {
      "x": -1,
      "y": 4,
      "z": 4,
      "name": "Cloth_Block_Wool_Blue_Light"
    },
    {
      "x": -1,
      "y": 5,
      "z": 4,
      "name": "Cloth_Block_Wool_Blue_Light"
    },
    {
      "x": -1,
      "y": 6,
      "z": 4,
      "name": "Cloth_Block_Wool_Blue_Light"
    },
    {
      "x": -1,
      "y": 7,
      "z": 4,
      "name": "Cloth_Block_Wool_Blue_Light"
    },
    {
      "x": -1,
      "y": 8,
      "z": 4,
      "name": "Cloth_Block_Wool_Blue_Light"
    },
    {
      "x": -1,
      "y": 9,
      "z": 4,
      "name": "Cloth_Block_Wool_Blue_Light"
    },
    {
      "x": -1,
      "y": 10,
      "z": 4,
      "name": "Cloth_Block_Wool_Blue_Light"
    },
    {
      "x": -1,
      "y": 11,
      "z": 4,
      "name": "Cloth_Block_Wool_Blue_Light"
    },
    {
      "x": -1,
      "y": 12,
      "z": 4,
      "name": "Cloth_Block_Wool_Blue_Light"
    },
    {
      "x": 0,
      "y": -12,
      "z": -4,
      "name": "Rock_Marble"
    },
    {
      "x": 0,
      "y": -11,
      "z": -4,
      "name": "Rock_Marble"
    },
    {
      "x": 0,
      "y": -10,
      "z": -4,
      "name": "Rock_Marble"
    },
    {
      "x": 0,
      "y": -9,
      "z": -4,
      "name": "Rock_Marble"
    },
    {
      "x": 0,
      "y": -8,
      "z": -4,
      "name": "Rock_Marble"
    },
    {
      "x": 0,
      "y": -7,
      "z": -4,
      "name": "Rock_Marble"
    },
    {
      "x": 0,
      "y": -6,
      "z": -4,
      "name": "Rock_Marble"
    },
    {
      "x": 0,
      "y": -5,
      "z": -4,
      "name": "Rock_Marble"
    },
    {
      "x": 0,
      "y": -4,
      "z": -4,
      "name": "Rock_Marble"
    },
    {
      "x": 0,
      "y": -3,
      "z": -4,
      "name": "Rock_Marble"
    },
    {
      "x": 0,
      "y": -2,
      "z": -4,
      "name": "Rock_Marble"
    },
    {
      "x": 0,
      "y": -1,
      "z": -4,
      "name": "Rock_Marble"
    },
    {
      "x": 0,
      "y": 0,
      "z": -4,
      "name": "Rock_Marble"
    },
    {
      "x": 0,
      "y": 1,
      "z": -4,
      "name": "Rock_Marble"
    },
    {
      "x": 0,
      "y": 2,
      "z": -4,
      "name": "Rock_Marble"
    },
    {
      "x": 0,
      "y": 3,
      "z": -4,
      "name": "Rock_Marble"
    },
    {
      "x": 0,
      "y": 4,
      "z": -4,
      "name": "Rock_Marble"
    },
    {
      "x": 0,
      "y": 5,
      "z": -4,
      "name": "Rock_Marble"
    },
    {
      "x": 0,
      "y": 6,
      "z": -4,
      "name": "Rock_Marble"
    },
    {
      "x": 0,
      "y": 7,
      "z": -4,
      "name": "Rock_Marble"
    },
    {
      "x": 0,
      "y": 8,
      "z": -4,
      "name": "Rock_Marble"
    },
    {
      "x": 0,
      "y": 9,
      "z": -4,
      "name": "Rock_Marble"
    },
    {
      "x": 0,
      "y": 10,
      "z": -4,
      "name": "Rock_Marble"
    },
    {
      "x": 0,
      "y": 11,
      "z": -4,
      "name": "Rock_Marble"
    },
    {
      "x": 0,
      "y": 12,
      "z": -4,
      "name": "Rock_Marble"
    },
    {
      "x": 0,
      "y": -12,
      "z": -3,
      "name": "Cloth_Block_Wool_Blue_Light"
    },
    {
      "x": 0,
      "y": 12,
      "z": -3,
      "name": "Cloth_Block_Wool_Blue_Light"
    },
    {
      "x": 0,
      "y": -12,
      "z": -2,
      "name": "Cloth_Block_Wool_Blue_Light"
    },
    {
      "x": 0,
      "y": 12,
      "z": -2,
      "name": "Cloth_Block_Wool_Blue_Light"
    },
    {
      "x": 0,
      "y": -12,
      "z": -1,
      "name": "Cloth_Block_Wool_Blue_Light"
    },
    {
      "x": 0,
      "y": 12,
      "z": -1,
      "name": "Cloth_Block_Wool_Blue_Light"
    },
    {
      "x": 0,
      "y": -12,
      "z": 0,
      "name": "Cloth_Block_Wool_Blue_Light"
    },
    {
      "x": 0,
      "y": 12,
      "z": 0,
      "name": "Cloth_Block_Wool_Blue_Light"
    },
    {
      "x": 0,
      "y": -12,
      "z": 1,
      "name": "Cloth_Block_Wool_Blue_Light"
    },
    {
      "x": 0,
      "y": 12,
      "z": 1,
      "name": "Cloth_Block_Wool_Blue_Light"
    },
    {
      "x": 0,
      "y": -12,
      "z": 2,
      "name": "Cloth_Block_Wool_Blue_Light"
    },
    {
      "x": 0,
      "y": 12,
      "z": 2,
      "name": "Cloth_Block_Wool_Blue_Light"
    },
    {
      "x": 0,
      "y": -12,
      "z": 3,
      "name": "Cloth_Block_Wool_Blue_Light"
    },
    {
      "x": 0,
      "y": 12,
      "z": 3,
      "name": "Cloth_Block_Wool_Blue_Light"
    },
    {
      "x": 0,
      "y": -12,
      "z": 4,
      "name": "Cloth_Block_Wool_Blue_Light"
    },
    {
      "x": 0,
      "y": -11,
      "z": 4,
      "name": "Cloth_Block_Wool_Blue_Light"
    },
    {
      "x": 0,
      "y": -10,
      "z": 4,
      "name": "Cloth_Block_Wool_Blue_Light"
    },
    {
      "x": 0,
      "y": -9,
      "z": 4,
      "name": "Cloth_Block_Wool_Blue_Light"
    },
    {
      "x": 0,
      "y": -8,
      "z": 4,
      "name": "Cloth_Block_Wool_Blue_Light"
    },
    {
      "x": 0,
      "y": -7,
      "z": 4,
      "name": "Cloth_Block_Wool_Blue_Light"
    },
    {
      "x": 0,
      "y": -6,
      "z": 4,
      "name": "Cloth_Block_Wool_Blue_Light"
    },
    {
      "x": 0,
      "y": -5,
      "z": 4,
      "name": "Cloth_Block_Wool_Blue_Light"
    },
    {
      "x": 0,
      "y": -4,
      "z": 4,
      "name": "Cloth_Block_Wool_Blue_Light"
    },
    {
      "x": 0,
      "y": -3,
      "z": 4,
      "name": "Cloth_Block_Wool_Blue_Light"
    },
    {
      "x": 0,
      "y": -2,
      "z": 4,
      "name": "Cloth_Block_Wool_Blue_Light"
    },
    {
      "x": 0,
      "y": -1,
      "z": 4,
      "name": "Cloth_Block_Wool_Blue_Light"
    },
    {
      "x": 0,
      "y": 0,
      "z": 4,
      "name": "Cloth_Block_Wool_Blue_Light"
    },
    {
      "x": 0,
      "y": 1,
      "z": 4,
      "name": "Cloth_Block_Wool_Blue_Light"
    },
    {
      "x": 0,
      "y": 2,
      "z": 4,
      "name": "Cloth_Block_Wool_Blue_Light"
    },
    {
      "x": 0,
      "y": 3,
      "z": 4,
      "name": "Cloth_Block_Wool_Blue_Light"
    },
    {
      "x": 0,
      "y": 4,
      "z": 4,
      "name": "Cloth_Block_Wool_Blue_Light"
    },
    {
      "x": 0,
      "y": 5,
      "z": 4,
      "name": "Cloth_Block_Wool_Blue_Light"
    },
    {
      "x": 0,
      "y": 6,
      "z": 4,
      "name": "Cloth_Block_Wool_Blue_Light"
    },
    {
      "x": 0,
      "y": 7,
      "z": 4,
      "name": "Cloth_Block_Wool_Blue_Light"
    },
    {
      "x": 0,
      "y": 8,
      "z": 4,
      "name": "Cloth_Block_Wool_Blue_Light"
    },
    {
      "x": 0,
      "y": 9,
      "z": 4,
      "name": "Cloth_Block_Wool_Blue_Light"
    },
    {
      "x": 0,
      "y": 10,
      "z": 4,
      "name": "Cloth_Block_Wool_Blue_Light"
    },
    {
      "x": 0,
      "y": 11,
      "z": 4,
      "name": "Cloth_Block_Wool_Blue_Light"
    },
    {
      "x": 0,
      "y": 12,
      "z": 4,
      "name": "Cloth_Block_Wool_Blue_Light"
    },
    {
      "x": 1,
      "y": -12,
      "z": -4,
      "name": "Rock_Marble"
    },
    {
      "x": 1,
      "y": -11,
      "z": -4,
      "name": "Rock_Marble"
    },
    {
      "x": 1,
      "y": -10,
      "z": -4,
      "name": "Rock_Marble"
    },
    {
      "x": 1,
      "y": -9,
      "z": -4,
      "name": "Rock_Marble"
    },
    {
      "x": 1,
      "y": -8,
      "z": -4,
      "name": "Rock_Marble"
    },
    {
      "x": 1,
      "y": -7,
      "z": -4,
      "name": "Rock_Marble"
    },
    {
      "x": 1,
      "y": -6,
      "z": -4,
      "name": "Rock_Marble"
    },
    {
      "x": 1,
      "y": -5,
      "z": -4,
      "name": "Rock_Marble"
    },
    {
      "x": 1,
      "y": -4,
      "z": -4,
      "name": "Rock_Marble"
    },
    {
      "x": 1,
      "y": -3,
      "z": -4,
      "name": "Rock_Marble"
    },
    {
      "x": 1,
      "y": -2,
      "z": -4,
      "name": "Rock_Marble"
    },
    {
      "x": 1,
      "y": -1,
      "z": -4,
      "name": "Rock_Marble"
    },
    {
      "x": 1,
      "y": 0,
      "z": -4,
      "name": "Rock_Marble"
    },
    {
      "x": 1,
      "y": 1,
      "z": -4,
      "name": "Rock_Marble"
    },
    {
      "x": 1,
      "y": 2,
      "z": -4,
      "name": "Rock_Marble"
    },
    {
      "x": 1,
      "y": 3,
      "z": -4,
      "name": "Rock_Marble"
    },
    {
      "x": 1,
      "y": 4,
      "z": -4,
      "name": "Rock_Marble"
    },
    {
      "x": 1,
      "y": 5,
      "z": -4,
      "name": "Rock_Marble"
    },
    {
      "x": 1,
      "y": 6,
      "z": -4,
      "name": "Rock_Marble"
    },
    {
      "x": 1,
      "y": 7,
      "z": -4,
      "name": "Rock_Marble"
    },
    {
      "x": 1,
      "y": 8,
      "z": -4,
      "name": "Rock_Marble"
    },
    {
      "x": 1,
      "y": 9,
      "z": -4,
      "name": "Rock_Marble"
    },
    {
      "x": 1,
      "y": 10,
      "z": -4,
      "name": "Rock_Marble"
    },
    {
      "x": 1,
      "y": 11,
      "z": -4,
      "name": "Rock_Marble"
    },
    {
      "x": 1,
      "y": 12,
      "z": -4,
      "name": "Rock_Marble"
    },
    {
      "x": 1,
      "y": -12,
      "z": -3,
      "name": "Cloth_Block_Wool_Blue_Light"
    },
    {
      "x": 1,
      "y": 12,
      "z": -3,
      "name": "Cloth_Block_Wool_Blue_Light"
    },
    {
      "x": 1,
      "y": -12,
      "z": -2,
      "name": "Cloth_Block_Wool_Blue_Light"
    },
    {
      "x": 1,
      "y": 12,
      "z": -2,
      "name": "Cloth_Block_Wool_Blue_Light"
    },
    {
      "x": 1,
      "y": -12,
      "z": -1,
      "name": "Cloth_Block_Wool_Blue_Light"
    },
    {
      "x": 1,
      "y": 12,
      "z": -1,
      "name": "Cloth_Block_Wool_Blue_Light"
    },
    {
      "x": 1,
      "y": -12,
      "z": 0,
      "name": "Cloth_Block_Wool_Blue_Light"
    },
    {
      "x": 1,
      "y": 12,
      "z": 0,
      "name": "Cloth_Block_Wool_Blue_Light"
    },
    {
      "x": 1,
      "y": -12,
      "z": 1,
      "name": "Cloth_Block_Wool_Blue_Light"
    },
    {
      "x": 1,
      "y": 12,
      "z": 1,
      "name": "Cloth_Block_Wool_Blue_Light"
    },
    {
      "x": 1,
      "y": -12,
      "z": 2,
      "name": "Cloth_Block_Wool_Blue_Light"
    },
    {
      "x": 1,
      "y": 12,
      "z": 2,
      "name": "Cloth_Block_Wool_Blue_Light"
    },
    {
      "x": 1,
      "y": -12,
      "z": 3,
      "name": "Cloth_Block_Wool_Blue_Light"
    },
    {
      "x": 1,
      "y": 12,
      "z": 3,
      "name": "Cloth_Block_Wool_Blue_Light"
    },
    {
      "x": 1,
      "y": -12,
      "z": 4,
      "name": "Cloth_Block_Wool_Blue_Light"
    },
    {
      "x": 1,
      "y": -11,
      "z": 4,
      "name": "Cloth_Block_Wool_Blue_Light"
    },
    {
      "x": 1,
      "y": -10,
      "z": 4,
      "name": "Cloth_Block_Wool_Blue_Light"
    },
    {
      "x": 1,
      "y": -9,
      "z": 4,
      "name": "Cloth_Block_Wool_Blue_Light"
    },
    {
      "x": 1,
      "y": -8,
      "z": 4,
      "name": "Cloth_Block_Wool_Blue_Light"
    },
    {
      "x": 1,
      "y": -7,
      "z": 4,
      "name": "Cloth_Block_Wool_Blue_Light"
    },
    {
      "x": 1,
      "y": -6,
      "z": 4,
      "name": "Cloth_Block_Wool_Blue_Light"
    },
    {
      "x": 1,
      "y": -5,
      "z": 4,
      "name": "Cloth_Block_Wool_Blue_Light"
    },
    {
      "x": 1,
      "y": -4,
      "z": 4,
      "name": "Cloth_Block_Wool_Blue_Light"
    },
    {
      "x": 1,
      "y": -3,
      "z": 4,
      "name": "Cloth_Block_Wool_Blue_Light"
    },
    {
      "x": 1,
      "y": -2,
      "z": 4,
      "name": "Cloth_Block_Wool_Blue_Light"
    },
    {
      "x": 1,
      "y": -1,
      "z": 4,
      "name": "Cloth_Block_Wool_Blue_Light"
    },
    {
      "x": 1,
      "y": 0,
      "z": 4,
      "name": "Cloth_Block_Wool_Blue_Light"
    },
    {
      "x": 1,
      "y": 1,
      "z": 4,
      "name": "Cloth_Block_Wool_Blue_Light"
    },
    {
      "x": 1,
      "y": 2,
      "z": 4,
      "name": "Cloth_Block_Wool_Blue_Light"
    },
    {
      "x": 1,
      "y": 3,
      "z": 4,
      "name": "Cloth_Block_Wool_Blue_Light"
    },
    {
      "x": 1,
      "y": 4,
      "z": 4,
      "name": "Cloth_Block_Wool_Blue_Light"
    },
    {
      "x": 1,
      "y": 5,
      "z": 4,
      "name": "Cloth_Block_Wool_Blue_Light"
    },
    {
      "x": 1,
      "y": 6,
      "z": 4,
      "name": "Cloth_Block_Wool_Blue_Light"
    },
    {
      "x": 1,
      "y": 7,
      "z": 4,
      "name": "Cloth_Block_Wool_Blue_Light"
    },
    {
      "x": 1,
      "y": 8,
      "z": 4,
      "name": "Cloth_Block_Wool_Blue_Light"
    },
    {
      "x": 1,
      "y": 9,
      "z": 4,
      "name": "Cloth_Block_Wool_Blue_Light"
    },
    {
      "x": 1,
      "y": 10,
      "z": 4,
      "name": "Cloth_Block_Wool_Blue_Light"
    },
    {
      "x": 1,
      "y": 11,
      "z": 4,
      "name": "Cloth_Block_Wool_Blue_Light"
    },
    {
      "x": 1,
      "y": 12,
      "z": 4,
      "name": "Cloth_Block_Wool_Blue_Light"
    },
    {
      "x": 2,
      "y": -12,
      "z": -4,
      "name": "Rock_Marble"
    },
    {
      "x": 2,
      "y": -11,
      "z": -4,
      "name": "Rock_Marble"
    },
    {
      "x": 2,
      "y": -10,
      "z": -4,
      "name": "Rock_Marble"
    },
    {
      "x": 2,
      "y": -9,
      "z": -4,
      "name": "Rock_Marble"
    },
    {
      "x": 2,
      "y": -8,
      "z": -4,
      "name": "Rock_Marble"
    },
    {
      "x": 2,
      "y": -7,
      "z": -4,
      "name": "Rock_Marble"
    },
    {
      "x": 2,
      "y": -6,
      "z": -4,
      "name": "Rock_Marble"
    },
    {
      "x": 2,
      "y": -5,
      "z": -4,
      "name": "Rock_Marble"
    },
    {
      "x": 2,
      "y": -4,
      "z": -4,
      "name": "Rock_Marble"
    },
    {
      "x": 2,
      "y": -3,
      "z": -4,
      "name": "Rock_Marble"
    },
    {
      "x": 2,
      "y": -2,
      "z": -4,
      "name": "Rock_Marble"
    },
    {
      "x": 2,
      "y": -1,
      "z": -4,
      "name": "Rock_Marble"
    },
    {
      "x": 2,
      "y": 0,
      "z": -4,
      "name": "Rock_Marble"
    },
    {
      "x": 2,
      "y": 1,
      "z": -4,
      "name": "Rock_Marble"
    },
    {
      "x": 2,
      "y": 2,
      "z": -4,
      "name": "Rock_Marble"
    },
    {
      "x": 2,
      "y": 3,
      "z": -4,
      "name": "Rock_Marble"
    },
    {
      "x": 2,
      "y": 4,
      "z": -4,
      "name": "Rock_Marble"
    },
    {
      "x": 2,
      "y": 5,
      "z": -4,
      "name": "Rock_Marble"
    },
    {
      "x": 2,
      "y": 6,
      "z": -4,
      "name": "Rock_Marble"
    },
    {
      "x": 2,
      "y": 7,
      "z": -4,
      "name": "Rock_Marble"
    },
    {
      "x": 2,
      "y": 8,
      "z": -4,
      "name": "Rock_Marble"
    },
    {
      "x": 2,
      "y": 9,
      "z": -4,
      "name": "Rock_Marble"
    },
    {
      "x": 2,
      "y": 10,
      "z": -4,
      "name": "Rock_Marble"
    },
    {
      "x": 2,
      "y": 11,
      "z": -4,
      "name": "Rock_Marble"
    },
    {
      "x": 2,
      "y": 12,
      "z": -4,
      "name": "Rock_Marble"
    },
    {
      "x": 2,
      "y": -12,
      "z": -3,
      "name": "Cloth_Block_Wool_Blue_Light"
    },
    {
      "x": 2,
      "y": 12,
      "z": -3,
      "name": "Cloth_Block_Wool_Blue_Light"
    },
    {
      "x": 2,
      "y": -12,
      "z": -2,
      "name": "Cloth_Block_Wool_Blue_Light"
    },
    {
      "x": 2,
      "y": 12,
      "z": -2,
      "name": "Cloth_Block_Wool_Blue_Light"
    },
    {
      "x": 2,
      "y": -12,
      "z": -1,
      "name": "Cloth_Block_Wool_Blue_Light"
    },
    {
      "x": 2,
      "y": 12,
      "z": -1,
      "name": "Cloth_Block_Wool_Blue_Light"
    },
    {
      "x": 2,
      "y": -12,
      "z": 0,
      "name": "Cloth_Block_Wool_Blue_Light"
    },
    {
      "x": 2,
      "y": 12,
      "z": 0,
      "name": "Cloth_Block_Wool_Blue_Light"
    },
    {
      "x": 2,
      "y": -12,
      "z": 1,
      "name": "Cloth_Block_Wool_Blue_Light"
    },
    {
      "x": 2,
      "y": 12,
      "z": 1,
      "name": "Cloth_Block_Wool_Blue_Light"
    },
    {
      "x": 2,
      "y": -12,
      "z": 2,
      "name": "Cloth_Block_Wool_Blue_Light"
    },
    {
      "x": 2,
      "y": 12,
      "z": 2,
      "name": "Cloth_Block_Wool_Blue_Light"
    },
    {
      "x": 2,
      "y": -12,
      "z": 3,
      "name": "Cloth_Block_Wool_Blue_Light"
    },
    {
      "x": 2,
      "y": 12,
      "z": 3,
      "name": "Cloth_Block_Wool_Blue_Light"
    },
    {
      "x": 2,
      "y": -12,
      "z": 4,
      "name": "Cloth_Block_Wool_Blue_Light"
    },
    {
      "x": 2,
      "y": -11,
      "z": 4,
      "name": "Cloth_Block_Wool_Blue_Light"
    },
    {
      "x": 2,
      "y": -10,
      "z": 4,
      "name": "Cloth_Block_Wool_Blue_Light"
    },
    {
      "x": 2,
      "y": -9,
      "z": 4,
      "name": "Cloth_Block_Wool_Blue_Light"
    },
    {
      "x": 2,
      "y": -8,
      "z": 4,
      "name": "Cloth_Block_Wool_Blue_Light"
    },
    {
      "x": 2,
      "y": -7,
      "z": 4,
      "name": "Cloth_Block_Wool_Blue_Light"
    },
    {
      "x": 2,
      "y": -6,
      "z": 4,
      "name": "Cloth_Block_Wool_Blue_Light"
    },
    {
      "x": 2,
      "y": -5,
      "z": 4,
      "name": "Cloth_Block_Wool_Blue_Light"
    },
    {
      "x": 2,
      "y": -4,
      "z": 4,
      "name": "Cloth_Block_Wool_Blue_Light"
    },
    {
      "x": 2,
      "y": -3,
      "z": 4,
      "name": "Cloth_Block_Wool_Blue_Light"
    },
    {
      "x": 2,
      "y": -2,
      "z": 4,
      "name": "Cloth_Block_Wool_Blue_Light"
    },
    {
      "x": 2,
      "y": -1,
      "z": 4,
      "name": "Cloth_Block_Wool_Blue_Light"
    },
    {
      "x": 2,
      "y": 0,
      "z": 4,
      "name": "Cloth_Block_Wool_Blue_Light"
    },
    {
      "x": 2,
      "y": 1,
      "z": 4,
      "name": "Cloth_Block_Wool_Blue_Light"
    },
    {
      "x": 2,
      "y": 2,
      "z": 4,
      "name": "Cloth_Block_Wool_Blue_Light"
    },
    {
      "x": 2,
      "y": 3,
      "z": 4,
      "name": "Cloth_Block_Wool_Blue_Light"
    },
    {
      "x": 2,
      "y": 4,
      "z": 4,
      "name": "Cloth_Block_Wool_Blue_Light"
    },
    {
      "x": 2,
      "y": 5,
      "z": 4,
      "name": "Cloth_Block_Wool_Blue_Light"
    },
    {
      "x": 2,
      "y": 6,
      "z": 4,
      "name": "Cloth_Block_Wool_Blue_Light"
    },
    {
      "x": 2,
      "y": 7,
      "z": 4,
      "name": "Cloth_Block_Wool_Blue_Light"
    },
    {
      "x": 2,
      "y": 8,
      "z": 4,
      "name": "Cloth_Block_Wool_Blue_Light"
    },
    {
      "x": 2,
      "y": 9,
      "z": 4,
      "name": "Cloth_Block_Wool_Blue_Light"
    },
    {
      "x": 2,
      "y": 10,
      "z": 4,
      "name": "Cloth_Block_Wool_Blue_Light"
    },
    {
      "x": 2,
      "y": 11,
      "z": 4,
      "name": "Cloth_Block_Wool_Blue_Light"
    },
    {
      "x": 2,
      "y": 12,
      "z": 4,
      "name": "Cloth_Block_Wool_Blue_Light"
    },
    {
      "x": 3,
      "y": -12,
      "z": -4,
      "name": "Rock_Marble"
    },
    {
      "x": 3,
      "y": -11,
      "z": -4,
      "name": "Rock_Marble"
    },
    {
      "x": 3,
      "y": -10,
      "z": -4,
      "name": "Rock_Marble"
    },
    {
      "x": 3,
      "y": -9,
      "z": -4,
      "name": "Rock_Marble"
    },
    {
      "x": 3,
      "y": -8,
      "z": -4,
      "name": "Rock_Marble"
    },
    {
      "x": 3,
      "y": -7,
      "z": -4,
      "name": "Rock_Marble"
    },
    {
      "x": 3,
      "y": -6,
      "z": -4,
      "name": "Rock_Marble"
    },
    {
      "x": 3,
      "y": -5,
      "z": -4,
      "name": "Rock_Marble"
    },
    {
      "x": 3,
      "y": -4,
      "z": -4,
      "name": "Rock_Marble"
    },
    {
      "x": 3,
      "y": -3,
      "z": -4,
      "name": "Rock_Marble"
    },
    {
      "x": 3,
      "y": -2,
      "z": -4,
      "name": "Rock_Marble"
    },
    {
      "x": 3,
      "y": -1,
      "z": -4,
      "name": "Rock_Marble"
    },
    {
      "x": 3,
      "y": 0,
      "z": -4,
      "name": "Rock_Marble"
    },
    {
      "x": 3,
      "y": 1,
      "z": -4,
      "name": "Rock_Marble"
    },
    {
      "x": 3,
      "y": 2,
      "z": -4,
      "name": "Rock_Marble"
    },
    {
      "x": 3,
      "y": 3,
      "z": -4,
      "name": "Rock_Marble"
    },
    {
      "x": 3,
      "y": 4,
      "z": -4,
      "name": "Rock_Marble"
    },
    {
      "x": 3,
      "y": 5,
      "z": -4,
      "name": "Rock_Marble"
    },
    {
      "x": 3,
      "y": 6,
      "z": -4,
      "name": "Rock_Marble"
    },
    {
      "x": 3,
      "y": 7,
      "z": -4,
      "name": "Rock_Marble"
    },
    {
      "x": 3,
      "y": 8,
      "z": -4,
      "name": "Rock_Marble"
    },
    {
      "x": 3,
      "y": 9,
      "z": -4,
      "name": "Rock_Marble"
    },
    {
      "x": 3,
      "y": 10,
      "z": -4,
      "name": "Rock_Marble"
    },
    {
      "x": 3,
      "y": 11,
      "z": -4,
      "name": "Rock_Marble"
    },
    {
      "x": 3,
      "y": 12,
      "z": -4,
      "name": "Rock_Marble"
    },
    {
      "x": 3,
      "y": -12,
      "z": -3,
      "name": "Cloth_Block_Wool_Blue_Light"
    },
    {
      "x": 3,
      "y": 12,
      "z": -3,
      "name": "Cloth_Block_Wool_Blue_Light"
    },
    {
      "x": 3,
      "y": -12,
      "z": -2,
      "name": "Cloth_Block_Wool_Blue_Light"
    },
    {
      "x": 3,
      "y": 12,
      "z": -2,
      "name": "Cloth_Block_Wool_Blue_Light"
    },
    {
      "x": 3,
      "y": -12,
      "z": -1,
      "name": "Cloth_Block_Wool_Blue_Light"
    },
    {
      "x": 3,
      "y": 12,
      "z": -1,
      "name": "Cloth_Block_Wool_Blue_Light"
    },
    {
      "x": 3,
      "y": -12,
      "z": 0,
      "name": "Cloth_Block_Wool_Blue_Light"
    },
    {
      "x": 3,
      "y": 12,
      "z": 0,
      "name": "Cloth_Block_Wool_Blue_Light"
    },
    {
      "x": 3,
      "y": -12,
      "z": 1,
      "name": "Cloth_Block_Wool_Blue_Light"
    },
    {
      "x": 3,
      "y": 12,
      "z": 1,
      "name": "Cloth_Block_Wool_Blue_Light"
    },
    {
      "x": 3,
      "y": -12,
      "z": 2,
      "name": "Cloth_Block_Wool_Blue_Light"
    },
    {
      "x": 3,
      "y": 12,
      "z": 2,
      "name": "Cloth_Block_Wool_Blue_Light"
    },
    {
      "x": 3,
      "y": -12,
      "z": 3,
      "name": "Cloth_Block_Wool_Blue_Light"
    },
    {
      "x": 3,
      "y": 12,
      "z": 3,
      "name": "Cloth_Block_Wool_Blue_Light"
    },
    {
      "x": 3,
      "y": -12,
      "z": 4,
      "name": "Cloth_Block_Wool_Blue_Light"
    },
    {
      "x": 3,
      "y": -11,
      "z": 4,
      "name": "Cloth_Block_Wool_Blue_Light"
    },
    {
      "x": 3,
      "y": -10,
      "z": 4,
      "name": "Cloth_Block_Wool_Blue_Light"
    },
    {
      "x": 3,
      "y": -9,
      "z": 4,
      "name": "Cloth_Block_Wool_Blue_Light"
    },
    {
      "x": 3,
      "y": -8,
      "z": 4,
      "name": "Cloth_Block_Wool_Blue_Light"
    },
    {
      "x": 3,
      "y": -7,
      "z": 4,
      "name": "Cloth_Block_Wool_Blue_Light"
    },
    {
      "x": 3,
      "y": -6,
      "z": 4,
      "name": "Cloth_Block_Wool_Blue_Light"
    },
    {
      "x": 3,
      "y": -5,
      "z": 4,
      "name": "Cloth_Block_Wool_Blue_Light"
    },
    {
      "x": 3,
      "y": -4,
      "z": 4,
      "name": "Cloth_Block_Wool_Blue_Light"
    },
    {
      "x": 3,
      "y": -3,
      "z": 4,
      "name": "Cloth_Block_Wool_Blue_Light"
    },
    {
      "x": 3,
      "y": -2,
      "z": 4,
      "name": "Cloth_Block_Wool_Blue_Light"
    },
    {
      "x": 3,
      "y": -1,
      "z": 4,
      "name": "Cloth_Block_Wool_Blue_Light"
    },
    {
      "x": 3,
      "y": 0,
      "z": 4,
      "name": "Cloth_Block_Wool_Blue_Light"
    },
    {
      "x": 3,
      "y": 1,
      "z": 4,
      "name": "Cloth_Block_Wool_Blue_Light"
    },
    {
      "x": 3,
      "y": 2,
      "z": 4,
      "name": "Cloth_Block_Wool_Blue_Light"
    },
    {
      "x": 3,
      "y": 3,
      "z": 4,
      "name": "Cloth_Block_Wool_Blue_Light"
    },
    {
      "x": 3,
      "y": 4,
      "z": 4,
      "name": "Cloth_Block_Wool_Blue_Light"
    },
    {
      "x": 3,
      "y": 5,
      "z": 4,
      "name": "Cloth_Block_Wool_Blue_Light"
    },
    {
      "x": 3,
      "y": 6,
      "z": 4,
      "name": "Cloth_Block_Wool_Blue_Light"
    },
    {
      "x": 3,
      "y": 7,
      "z": 4,
      "name": "Cloth_Block_Wool_Blue_Light"
    },
    {
      "x": 3,
      "y": 8,
      "z": 4,
      "name": "Cloth_Block_Wool_Blue_Light"
    },
    {
      "x": 3,
      "y": 9,
      "z": 4,
      "name": "Cloth_Block_Wool_Blue_Light"
    },
    {
      "x": 3,
      "y": 10,
      "z": 4,
      "name": "Cloth_Block_Wool_Blue_Light"
    },
    {
      "x": 3,
      "y": 11,
      "z": 4,
      "name": "Cloth_Block_Wool_Blue_Light"
    },
    {
      "x": 3,
      "y": 12,
      "z": 4,
      "name": "Cloth_Block_Wool_Blue_Light"
    },
    {
      "x": 4,
      "y": -12,
      "z": -4,
      "name": "Rock_Marble"
    },
    {
      "x": 4,
      "y": -11,
      "z": -4,
      "name": "Rock_Marble"
    },
    {
      "x": 4,
      "y": -10,
      "z": -4,
      "name": "Rock_Marble"
    },
    {
      "x": 4,
      "y": -9,
      "z": -4,
      "name": "Rock_Marble"
    },
    {
      "x": 4,
      "y": -8,
      "z": -4,
      "name": "Rock_Marble"
    },
    {
      "x": 4,
      "y": -7,
      "z": -4,
      "name": "Rock_Marble"
    },
    {
      "x": 4,
      "y": -6,
      "z": -4,
      "name": "Rock_Marble"
    },
    {
      "x": 4,
      "y": -5,
      "z": -4,
      "name": "Rock_Marble"
    },
    {
      "x": 4,
      "y": -4,
      "z": -4,
      "name": "Rock_Marble"
    },
    {
      "x": 4,
      "y": -3,
      "z": -4,
      "name": "Rock_Marble"
    },
    {
      "x": 4,
      "y": -2,
      "z": -4,
      "name": "Rock_Marble"
    },
    {
      "x": 4,
      "y": -1,
      "z": -4,
      "name": "Rock_Marble"
    },
    {
      "x": 4,
      "y": 0,
      "z": -4,
      "name": "Rock_Marble"
    },
    {
      "x": 4,
      "y": 1,
      "z": -4,
      "name": "Rock_Marble"
    },
    {
      "x": 4,
      "y": 2,
      "z": -4,
      "name": "Rock_Marble"
    },
    {
      "x": 4,
      "y": 3,
      "z": -4,
      "name": "Rock_Marble"
    },
    {
      "x": 4,
      "y": 4,
      "z": -4,
      "name": "Rock_Marble"
    },
    {
      "x": 4,
      "y": 5,
      "z": -4,
      "name": "Rock_Marble"
    },
    {
      "x": 4,
      "y": 6,
      "z": -4,
      "name": "Rock_Marble"
    },
    {
      "x": 4,
      "y": 7,
      "z": -4,
      "name": "Rock_Marble"
    },
    {
      "x": 4,
      "y": 8,
      "z": -4,
      "name": "Rock_Marble"
    },
    {
      "x": 4,
      "y": 9,
      "z": -4,
      "name": "Rock_Marble"
    },
    {
      "x": 4,
      "y": 10,
      "z": -4,
      "name": "Rock_Marble"
    },
    {
      "x": 4,
      "y": 11,
      "z": -4,
      "name": "Rock_Marble"
    },
    {
      "x": 4,
      "y": 12,
      "z": -4,
      "name": "Rock_Marble"
    },
    {
      "x": 4,
      "y": -12,
      "z": -3,
      "name": "Cloth_Block_Wool_Blue_Light"
    },
    {
      "x": 4,
      "y": -11,
      "z": -3,
      "name": "Cloth_Block_Wool_Blue_Light"
    },
    {
      "x": 4,
      "y": -10,
      "z": -3,
      "name": "Cloth_Block_Wool_Blue_Light"
    },
    {
      "x": 4,
      "y": -9,
      "z": -3,
      "name": "Cloth_Block_Wool_Blue_Light"
    },
    {
      "x": 4,
      "y": -8,
      "z": -3,
      "name": "Cloth_Block_Wool_Blue_Light"
    },
    {
      "x": 4,
      "y": -7,
      "z": -3,
      "name": "Cloth_Block_Wool_Blue_Light"
    },
    {
      "x": 4,
      "y": -6,
      "z": -3,
      "name": "Cloth_Block_Wool_Blue_Light"
    },
    {
      "x": 4,
      "y": -5,
      "z": -3,
      "name": "Cloth_Block_Wool_Blue_Light"
    },
    {
      "x": 4,
      "y": -4,
      "z": -3,
      "name": "Cloth_Block_Wool_Blue_Light"
    },
    {
      "x": 4,
      "y": -3,
      "z": -3,
      "name": "Cloth_Block_Wool_Blue_Light"
    },
    {
      "x": 4,
      "y": -2,
      "z": -3,
      "name": "Cloth_Block_Wool_Blue_Light"
    },
    {
      "x": 4,
      "y": -1,
      "z": -3,
      "name": "Cloth_Block_Wool_Blue_Light"
    },
    {
      "x": 4,
      "y": 0,
      "z": -3,
      "name": "Cloth_Block_Wool_Blue_Light"
    },
    {
      "x": 4,
      "y": 1,
      "z": -3,
      "name": "Cloth_Block_Wool_Blue_Light"
    },
    {
      "x": 4,
      "y": 2,
      "z": -3,
      "name": "Cloth_Block_Wool_Blue_Light"
    },
    {
      "x": 4,
      "y": 3,
      "z": -3,
      "name": "Cloth_Block_Wool_Blue_Light"
    },
    {
      "x": 4,
      "y": 4,
      "z": -3,
      "name": "Cloth_Block_Wool_Blue_Light"
    },
    {
      "x": 4,
      "y": 5,
      "z": -3,
      "name": "Cloth_Block_Wool_Blue_Light"
    },
    {
      "x": 4,
      "y": 6,
      "z": -3,
      "name": "Cloth_Block_Wool_Blue_Light"
    },
    {
      "x": 4,
      "y": 7,
      "z": -3,
      "name": "Cloth_Block_Wool_Blue_Light"
    },
    {
      "x": 4,
      "y": 8,
      "z": -3,
      "name": "Cloth_Block_Wool_Blue_Light"
    },
    {
      "x": 4,
      "y": 9,
      "z": -3,
      "name": "Cloth_Block_Wool_Blue_Light"
    },
    {
      "x": 4,
      "y": 10,
      "z": -3,
      "name": "Cloth_Block_Wool_Blue_Light"
    },
    {
      "x": 4,
      "y": 11,
      "z": -3,
      "name": "Cloth_Block_Wool_Blue_Light"
    },
    {
      "x": 4,
      "y": 12,
      "z": -3,
      "name": "Cloth_Block_Wool_Blue_Light"
    },
    {
      "x": 4,
      "y": -12,
      "z": -2,
      "name": "Cloth_Block_Wool_Blue_Light"
    },
    {
      "x": 4,
      "y": -11,
      "z": -2,
      "name": "Cloth_Block_Wool_Blue_Light"
    },
    {
      "x": 4,
      "y": -10,
      "z": -2,
      "name": "Cloth_Block_Wool_Blue_Light"
    },
    {
      "x": 4,
      "y": -9,
      "z": -2,
      "name": "Cloth_Block_Wool_Blue_Light"
    },
    {
      "x": 4,
      "y": -8,
      "z": -2,
      "name": "Cloth_Block_Wool_Blue_Light"
    },
    {
      "x": 4,
      "y": -7,
      "z": -2,
      "name": "Cloth_Block_Wool_Blue_Light"
    },
    {
      "x": 4,
      "y": -6,
      "z": -2,
      "name": "Cloth_Block_Wool_Blue_Light"
    },
    {
      "x": 4,
      "y": -5,
      "z": -2,
      "name": "Cloth_Block_Wool_Blue_Light"
    },
    {
      "x": 4,
      "y": -4,
      "z": -2,
      "name": "Cloth_Block_Wool_Blue_Light"
    },
    {
      "x": 4,
      "y": -3,
      "z": -2,
      "name": "Cloth_Block_Wool_Blue_Light"
    },
    {
      "x": 4,
      "y": -2,
      "z": -2,
      "name": "Cloth_Block_Wool_Blue_Light"
    },
    {
      "x": 4,
      "y": -1,
      "z": -2,
      "name": "Cloth_Block_Wool_Blue_Light"
    },
    {
      "x": 4,
      "y": 0,
      "z": -2,
      "name": "Cloth_Block_Wool_Blue_Light"
    },
    {
      "x": 4,
      "y": 1,
      "z": -2,
      "name": "Cloth_Block_Wool_Blue_Light"
    },
    {
      "x": 4,
      "y": 2,
      "z": -2,
      "name": "Cloth_Block_Wool_Blue_Light"
    },
    {
      "x": 4,
      "y": 3,
      "z": -2,
      "name": "Cloth_Block_Wool_Blue_Light"
    },
    {
      "x": 4,
      "y": 4,
      "z": -2,
      "name": "Cloth_Block_Wool_Blue_Light"
    },
    {
      "x": 4,
      "y": 5,
      "z": -2,
      "name": "Cloth_Block_Wool_Blue_Light"
    },
    {
      "x": 4,
      "y": 6,
      "z": -2,
      "name": "Cloth_Block_Wool_Blue_Light"
    },
    {
      "x": 4,
      "y": 7,
      "z": -2,
      "name": "Cloth_Block_Wool_Blue_Light"
    },
    {
      "x": 4,
      "y": 8,
      "z": -2,
      "name": "Cloth_Block_Wool_Blue_Light"
    },
    {
      "x": 4,
      "y": 9,
      "z": -2,
      "name": "Cloth_Block_Wool_Blue_Light"
    },
    {
      "x": 4,
      "y": 10,
      "z": -2,
      "name": "Cloth_Block_Wool_Blue_Light"
    },
    {
      "x": 4,
      "y": 11,
      "z": -2,
      "name": "Cloth_Block_Wool_Blue_Light"
    },
    {
      "x": 4,
      "y": 12,
      "z": -2,
      "name": "Cloth_Block_Wool_Blue_Light"
    },
    {
      "x": 4,
      "y": -12,
      "z": -1,
      "name": "Cloth_Block_Wool_Blue_Light"
    },
    {
      "x": 4,
      "y": -11,
      "z": -1,
      "name": "Cloth_Block_Wool_Blue_Light"
    },
    {
      "x": 4,
      "y": -10,
      "z": -1,
      "name": "Cloth_Block_Wool_Blue_Light"
    },
    {
      "x": 4,
      "y": -9,
      "z": -1,
      "name": "Cloth_Block_Wool_Blue_Light"
    },
    {
      "x": 4,
      "y": -8,
      "z": -1,
      "name": "Cloth_Block_Wool_Blue_Light"
    },
    {
      "x": 4,
      "y": -7,
      "z": -1,
      "name": "Cloth_Block_Wool_Blue_Light"
    },
    {
      "x": 4,
      "y": -6,
      "z": -1,
      "name": "Cloth_Block_Wool_Blue_Light"
    },
    {
      "x": 4,
      "y": -5,
      "z": -1,
      "name": "Cloth_Block_Wool_Blue_Light"
    },
    {
      "x": 4,
      "y": -4,
      "z": -1,
      "name": "Cloth_Block_Wool_Blue_Light"
    },
    {
      "x": 4,
      "y": -3,
      "z": -1,
      "name": "Cloth_Block_Wool_Blue_Light"
    },
    {
      "x": 4,
      "y": -2,
      "z": -1,
      "name": "Cloth_Block_Wool_Blue_Light"
    },
    {
      "x": 4,
      "y": -1,
      "z": -1,
      "name": "Cloth_Block_Wool_Blue_Light"
    },
    {
      "x": 4,
      "y": 0,
      "z": -1,
      "name": "Cloth_Block_Wool_Blue_Light"
    },
    {
      "x": 4,
      "y": 1,
      "z": -1,
      "name": "Cloth_Block_Wool_Blue_Light"
    },
    {
      "x": 4,
      "y": 2,
      "z": -1,
      "name": "Cloth_Block_Wool_Blue_Light"
    },
    {
      "x": 4,
      "y": 3,
      "z": -1,
      "name": "Cloth_Block_Wool_Blue_Light"
    },
    {
      "x": 4,
      "y": 4,
      "z": -1,
      "name": "Cloth_Block_Wool_Blue_Light"
    },
    {
      "x": 4,
      "y": 5,
      "z": -1,
      "name": "Cloth_Block_Wool_Blue_Light"
    },
    {
      "x": 4,
      "y": 6,
      "z": -1,
      "name": "Cloth_Block_Wool_Blue_Light"
    },
    {
      "x": 4,
      "y": 7,
      "z": -1,
      "name": "Cloth_Block_Wool_Blue_Light"
    },
    {
      "x": 4,
      "y": 8,
      "z": -1,
      "name": "Cloth_Block_Wool_Blue_Light"
    },
    {
      "x": 4,
      "y": 9,
      "z": -1,
      "name": "Cloth_Block_Wool_Blue_Light"
    },
    {
      "x": 4,
      "y": 10,
      "z": -1,
      "name": "Cloth_Block_Wool_Blue_Light"
    },
    {
      "x": 4,
      "y": 11,
      "z": -1,
      "name": "Cloth_Block_Wool_Blue_Light"
    },
    {
      "x": 4,
      "y": 12,
      "z": -1,
      "name": "Cloth_Block_Wool_Blue_Light"
    },
    {
      "x": 4,
      "y": -12,
      "z": 0,
      "name": "Cloth_Block_Wool_Blue_Light"
    },
    {
      "x": 4,
      "y": -11,
      "z": 0,
      "name": "Cloth_Block_Wool_Blue_Light"
    },
    {
      "x": 4,
      "y": -10,
      "z": 0,
      "name": "Cloth_Block_Wool_Blue_Light"
    },
    {
      "x": 4,
      "y": -9,
      "z": 0,
      "name": "Cloth_Block_Wool_Blue_Light"
    },
    {
      "x": 4,
      "y": -8,
      "z": 0,
      "name": "Cloth_Block_Wool_Blue_Light"
    },
    {
      "x": 4,
      "y": -7,
      "z": 0,
      "name": "Cloth_Block_Wool_Blue_Light"
    },
    {
      "x": 4,
      "y": -6,
      "z": 0,
      "name": "Cloth_Block_Wool_Blue_Light"
    },
    {
      "x": 4,
      "y": -5,
      "z": 0,
      "name": "Cloth_Block_Wool_Blue_Light"
    },
    {
      "x": 4,
      "y": -4,
      "z": 0,
      "name": "Cloth_Block_Wool_Blue_Light"
    },
    {
      "x": 4,
      "y": -3,
      "z": 0,
      "name": "Cloth_Block_Wool_Blue_Light"
    },
    {
      "x": 4,
      "y": -2,
      "z": 0,
      "name": "Cloth_Block_Wool_Blue_Light"
    },
    {
      "x": 4,
      "y": -1,
      "z": 0,
      "name": "Cloth_Block_Wool_Blue_Light"
    },
    {
      "x": 4,
      "y": 0,
      "z": 0,
      "name": "Cloth_Block_Wool_Blue_Light"
    },
    {
      "x": 4,
      "y": 1,
      "z": 0,
      "name": "Cloth_Block_Wool_Blue_Light"
    },
    {
      "x": 4,
      "y": 2,
      "z": 0,
      "name": "Cloth_Block_Wool_Blue_Light"
    },
    {
      "x": 4,
      "y": 3,
      "z": 0,
      "name": "Cloth_Block_Wool_Blue_Light"
    },
    {
      "x": 4,
      "y": 4,
      "z": 0,
      "name": "Cloth_Block_Wool_Blue_Light"
    },
    {
      "x": 4,
      "y": 5,
      "z": 0,
      "name": "Cloth_Block_Wool_Blue_Light"
    },
    {
      "x": 4,
      "y": 6,
      "z": 0,
      "name": "Cloth_Block_Wool_Blue_Light"
    },
    {
      "x": 4,
      "y": 7,
      "z": 0,
      "name": "Cloth_Block_Wool_Blue_Light"
    },
    {
      "x": 4,
      "y": 8,
      "z": 0,
      "name": "Cloth_Block_Wool_Blue_Light"
    },
    {
      "x": 4,
      "y": 9,
      "z": 0,
      "name": "Cloth_Block_Wool_Blue_Light"
    },
    {
      "x": 4,
      "y": 10,
      "z": 0,
      "name": "Cloth_Block_Wool_Blue_Light"
    },
    {
      "x": 4,
      "y": 11,
      "z": 0,
      "name": "Cloth_Block_Wool_Blue_Light"
    },
    {
      "x": 4,
      "y": 12,
      "z": 0,
      "name": "Cloth_Block_Wool_Blue_Light"
    },
    {
      "x": 4,
      "y": -12,
      "z": 1,
      "name": "Cloth_Block_Wool_Blue_Light"
    },
    {
      "x": 4,
      "y": -11,
      "z": 1,
      "name": "Cloth_Block_Wool_Blue_Light"
    },
    {
      "x": 4,
      "y": -10,
      "z": 1,
      "name": "Cloth_Block_Wool_Blue_Light"
    },
    {
      "x": 4,
      "y": -9,
      "z": 1,
      "name": "Cloth_Block_Wool_Blue_Light"
    },
    {
      "x": 4,
      "y": -8,
      "z": 1,
      "name": "Cloth_Block_Wool_Blue_Light"
    },
    {
      "x": 4,
      "y": -7,
      "z": 1,
      "name": "Cloth_Block_Wool_Blue_Light"
    },
    {
      "x": 4,
      "y": -6,
      "z": 1,
      "name": "Cloth_Block_Wool_Blue_Light"
    },
    {
      "x": 4,
      "y": -5,
      "z": 1,
      "name": "Cloth_Block_Wool_Blue_Light"
    },
    {
      "x": 4,
      "y": -4,
      "z": 1,
      "name": "Cloth_Block_Wool_Blue_Light"
    },
    {
      "x": 4,
      "y": -3,
      "z": 1,
      "name": "Cloth_Block_Wool_Blue_Light"
    },
    {
      "x": 4,
      "y": -2,
      "z": 1,
      "name": "Cloth_Block_Wool_Blue_Light"
    },
    {
      "x": 4,
      "y": -1,
      "z": 1,
      "name": "Cloth_Block_Wool_Blue_Light"
    },
    {
      "x": 4,
      "y": 0,
      "z": 1,
      "name": "Cloth_Block_Wool_Blue_Light"
    },
    {
      "x": 4,
      "y": 1,
      "z": 1,
      "name": "Cloth_Block_Wool_Blue_Light"
    },
    {
      "x": 4,
      "y": 2,
      "z": 1,
      "name": "Cloth_Block_Wool_Blue_Light"
    },
    {
      "x": 4,
      "y": 3,
      "z": 1,
      "name": "Cloth_Block_Wool_Blue_Light"
    },
    {
      "x": 4,
      "y": 4,
      "z": 1,
      "name": "Cloth_Block_Wool_Blue_Light"
    },
    {
      "x": 4,
      "y": 5,
      "z": 1,
      "name": "Cloth_Block_Wool_Blue_Light"
    },
    {
      "x": 4,
      "y": 6,
      "z": 1,
      "name": "Cloth_Block_Wool_Blue_Light"
    },
    {
      "x": 4,
      "y": 7,
      "z": 1,
      "name": "Cloth_Block_Wool_Blue_Light"
    },
    {
      "x": 4,
      "y": 8,
      "z": 1,
      "name": "Cloth_Block_Wool_Blue_Light"
    },
    {
      "x": 4,
      "y": 9,
      "z": 1,
      "name": "Cloth_Block_Wool_Blue_Light"
    },
    {
      "x": 4,
      "y": 10,
      "z": 1,
      "name": "Cloth_Block_Wool_Blue_Light"
    },
    {
      "x": 4,
      "y": 11,
      "z": 1,
      "name": "Cloth_Block_Wool_Blue_Light"
    },
    {
      "x": 4,
      "y": 12,
      "z": 1,
      "name": "Cloth_Block_Wool_Blue_Light"
    },
    {
      "x": 4,
      "y": -12,
      "z": 2,
      "name": "Cloth_Block_Wool_Blue_Light"
    },
    {
      "x": 4,
      "y": -11,
      "z": 2,
      "name": "Cloth_Block_Wool_Blue_Light"
    },
    {
      "x": 4,
      "y": -10,
      "z": 2,
      "name": "Cloth_Block_Wool_Blue_Light"
    },
    {
      "x": 4,
      "y": -9,
      "z": 2,
      "name": "Cloth_Block_Wool_Blue_Light"
    },
    {
      "x": 4,
      "y": -8,
      "z": 2,
      "name": "Cloth_Block_Wool_Blue_Light"
    },
    {
      "x": 4,
      "y": -7,
      "z": 2,
      "name": "Cloth_Block_Wool_Blue_Light"
    },
    {
      "x": 4,
      "y": -6,
      "z": 2,
      "name": "Cloth_Block_Wool_Blue_Light"
    },
    {
      "x": 4,
      "y": -5,
      "z": 2,
      "name": "Cloth_Block_Wool_Blue_Light"
    },
    {
      "x": 4,
      "y": -4,
      "z": 2,
      "name": "Cloth_Block_Wool_Blue_Light"
    },
    {
      "x": 4,
      "y": -3,
      "z": 2,
      "name": "Cloth_Block_Wool_Blue_Light"
    },
    {
      "x": 4,
      "y": -2,
      "z": 2,
      "name": "Cloth_Block_Wool_Blue_Light"
    },
    {
      "x": 4,
      "y": -1,
      "z": 2,
      "name": "Cloth_Block_Wool_Blue_Light"
    },
    {
      "x": 4,
      "y": 0,
      "z": 2,
      "name": "Cloth_Block_Wool_Blue_Light"
    },
    {
      "x": 4,
      "y": 1,
      "z": 2,
      "name": "Cloth_Block_Wool_Blue_Light"
    },
    {
      "x": 4,
      "y": 2,
      "z": 2,
      "name": "Cloth_Block_Wool_Blue_Light"
    },
    {
      "x": 4,
      "y": 3,
      "z": 2,
      "name": "Cloth_Block_Wool_Blue_Light"
    },
    {
      "x": 4,
      "y": 4,
      "z": 2,
      "name": "Cloth_Block_Wool_Blue_Light"
    },
    {
      "x": 4,
      "y": 5,
      "z": 2,
      "name": "Cloth_Block_Wool_Blue_Light"
    },
    {
      "x": 4,
      "y": 6,
      "z": 2,
      "name": "Cloth_Block_Wool_Blue_Light"
    },
    {
      "x": 4,
      "y": 7,
      "z": 2,
      "name": "Cloth_Block_Wool_Blue_Light"
    },
    {
      "x": 4,
      "y": 8,
      "z": 2,
      "name": "Cloth_Block_Wool_Blue_Light"
    },
    {
      "x": 4,
      "y": 9,
      "z": 2,
      "name": "Cloth_Block_Wool_Blue_Light"
    },
    {
      "x": 4,
      "y": 10,
      "z": 2,
      "name": "Cloth_Block_Wool_Blue_Light"
    },
    {
      "x": 4,
      "y": 11,
      "z": 2,
      "name": "Cloth_Block_Wool_Blue_Light"
    },
    {
      "x": 4,
      "y": 12,
      "z": 2,
      "name": "Cloth_Block_Wool_Blue_Light"
    },
    {
      "x": 4,
      "y": -12,
      "z": 3,
      "name": "Cloth_Block_Wool_Blue_Light"
    },
    {
      "x": 4,
      "y": -11,
      "z": 3,
      "name": "Cloth_Block_Wool_Blue_Light"
    },
    {
      "x": 4,
      "y": -10,
      "z": 3,
      "name": "Cloth_Block_Wool_Blue_Light"
    },
    {
      "x": 4,
      "y": -9,
      "z": 3,
      "name": "Cloth_Block_Wool_Blue_Light"
    },
    {
      "x": 4,
      "y": -8,
      "z": 3,
      "name": "Cloth_Block_Wool_Blue_Light"
    },
    {
      "x": 4,
      "y": -7,
      "z": 3,
      "name": "Cloth_Block_Wool_Blue_Light"
    },
    {
      "x": 4,
      "y": -6,
      "z": 3,
      "name": "Cloth_Block_Wool_Blue_Light"
    },
    {
      "x": 4,
      "y": -5,
      "z": 3,
      "name": "Cloth_Block_Wool_Blue_Light"
    },
    {
      "x": 4,
      "y": -4,
      "z": 3,
      "name": "Cloth_Block_Wool_Blue_Light"
    },
    {
      "x": 4,
      "y": -3,
      "z": 3,
      "name": "Cloth_Block_Wool_Blue_Light"
    },
    {
      "x": 4,
      "y": -2,
      "z": 3,
      "name": "Cloth_Block_Wool_Blue_Light"
    },
    {
      "x": 4,
      "y": -1,
      "z": 3,
      "name": "Cloth_Block_Wool_Blue_Light"
    },
    {
      "x": 4,
      "y": 0,
      "z": 3,
      "name": "Cloth_Block_Wool_Blue_Light"
    },
    {
      "x": 4,
      "y": 1,
      "z": 3,
      "name": "Cloth_Block_Wool_Blue_Light"
    },
    {
      "x": 4,
      "y": 2,
      "z": 3,
      "name": "Cloth_Block_Wool_Blue_Light"
    },
    {
      "x": 4,
      "y": 3,
      "z": 3,
      "name": "Cloth_Block_Wool_Blue_Light"
    },
    {
      "x": 4,
      "y": 4,
      "z": 3,
      "name": "Cloth_Block_Wool_Blue_Light"
    },
    {
      "x": 4,
      "y": 5,
      "z": 3,
      "name": "Cloth_Block_Wool_Blue_Light"
    },
    {
      "x": 4,
      "y": 6,
      "z": 3,
      "name": "Cloth_Block_Wool_Blue_Light"
    },
    {
      "x": 4,
      "y": 7,
      "z": 3,
      "name": "Cloth_Block_Wool_Blue_Light"
    },
    {
      "x": 4,
      "y": 8,
      "z": 3,
      "name": "Cloth_Block_Wool_Blue_Light"
    },
    {
      "x": 4,
      "y": 9,
      "z": 3,
      "name": "Cloth_Block_Wool_Blue_Light"
    },
    {
      "x": 4,
      "y": 10,
      "z": 3,
      "name": "Cloth_Block_Wool_Blue_Light"
    },
    {
      "x": 4,
      "y": 11,
      "z": 3,
      "name": "Cloth_Block_Wool_Blue_Light"
    },
    {
      "x": 4,
      "y": 12,
      "z": 3,
      "name": "Cloth_Block_Wool_Blue_Light"
    },
    {
      "x": 4,
      "y": -12,
      "z": 4,
      "name": "Cloth_Block_Wool_Blue_Light"
    },
    {
      "x": 4,
      "y": -11,
      "z": 4,
      "name": "Cloth_Block_Wool_Blue_Light"
    },
    {
      "x": 4,
      "y": -10,
      "z": 4,
      "name": "Cloth_Block_Wool_Blue_Light"
    },
    {
      "x": 4,
      "y": -9,
      "z": 4,
      "name": "Cloth_Block_Wool_Blue_Light"
    },
    {
      "x": 4,
      "y": -8,
      "z": 4,
      "name": "Cloth_Block_Wool_Blue_Light"
    },
    {
      "x": 4,
      "y": -7,
      "z": 4,
      "name": "Cloth_Block_Wool_Blue_Light"
    },
    {
      "x": 4,
      "y": -6,
      "z": 4,
      "name": "Cloth_Block_Wool_Blue_Light"
    },
    {
      "x": 4,
      "y": -5,
      "z": 4,
      "name": "Cloth_Block_Wool_Blue_Light"
    },
    {
      "x": 4,
      "y": -4,
      "z": 4,
      "name": "Cloth_Block_Wool_Blue_Light"
    },
    {
      "x": 4,
      "y": -3,
      "z": 4,
      "name": "Cloth_Block_Wool_Blue_Light"
    },
    {
      "x": 4,
      "y": -2,
      "z": 4,
      "name": "Cloth_Block_Wool_Blue_Light"
    },
    {
      "x": 4,
      "y": -1,
      "z": 4,
      "name": "Cloth_Block_Wool_Blue_Light"
    },
    {
      "x": 4,
      "y": 0,
      "z": 4,
      "name": "Cloth_Block_Wool_Blue_Light"
    },
    {
      "x": 4,
      "y": 1,
      "z": 4,
      "name": "Cloth_Block_Wool_Blue_Light"
    },
    {
      "x": 4,
      "y": 2,
      "z": 4,
      "name": "Cloth_Block_Wool_Blue_Light"
    },
    {
      "x": 4,
      "y": 3,
      "z": 4,
      "name": "Cloth_Block_Wool_Blue_Light"
    },
    {
      "x": 4,
      "y": 4,
      "z": 4,
      "name": "Cloth_Block_Wool_Blue_Light"
    },
    {
      "x": 4,
      "y": 5,
      "z": 4,
      "name": "Cloth_Block_Wool_Blue_Light"
    },
    {
      "x": 4,
      "y": 6,
      "z": 4,
      "name": "Cloth_Block_Wool_Blue_Light"
    },
    {
      "x": 4,
      "y": 7,
      "z": 4,
      "name": "Cloth_Block_Wool_Blue_Light"
    },
    {
      "x": 4,
      "y": 8,
      "z": 4,
      "name": "Cloth_Block_Wool_Blue_Light"
    },
    {
      "x": 4,
      "y": 9,
      "z": 4,
      "name": "Cloth_Block_Wool_Blue_Light"
    },
    {
      "x": 4,
      "y": 10,
      "z": 4,
      "name": "Cloth_Block_Wool_Blue_Light"
    },
    {
      "x": 4,
      "y": 11,
      "z": 4,
      "name": "Cloth_Block_Wool_Blue_Light"
    },
    {
      "x": 4,
      "y": 12,
      "z": 4,
      "name": "Cloth_Block_Wool_Blue_Light"
    },
    {
      "x": 5,
      "y": -12,
      "z": -5,
      "name": "Empty"
    }
  ]
}