{
  "version": 8,
  "blockIdVersion": 11,
  "anchorX": 0,
  "anchorY": 0,
  "anchorZ": 0,
  "blocks": [
    {
      "x": -4,
      "y": 0,
      "z": -4,
      "name": "Metal_Iron_Pipe_Long",
      "support": 15
    },
    {
      "x": -4,
      "y": 1,
      "z": -4,
      "name": "Metal_Iron_Pipe_Long",
      "support": 15
    },
    {
      "x": -4,
      "y": 2,
      "z": -4,
      "name": "Metal_Iron_Pipe_Long",
      "support": 15
    },
    {
      "x": -4,
      "y": 3,
      "z": -4,
      "name": "Metal_Iron_Pipe_Long",
      "support": 15
    },
    {
      "x": -4,
      "y": 4,
      "z": -4,
      "name": "Metal_Iron_Pipe_Long",
      "support": 15
    },
    {
      "x": -4,
      "y": 5,
      "z": -4,
      "name": "Metal_Iron"
    },
    {
      "x": -4,
      "y": 6,
      "z": -4,
      "name": "Metal_Iron_Pipe_Long",
      "support": 15
    },
    {
      "x": -4,
      "y": 7,
      "z": -4,
      "name": "Metal_Iron_Pipe_Long",
      "support": 15
    },
    {
      "x": -4,
      "y": 8,
      "z": -4,
      "name": "Metal_Iron_Pipe_Long",
      "support": 15
    },
    {
      "x": -4,
      "y": 9,
      "z": -4,
      "name": "Metal_Iron_Pipe_Long",
      "support": 15
    },
    {
      "x": -4,
      "y": 10,
      "z": -4,
      "name": "Metal_Iron_Pipe_Long",
      "support": 15
    },
    {
      "x": -4,
      "y": 11,
      "z": -4,
      "name": "Metal_Iron_Pipe_Long",
      "support": 15
    },
    {
      "x": -4,
      "y": 12,
      "z": -4,
      "name": "Metal_Iron_Pipe_Long",
      "support": 15
    },
    {
      "x": -4,
      "y": 13,
      "z": -4,
      "name": "Metal_Iron"
    },
    {
      "x": -4,
      "y": 14,
      "z": -4,
      "name": "Metal_Iron_Pipe_Long",
      "support": 15
    },
    {
      "x": -4,
      "y": 15,
      "z": -4,
      "name": "Metal_Iron_Pipe_Long",
      "support": 15
    },
    {
      "x": -4,
      "y": 16,
      "z": -4,
      "name": "Metal_Iron_Pipe_Long",
      "rotation": 3
    },
    {
      "x": -4,
      "y": 17,
      "z": -4,
      "name": "Metal_Iron_Pipe_Long",
      "rotation": 3
    },
    {
      "x": -4,
      "y": 18,
      "z": -4,
      "name": "Metal_Iron_Pipe_Long",
      "rotation": 3
    },
    {
      "x": -4,
      "y": 19,
      "z": -4,
      "name": "Metal_Iron_Pipe_Long",
      "rotation": 3
    },
    {
      "x": -4,
      "y": 20,
      "z": -4,
      "name": "Metal_Iron_Pipe_Long",
      "rotation": 3
    },
    {
      "x": -4,
      "y": 21,
      "z": -4,
      "name": "Metal_Iron",
      "rotation": 3
    },
    {
      "x": -4,
      "y": 22,
      "z": -4,
      "name": "Metal_Iron_Pipe_Long",
      "rotation": 3
    },
    {
      "x": -4,
      "y": 23,
      "z": -4,
      "name": "Metal_Iron_Pipe_Long",
      "rotation": 3
    },
    {
      "x": -4,
      "y": 24,
      "z": -4,
      "name": "Metal_Iron_Pipe_Long",
      "rotation": 3
    },
    {
      "x": -4,
      "y": 25,
      "z": -4,
      "name": "Metal_Iron_Pipe_Long",
      "rotation": 3
    },
    {
      "x": -4,
      "y": 26,
      "z": -4,
      "name": "Metal_Iron_Pipe_Long",
      "rotation": 3
    },
    {
      "x": -4,
      "y": 27,
      "z": -4,
      "name": "Metal_Iron_Pipe_Long",
      "rotation": 3
    },
    {
      "x": -4,
      "y": 28,
      "z": -4,
      "name": "Metal_Iron_Pipe_Long",
      "rotation": 3
    },
    {
      "x": -4,
      "y": 29,
      "z": -4,
      "name": "Metal_Iron",
      "rotation": 3
    },
    {
      "x": -4,
      "y": 30,
      "z": -4,
      "name": "Metal_Iron_Pipe_Long",
      "rotation": 3
    },
    {
      "x": -4,
      "y": 31,
      "z": -4,
      "name": "Metal_Iron_Pipe_Long",
      "rotation": 3
    },
    {
      "x": -4,
      "y": 32,
      "z": -4,
      "name": "Metal_Iron_Pipe_Long",
      "rotation": 3
    },
    {
      "x": -4,
      "y": 5,
      "z": -3,
      "name": "Metal_Iron_Pipe_Long",
      "support": 15,
      "rotation": 4
    },
    {
      "x": -4,
      "y": 6,
      "z": -3,
      "name": "Deco_Iron_Chains",
      "rotation": 2
    },
    {
      "x": -4,
      "y": 12,
      "z": -3,
      "name": "Deco_Iron_Chains"
    },
    {
      "x": -4,
      "y": 13,
      "z": -3,
      "name": "Metal_Iron_Pipe_Long",
      "support": 15,
      "rotation": 4
    },
    {
      "x": -4,
      "y": 21,
      "z": -3,
      "name": "Metal_Iron_Pipe_Long",
      "rotation": 4
    },
    {
      "x": -4,
      "y": 29,
      "z": -3,
      "name": "Metal_Iron_Pipe_Long",
      "rotation": 4
    },
    {
      "x": -4,
      "y": 5,
      "z": -2,
      "name": "Metal_Iron_Pipe_Long",
      "support": 15,
      "rotation": 4
    },
    {
      "x": -4,
      "y": 7,
      "z": -2,
      "name": "Deco_Iron_Chains",
      "rotation": 2
    },
    {
      "x": -4,
      "y": 11,
      "z": -2,
      "name": "Deco_Iron_Chains"
    },
    {
      "x": -4,
      "y": 13,
      "z": -2,
      "name": "Metal_Iron_Pipe_Long",
      "support": 15,
      "rotation": 4
    },
    {
      "x": -4,
      "y": 21,
      "z": -2,
      "name": "Metal_Iron_Pipe_Long",
      "rotation": 4
    },
    {
      "x": -4,
      "y": 29,
      "z": -2,
      "name": "Metal_Iron_Pipe_Long",
      "rotation": 4
    },
    {
      "x": -4,
      "y": 5,
      "z": -1,
      "name": "Metal_Iron_Pipe_Long",
      "support": 15,
      "rotation": 4
    },
    {
      "x": -4,
      "y": 8,
      "z": -1,
      "name": "Deco_Iron_Chains",
      "rotation": 2
    },
    {
      "x": -4,
      "y": 10,
      "z": -1,
      "name": "Deco_Iron_Chains"
    },
    {
      "x": -4,
      "y": 13,
      "z": -1,
      "name": "Metal_Iron_Pipe_Long",
      "support": 15,
      "rotation": 4
    },
    {
      "x": -4,
      "y": 21,
      "z": -1,
      "name": "Metal_Iron_Pipe_Long",
      "rotation": 4
    },
    {
      "x": -4,
      "y": 29,
      "z": -1,
      "name": "Metal_Iron_Pipe_Long",
      "rotation": 4
    },
    {
      "x": -4,
      "y": 5,
      "z": 0,
      "name": "Metal_Iron_Pipe_Long",
      "support": 15,
      "rotation": 4
    },
    {
      "x": -4,
      "y": 9,
      "z": 0,
      "name": "Deco_Iron_Chains"
    },
    {
      "x": -4,
      "y": 13,
      "z": 0,
      "name": "Metal_Iron_Pipe_Long",
      "support": 15,
      "rotation": 4
    },
    {
      "x": -4,
      "y": 21,
      "z": 0,
      "name": "Metal_Iron_Pipe_Long",
      "rotation": 4
    },
    {
      "x": -4,
      "y": 29,
      "z": 0,
      "name": "Metal_Iron_Pipe_Long",
      "rotation": 4
    },
    {
      "x": -4,
      "y": 5,
      "z": 1,
      "name": "Metal_Iron_Pipe_Long",
      "support": 15,
      "rotation": 4
    },
    {
      "x": -4,
      "y": 8,
      "z": 1,
      "name": "Deco_Iron_Chains"
    },
    {
      "x": -4,
      "y": 10,
      "z": 1,
      "name": "Deco_Iron_Chains",
      "rotation": 2
    },
    {
      "x": -4,
      "y": 13,
      "z": 1,
      "name": "Metal_Iron_Pipe_Long",
      "support": 15,
      "rotation": 4
    },
    {
      "x": -4,
      "y": 21,
      "z": 1,
      "name": "Metal_Iron_Pipe_Long",
      "rotation": 4
    },
    {
      "x": -4,
      "y": 29,
      "z": 1,
      "name": "Metal_Iron_Pipe_Long",
      "rotation": 4
    },
    {
      "x": -4,
      "y": 5,
      "z": 2,
      "name": "Metal_Iron_Pipe_Long",
      "support": 15,
      "rotation": 4
    },
    {
      "x": -4,
      "y": 7,
      "z": 2,
      "name": "Deco_Iron_Chains"
    },
    {
      "x": -4,
      "y": 11,
      "z": 2,
      "name": "Deco_Iron_Chains",
      "rotation": 2
    },
    {
      "x": -4,
      "y": 13,
      "z": 2,
      "name": "Metal_Iron_Pipe_Long",
      "support": 15,
      "rotation": 4
    },
    {
      "x": -4,
      "y": 21,
      "z": 2,
      "name": "Metal_Iron_Pipe_Long",
      "rotation": 4
    },
    {
      "x": -4,
      "y": 29,
      "z": 2,
      "name": "Metal_Iron_Pipe_Long",
      "rotation": 4
    },
    {
      "x": -4,
      "y": 5,
      "z": 3,
      "name": "Metal_Iron_Pipe_Long",
      "support": 15,
      "rotation": 4
    },
    {
      "x": -4,
      "y": 6,
      "z": 3,
      "name": "Deco_Iron_Chains"
    },
    {
      "x": -4,
      "y": 12,
      "z": 3,
      "name": "Deco_Iron_Chains",
      "rotation": 2
    },
    {
      "x": -4,
      "y": 13,
      "z": 3,
      "name": "Metal_Iron_Pipe_Long",
      "support": 15,
      "rotation": 4
    },
    {
      "x": -4,
      "y": 21,
      "z": 3,
      "name": "Metal_Iron_Pipe_Long",
      "rotation": 4
    },
    {
      "x": -4,
      "y": 29,
      "z": 3,
      "name": "Metal_Iron_Pipe_Long",
      "rotation": 4
    },
    {
      "x": -4,
      "y": 0,
      "z": 4,
      "name": "Metal_Iron_Pipe_Long",
      "support": 15
    },
    {
      "x": -4,
      "y": 1,
      "z": 4,
      "name": "Metal_Iron_Pipe_Long",
      "support": 15
    },
    {
      "x": -4,
      "y": 2,
      "z": 4,
      "name": "Metal_Iron_Pipe_Long",
      "support": 15
    },
    {
      "x": -4,
      "y": 3,
      "z": 4,
      "name": "Metal_Iron_Pipe_Long",
      "support": 15
    },
    {
      "x": -4,
      "y": 4,
      "z": 4,
      "name": "Metal_Iron_Pipe_Long",
      "support": 15
    },
    {
      "x": -4,
      "y": 5,
      "z": 4,
      "name": "Metal_Iron"
    },
    {
      "x": -4,
      "y": 6,
      "z": 4,
      "name": "Metal_Iron_Pipe_Long",
      "support": 15
    },
    {
      "x": -4,
      "y": 7,
      "z": 4,
      "name": "Metal_Iron_Pipe_Long",
      "support": 15
    },
    {
      "x": -4,
      "y": 8,
      "z": 4,
      "name": "Metal_Iron_Pipe_Long",
      "support": 15
    },
    {
      "x": -4,
      "y": 9,
      "z": 4,
      "name": "Metal_Iron_Pipe_Long",
      "support": 15
    },
    {
      "x": -4,
      "y": 10,
      "z": 4,
      "name": "Metal_Iron_Pipe_Long",
      "support": 15
    },
    {
      "x": -4,
      "y": 11,
      "z": 4,
      "name": "Metal_Iron_Pipe_Long",
      "support": 15
    },
    {
      "x": -4,
      "y": 12,
      "z": 4,
      "name": "Metal_Iron_Pipe_Long",
      "support": 15
    },
    {
      "x": -4,
      "y": 13,
      "z": 4,
      "name": "Metal_Iron"
    },
    {
      "x": -4,
      "y": 14,
      "z": 4,
      "name": "Metal_Iron_Pipe_Long",
      "support": 15
    },
    {
      "x": -4,
      "y": 15,
      "z": 4,
      "name": "Metal_Iron_Pipe_Long",
      "support": 15
    },
    {
      "x": -4,
      "y": 16,
      "z": 4,
      "name": "Metal_Iron_Pipe_Long",
      "support": 15,
      "rotation": 3
    },
    {
      "x": -4,
      "y": 17,
      "z": 4,
      "name": "Metal_Iron_Pipe_Long",
      "rotation": 3
    },
    {
      "x": -4,
      "y": 18,
      "z": 4,
      "name": "Metal_Iron_Pipe_Long",
      "rotation": 3
    },
    {
      "x": -4,
      "y": 19,
      "z": 4,
      "name": "Metal_Iron_Pipe_Long",
      "rotation": 3
    },
    {
      "x": -4,
      "y": 20,
      "z": 4,
      "name": "Metal_Iron_Pipe_Long",
      "rotation": 3
    },
    {
      "x": -4,
      "y": 21,
      "z": 4,
      "name": "Metal_Iron",
      "rotation": 3
    },
    {
      "x": -4,
      "y": 22,
      "z": 4,
      "name": "Metal_Iron_Pipe_Long",
      "rotation": 3
    },
    {
      "x": -4,
      "y": 23,
      "z": 4,
      "name": "Metal_Iron_Pipe_Long",
      "rotation": 3
    },
    {
      "x": -4,
      "y": 24,
      "z": 4,
      "name": "Metal_Iron_Pipe_Long",
      "rotation": 3
    },
    {
      "x": -4,
      "y": 25,
      "z": 4,
      "name": "Metal_Iron_Pipe_Long",
      "rotation": 3
    },
    {
      "x": -4,
      "y": 26,
      "z": 4,
      "name": "Metal_Iron_Pipe_Long",
      "rotation": 3
    },
    {
      "x": -4,
      "y": 27,
      "z": 4,
      "name": "Metal_Iron_Pipe_Long",
      "rotation": 3
    },
    {
      "x": -4,
      "y": 28,
      "z": 4,
      "name": "Metal_Iron_Pipe_Long",
      "rotation": 3
    },
    {
      "x": -4,
      "y": 29,
      "z": 4,
      "name": "Metal_Iron",
      "rotation": 3
    },
    {
      "x": -4,
      "y": 30,
      "z": 4,
      "name": "Metal_Iron_Pipe_Long",
      "rotation": 3
    },
    {
      "x": -3,
      "y": 5,
      "z": -4,
      "name": "Metal_Iron_Pipe_Long",
      "support": 15,
      "rotation": 5
    },
    {
      "x": -3,
      "y": 13,
      "z": -4,
      "name": "Metal_Iron_Pipe_Long",
      "support": 15,
      "rotation": 5
    },
    {
      "x": -3,
      "y": 21,
      "z": -4,
      "name": "Metal_Iron_Pipe_Long",
      "rotation": 7
    },
    {
      "x": -3,
      "y": 22,
      "z": -4,
      "name": "Deco_Iron_Chains",
      "rotation": 3
    },
    {
      "x": -3,
      "y": 28,
      "z": -4,
      "name": "Deco_Iron_Chains",
      "rotation": 1
    },
    {
      "x": -3,
      "y": 29,
      "z": -4,
      "name": "Metal_Iron_Pipe_Long",
      "rotation": 7
    },
    {
      "x": -3,
      "y": 13,
      "z": -3,
      "name": "Metal_Iron_Half"
    },
    {
      "x": -3,
      "y": 21,
      "z": -3,
      "name": "Metal_Iron_Half"
    },
    {
      "x": -3,
      "y": 13,
      "z": -2,
      "name": "Metal_Iron_Half"
    },
    {
      "x": -3,
      "y": 21,
      "z": -2,
      "name": "Metal_Iron_Half"
    },
    {
      "x": -3,
      "y": 13,
      "z": -1,
      "name": "Metal_Iron_Half"
    },
    {
      "x": -3,
      "y": 21,
      "z": -1,
      "name": "Metal_Iron_Half"
    },
    {
      "x": -3,
      "y": 13,
      "z": 0,
      "name": "Metal_Iron_Half"
    },
    {
      "x": -3,
      "y": 21,
      "z": 0,
      "name": "Metal_Iron_Half"
    },
    {
      "x": -3,
      "y": 13,
      "z": 1,
      "name": "Metal_Iron_Half"
    },
    {
      "x": -3,
      "y": 21,
      "z": 1,
      "name": "Metal_Iron_Half"
    },
    {
      "x": -3,
      "y": 13,
      "z": 2,
      "name": "Metal_Iron_Half"
    },
    {
      "x": -3,
      "y": 21,
      "z": 2,
      "name": "Metal_Iron_Half"
    },
    {
      "x": -3,
      "y": 0,
      "z": 3,
      "name": "Furniture_Village_Ladder",
      "rotation": 1
    },
    {
      "x": -3,
      "y": 1,
      "z": 3,
      "name": "Furniture_Village_Ladder",
      "rotation": 1
    },
    {
      "x": -3,
      "y": 2,
      "z": 3,
      "name": "Furniture_Village_Ladder",
      "rotation": 1
    },
    {
      "x": -3,
      "y": 3,
      "z": 3,
      "name": "Furniture_Village_Ladder",
      "rotation": 1
    },
    {
      "x": -3,
      "y": 4,
      "z": 3,
      "name": "Furniture_Village_Ladder",
      "rotation": 1
    },
    {
      "x": -3,
      "y": 5,
      "z": 3,
      "name": "Furniture_Village_Ladder",
      "rotation": 1
    },
    {
      "x": -3,
      "y": 6,
      "z": 3,
      "name": "Furniture_Village_Ladder",
      "rotation": 1
    },
    {
      "x": -3,
      "y": 7,
      "z": 3,
      "name": "Furniture_Village_Ladder",
      "rotation": 1
    },
    {
      "x": -3,
      "y": 8,
      "z": 3,
      "name": "Furniture_Village_Ladder",
      "rotation": 1
    },
    {
      "x": -3,
      "y": 9,
      "z": 3,
      "name": "Furniture_Village_Ladder",
      "rotation": 1
    },
    {
      "x": -3,
      "y": 10,
      "z": 3,
      "name": "Furniture_Village_Ladder",
      "rotation": 1
    },
    {
      "x": -3,
      "y": 11,
      "z": 3,
      "name": "Furniture_Village_Ladder",
      "rotation": 1
    },
    {
      "x": -3,
      "y": 12,
      "z": 3,
      "name": "Furniture_Village_Ladder",
      "rotation": 1
    },
    {
      "x": -3,
      "y": 13,
      "z": 3,
      "name": "Furniture_Village_Ladder",
      "rotation": 1
    },
    {
      "x": -3,
      "y": 21,
      "z": 3,
      "name": "Metal_Iron_Half"
    },
    {
      "x": -3,
      "y": 5,
      "z": 4,
      "name": "Metal_Iron_Pipe_Long",
      "support": 15,
      "rotation": 5
    },
    {
      "x": -3,
      "y": 13,
      "z": 4,
      "name": "Metal_Iron_Pipe_Long",
      "support": 15,
      "rotation": 5
    },
    {
      "x": -3,
      "y": 21,
      "z": 4,
      "name": "Metal_Iron_Pipe_Long",
      "rotation": 7
    },
    {
      "x": -3,
      "y": 22,
      "z": 4,
      "name": "Deco_Iron_Chains",
      "rotation": 3
    },
    {
      "x": -3,
      "y": 28,
      "z": 4,
      "name": "Deco_Iron_Chains",
      "rotation": 1
    },
    {
      "x": -3,
      "y": 29,
      "z": 4,
      "name": "Metal_Iron_Pipe_Long",
      "rotation": 7
    },
    {
      "x": -2,
      "y": 5,
      "z": -4,
      "name": "Metal_Iron_Pipe_Long",
      "support": 15,
      "rotation": 5
    },
    {
      "x": -2,
      "y": 13,
      "z": -4,
      "name": "Metal_Iron_Pipe_Long",
      "support": 15,
      "rotation": 5
    },
    {
      "x": -2,
      "y": 21,
      "z": -4,
      "name": "Metal_Iron_Pipe_Long",
      "rotation": 7
    },
    {
      "x": -2,
      "y": 23,
      "z": -4,
      "name": "Deco_Iron_Chains",
      "rotation": 3
    },
    {
      "x": -2,
      "y": 27,
      "z": -4,
      "name": "Deco_Iron_Chains",
      "rotation": 1
    },
    {
      "x": -2,
      "y": 29,
      "z": -4,
      "name": "Metal_Iron_Pipe_Long",
      "rotation": 7
    },
    {
      "x": -2,
      "y": 21,
      "z": -3,
      "name": "Metal_Iron_Half"
    },
    {
      "x": -2,
      "y": 13,
      "z": -2,
      "name": "Metal_Iron_Half"
    },
    {
      "x": -2,
      "y": 21,
      "z": -2,
      "name": "Metal_Iron_Half"
    },
    {
      "x": -2,
      "y": 13,
      "z": -1,
      "name": "Metal_Iron_Half"
    },
    {
      "x": -2,
      "y": 19,
      "z": -1,
      "name": "Deco_Lantern_Ceiling"
    },
    {
      "x": -2,
      "y": 20,
      "z": -1,
      "name": "Deco_Iron_Chain_Small"
    },
    {
      "x": -2,
      "y": 21,
      "z": -1,
      "name": "Metal_Iron_Half"
    },
    {
      "x": -2,
      "y": 13,
      "z": 0,
      "name": "Metal_Iron_Half"
    },
    {
      "x": -2,
      "y": 21,
      "z": 0,
      "name": "Metal_Iron_Half"
    },
    {
      "x": -2,
      "y": 13,
      "z": 1,
      "name": "Metal_Iron_Half"
    },
    {
      "x": -2,
      "y": 21,
      "z": 1,
      "name": "Metal_Iron_Half"
    },
    {
      "x": -2,
      "y": 13,
      "z": 2,
      "name": "Metal_Iron_Half"
    },
    {
      "x": -2,
      "y": 21,
      "z": 2,
      "name": "Metal_Iron_Half"
    },
    {
      "x": -2,
      "y": 13,
      "z": 3,
      "name": "Metal_Iron_Half"
    },
    {
      "x": -2,
      "y": 21,
      "z": 3,
      "name": "Metal_Iron_Half"
    },
    {
      "x": -2,
      "y": 5,
      "z": 4,
      "name": "Metal_Iron_Pipe_Long",
      "support": 15,
      "rotation": 5
    },
    {
      "x": -2,
      "y": 13,
      "z": 4,
      "name": "Metal_Iron_Pipe_Long",
      "support": 15,
      "rotation": 5
    },
    {
      "x": -2,
      "y": 21,
      "z": 4,
      "name": "Metal_Iron_Pipe_Long",
      "rotation": 7
    },
    {
      "x": -2,
      "y": 23,
      "z": 4,
      "name": "Deco_Iron_Chains",
      "rotation": 3
    },
    {
      "x": -2,
      "y": 27,
      "z": 4,
      "name": "Deco_Iron_Chains",
      "rotation": 1
    },
    {
      "x": -2,
      "y": 29,
      "z": 4,
      "name": "Metal_Iron_Pipe_Long",
      "rotation": 7
    },
    {
      "x": -1,
      "y": 5,
      "z": -4,
      "name": "Metal_Iron_Pipe_Long",
      "support": 15,
      "rotation": 5
    },
    {
      "x": -1,
      "y": 13,
      "z": -4,
      "name": "Metal_Iron_Pipe_Long",
      "support": 15,
      "rotation": 5
    },
    {
      "x": -1,
      "y": 21,
      "z": -4,
      "name": "Metal_Iron_Pipe_Long",
      "rotation": 7
    },
    {
      "x": -1,
      "y": 24,
      "z": -4,
      "name": "Deco_Iron_Chains",
      "rotation": 3
    },
    {
      "x": -1,
      "y": 26,
      "z": -4,
      "name": "Deco_Iron_Chains",
      "rotation": 1
    },
    {
      "x": -1,
      "y": 29,
      "z": -4,
      "name": "Metal_Iron_Pipe_Long",
      "rotation": 7
    },
    {
      "x": -1,
      "y": 13,
      "z": -3,
      "name": "Metal_Iron_Half"
    },
    {
      "x": -1,
      "y": 21,
      "z": -3,
      "name": "Metal_Iron_Half"
    },
    {
      "x": -1,
      "y": 13,
      "z": -2,
      "name": "Metal_Iron_Half"
    },
    {
      "x": -1,
      "y": 21,
      "z": -1,
      "name": "Metal_Iron_Half"
    },
    {
      "x": -1,
      "y": 13,
      "z": 0,
      "name": "Metal_Iron_Half"
    },
    {
      "x": -1,
      "y": 21,
      "z": 0,
      "name": "Metal_Iron_Half"
    },
    {
      "x": -1,
      "y": 13,
      "z": 1,
      "name": "Metal_Iron_Half"
    },
    {
      "x": -1,
      "y": 13,
      "z": 2,
      "name": "Metal_Iron_Half"
    },
    {
      "x": -1,
      "y": 21,
      "z": 2,
      "name": "Metal_Iron_Half"
    },
    {
      "x": -1,
      "y": 13,
      "z": 3,
      "name": "Metal_Iron_Half"
    },
    {
      "x": -1,
      "y": 21,
      "z": 3,
      "name": "Metal_Iron_Half"
    },
    {
      "x": -1,
      "y": 5,
      "z": 4,
      "name": "Metal_Iron_Pipe_Long",
      "support": 15,
      "rotation": 5
    },
    {
      "x": -1,
      "y": 13,
      "z": 4,
      "name": "Metal_Iron_Pipe_Long",
      "support": 15,
      "rotation": 5
    },
    {
      "x": -1,
      "y": 21,
      "z": 4,
      "name": "Metal_Iron_Pipe_Long",
      "rotation": 7
    },
    {
      "x": -1,
      "y": 24,
      "z": 4,
      "name": "Deco_Iron_Chains",
      "rotation": 3
    },
    {
      "x": -1,
      "y": 26,
      "z": 4,
      "name": "Deco_Iron_Chains",
      "rotation": 1
    },
    {
      "x": -1,
      "y": 29,
      "z": 4,
      "name": "Metal_Iron_Pipe_Long",
      "rotation": 7
    },
    {
      "x": 0,
      "y": 5,
      "z": -4,
      "name": "Metal_Iron_Pipe_Long",
      "support": 15,
      "rotation": 5
    },
    {
      "x": 0,
      "y": 13,
      "z": -4,
      "name": "Metal_Iron_Pipe_Long",
      "support": 15,
      "rotation": 5
    },
    {
      "x": 0,
      "y": 21,
      "z": -4,
      "name": "Metal_Iron_Pipe_Long",
      "rotation": 7
    },
    {
      "x": 0,
      "y": 25,
      "z": -4,
      "name": "Deco_Iron_Chains",
      "rotation": 3
    },
    {
      "x": 0,
      "y": 29,
      "z": -4,
      "name": "Metal_Iron_Pipe_Long",
      "rotation": 7
    },
    {
      "x": 0,
      "y": 13,
      "z": -3,
      "name": "Metal_Iron_Half"
    },
    {
      "x": 0,
      "y": 21,
      "z": -3,
      "name": "Metal_Iron_Half"
    },
    {
      "x": 0,
      "y": 13,
      "z": -2,
      "name": "Metal_Iron_Half"
    },
    {
      "x": 0,
      "y": 21,
      "z": -2,
      "name": "Metal_Iron_Half"
    },
    {
      "x": 0,
      "y": 13,
      "z": -1,
      "name": "Metal_Iron_Half"
    },
    {
      "x": 0,
      "y": 21,
      "z": -1,
      "name": "Metal_Iron_Half"
    },
    {
      "x": 0,
      "y": 13,
      "z": 0,
      "name": "Metal_Iron_Half"
    },
    {
      "x": 0,
      "y": 21,
      "z": 0,
      "name": "Metal_Iron_Half"
    },
    {
      "x": 0,
      "y": 13,
      "z": 1,
      "name": "Metal_Iron_Half"
    },
    {
      "x": 0,
      "y": 21,
      "z": 1,
      "name": "Metal_Iron_Half"
    },
    {
      "x": 0,
      "y": 13,
      "z": 2,
      "name": "Metal_Iron_Half"
    },
    {
      "x": 0,
      "y": 13,
      "z": 3,
      "name": "Metal_Iron_Half"
    },
    {
      "x": 0,
      "y": 21,
      "z": 3,
      "name": "Metal_Iron_Half"
    },
    {
      "x": 0,
      "y": 5,
      "z": 4,
      "name": "Metal_Iron_Pipe_Long",
      "support": 15,
      "rotation": 5
    },
    {
      "x": 0,
      "y": 13,
      "z": 4,
      "name": "Metal_Iron_Pipe_Long",
      "support": 15,
      "rotation": 5
    },
    {
      "x": 0,
      "y": 21,
      "z": 4,
      "name": "Metal_Iron_Pipe_Long",
      "rotation": 7
    },
    {
      "x": 0,
      "y": 25,
      "z": 4,
      "name": "Deco_Iron_Chains",
      "rotation": 1
    },
    {
      "x": 0,
      "y": 29,
      "z": 4,
      "name": "Metal_Iron_Pipe_Long",
      "rotation": 7
    },
    {
      "x": 1,
      "y": 5,
      "z": -4,
      "name": "Metal_Iron_Pipe_Long",
      "support": 15,
      "rotation": 5
    },
    {
      "x": 1,
      "y": 13,
      "z": -4,
      "name": "Metal_Iron_Pipe_Long",
      "support": 15,
      "rotation": 5
    },
    {
      "x": 1,
      "y": 21,
      "z": -4,
      "name": "Metal_Iron_Pipe_Long",
      "rotation": 7
    },
    {
      "x": 1,
      "y": 24,
      "z": -4,
      "name": "Deco_Iron_Chains",
      "rotation": 1
    },
    {
      "x": 1,
      "y": 26,
      "z": -4,
      "name": "Deco_Iron_Chains",
      "rotation": 3
    },
    {
      "x": 1,
      "y": 29,
      "z": -4,
      "name": "Metal_Iron_Pipe_Long",
      "rotation": 7
    },
    {
      "x": 1,
      "y": 13,
      "z": -3,
      "name": "Metal_Iron_Half"
    },
    {
      "x": 1,
      "y": 21,
      "z": -3,
      "name": "Metal_Iron_Half"
    },
    {
      "x": 1,
      "y": 13,
      "z": -2,
      "name": "Metal_Iron_Half"
    },
    {
      "x": 1,
      "y": 21,
      "z": -2,
      "name": "Metal_Iron_Half"
    },
    {
      "x": 1,
      "y": 13,
      "z": -1,
      "name": "Metal_Iron_Half"
    },
    {
      "x": 1,
      "y": 21,
      "z": -1,
      "name": "Metal_Iron_Half"
    },
    {
      "x": 1,
      "y": 13,
      "z": 0,
      "name": "Metal_Iron_Half"
    },
    {
      "x": 1,
      "y": 21,
      "z": 0,
      "name": "Metal_Iron_Half"
    },
    {
      "x": 1,
      "y": 10,
      "z": 1,
      "name": "Deco_Lantern_Ceiling"
    },
    {
      "x": 1,
      "y": 11,
      "z": 1,
      "name": "Deco_Iron_Chain_Small"
    },
    {
      "x": 1,
      "y": 12,
      "z": 1,
      "name": "Deco_Iron_Chain_Small"
    },
    {
      "x": 1,
      "y": 13,
      "z": 1,
      "name": "Metal_Iron_Half"
    },
    {
      "x": 1,
      "y": 21,
      "z": 1,
      "name": "Metal_Iron_Half"
    },
    {
      "x": 1,
      "y": 13,
      "z": 2,
      "name": "Metal_Iron_Half"
    },
    {
      "x": 1,
      "y": 21,
      "z": 2,
      "name": "Metal_Iron_Half"
    },
    {
      "x": 1,
      "y": 21,
      "z": 3,
      "name": "Metal_Iron_Half"
    },
    {
      "x": 1,
      "y": 5,
      "z": 4,
      "name": "Metal_Iron_Pipe_Long",
      "support": 15,
      "rotation": 5
    },
    {
      "x": 1,
      "y": 13,
      "z": 4,
      "name": "Metal_Iron_Pipe_Long",
      "support": 15,
      "rotation": 5
    },
    {
      "x": 1,
      "y": 21,
      "z": 4,
      "name": "Metal_Iron_Pipe_Long",
      "rotation": 7
    },
    {
      "x": 1,
      "y": 24,
      "z": 4,
      "name": "Deco_Iron_Chains",
      "rotation": 1
    },
    {
      "x": 1,
      "y": 26,
      "z": 4,
      "name": "Deco_Iron_Chains",
      "rotation": 3
    },
    {
      "x": 1,
      "y": 29,
      "z": 4,
      "name": "Metal_Iron_Pipe_Long",
      "rotation": 7
    },
    {
      "x": 2,
      "y": 5,
      "z": -4,
      "name": "Metal_Iron_Pipe_Long",
      "support": 15,
      "rotation": 5
    },
    {
      "x": 2,
      "y": 13,
      "z": -4,
      "name": "Metal_Iron_Pipe_Long",
      "support": 15,
      "rotation": 5
    },
    {
      "x": 2,
      "y": 21,
      "z": -4,
      "name": "Metal_Iron_Pipe_Long",
      "rotation": 7
    },
    {
      "x": 2,
      "y": 23,
      "z": -4,
      "name": "Deco_Iron_Chains",
      "rotation": 1
    },
    {
      "x": 2,
      "y": 27,
      "z": -4,
      "name": "Deco_Iron_Chains",
      "rotation": 3
    },
    {
      "x": 2,
      "y": 29,
      "z": -4,
      "name": "Metal_Iron_Pipe_Long",
      "rotation": 7
    },
    {
      "x": 2,
      "y": 13,
      "z": -3,
      "name": "Metal_Iron_Half"
    },
    {
      "x": 2,
      "y": 21,
      "z": -3,
      "name": "Metal_Iron_Half"
    },
    {
      "x": 2,
      "y": 8,
      "z": -2,
      "name": "Deco_Lantern_Ceiling"
    },
    {
      "x": 2,
      "y": 9,
      "z": -2,
      "name": "Deco_Iron_Chain_Small"
    },
    {
      "x": 2,
      "y": 10,
      "z": -2,
      "name": "Deco_Iron_Chain_Small"
    },
    {
      "x": 2,
      "y": 11,
      "z": -2,
      "name": "Deco_Iron_Chain_Small"
    },
    {
      "x": 2,
      "y": 12,
      "z": -2,
      "name": "Deco_Iron_Chain_Small"
    },
    {
      "x": 2,
      "y": 13,
      "z": -2,
      "name": "Metal_Iron_Half"
    },
    {
      "x": 2,
      "y": 21,
      "z": -2,
      "name": "Metal_Iron_Half"
    },
    {
      "x": 2,
      "y": 13,
      "z": -1,
      "name": "Metal_Iron_Half"
    },
    {
      "x": 2,
      "y": 21,
      "z": -1,
      "name": "Metal_Iron_Half"
    },
    {
      "x": 2,
      "y": 13,
      "z": 0,
      "name": "Metal_Iron_Half"
    },
    {
      "x": 2,
      "y": 13,
      "z": 1,
      "name": "Metal_Iron_Half"
    },
    {
      "x": 2,
      "y": 21,
      "z": 1,
      "name": "Metal_Iron_Half"
    },
    {
      "x": 2,
      "y": 21,
      "z": 2,
      "name": "Metal_Iron_Half"
    },
    {
      "x": 2,
      "y": 13,
      "z": 3,
      "name": "Metal_Iron_Half"
    },
    {
      "x": 2,
      "y": 21,
      "z": 3,
      "name": "Metal_Iron_Half"
    },
    {
      "x": 2,
      "y": 5,
      "z": 4,
      "name": "Metal_Iron_Pipe_Long",
      "support": 15,
      "rotation": 5
    },
    {
      "x": 2,
      "y": 13,
      "z": 4,
      "name": "Metal_Iron_Pipe_Long",
      "support": 15,
      "rotation": 5
    },
    {
      "x": 2,
      "y": 21,
      "z": 4,
      "name": "Metal_Iron_Pipe_Long",
      "rotation": 7
    },
    {
      "x": 2,
      "y": 23,
      "z": 4,
      "name": "Deco_Iron_Chains",
      "rotation": 1
    },
    {
      "x": 2,
      "y": 27,
      "z": 4,
      "name": "Deco_Iron_Chains",
      "rotation": 3
    },
    {
      "x": 2,
      "y": 29,
      "z": 4,
      "name": "Metal_Iron_Pipe_Long",
      "rotation": 7
    },
    {
      "x": 3,
      "y": 5,
      "z": -4,
      "name": "Metal_Iron_Pipe_Long",
      "support": 15,
      "rotation": 5
    },
    {
      "x": 3,
      "y": 13,
      "z": -4,
      "name": "Metal_Iron_Pipe_Long",
      "support": 15,
      "rotation": 5
    },
    {
      "x": 3,
      "y": 21,
      "z": -4,
      "name": "Metal_Iron_Pipe_Long",
      "rotation": 7
    },
    {
      "x": 3,
      "y": 22,
      "z": -4,
      "name": "Deco_Iron_Chains",
      "rotation": 1
    },
    {
      "x": 3,
      "y": 28,
      "z": -4,
      "name": "Deco_Iron_Chains",
      "rotation": 3
    },
    {
      "x": 3,
      "y": 29,
      "z": -4,
      "name": "Metal_Iron_Pipe_Long",
      "rotation": 7
    },
    {
      "x": 3,
      "y": 13,
      "z": -3,
      "name": "Furniture_Village_Ladder"
    },
    {
      "x": 3,
      "y": 14,
      "z": -3,
      "name": "Furniture_Village_Ladder"
    },
    {
      "x": 3,
      "y": 15,
      "z": -3,
      "name": "Furniture_Village_Ladder"
    },
    {
      "x": 3,
      "y": 16,
      "z": -3,
      "name": "Furniture_Village_Ladder"
    },
    {
      "x": 3,
      "y": 17,
      "z": -3,
      "name": "Furniture_Village_Ladder"
    },
    {
      "x": 3,
      "y": 18,
      "z": -3,
      "name": "Furniture_Village_Ladder"
    },
    {
      "x": 3,
      "y": 19,
      "z": -3,
      "name": "Furniture_Village_Ladder"
    },
    {
      "x": 3,
      "y": 20,
      "z": -3,
      "name": "Furniture_Village_Ladder"
    },
    {
      "x": 3,
      "y": 21,
      "z": -3,
      "name": "Furniture_Village_Ladder"
    },
    {
      "x": 3,
      "y": 13,
      "z": -2,
      "name": "Metal_Iron_Half"
    },
    {
      "x": 3,
      "y": 21,
      "z": -2,
      "name": "Metal_Iron_Half"
    },
    {
      "x": 3,
      "y": 13,
      "z": -1,
      "name": "Metal_Iron_Half"
    },
    {
      "x": 3,
      "y": 21,
      "z": -1,
      "name": "Metal_Iron_Half"
    },
    {
      "x": 3,
      "y": 13,
      "z": 0,
      "name": "Metal_Iron_Half"
    },
    {
      "x": 3,
      "y": 21,
      "z": 0,
      "name": "Metal_Iron_Half"
    },
    {
      "x": 3,
      "y": 13,
      "z": 1,
      "name": "Metal_Iron_Half"
    },
    {
      "x": 3,
      "y": 21,
      "z": 1,
      "name": "Metal_Iron_Half"
    },
    {
      "x": 3,
      "y": 13,
      "z": 2,
      "name": "Metal_Iron_Half"
    },
    {
      "x": 3,
      "y": 21,
      "z": 2,
      "name": "Metal_Iron_Half"
    },
    {
      "x": 3,
      "y": 13,
      "z": 3,
      "name": "Metal_Iron_Half"
    },
    {
      "x": 3,
      "y": 21,
      "z": 3,
      "name": "Metal_Iron_Half"
    },
    {
      "x": 3,
      "y": 5,
      "z": 4,
      "name": "Metal_Iron_Pipe_Long",
      "support": 15,
      "rotation": 5
    },
    {
      "x": 3,
      "y": 13,
      "z": 4,
      "name": "Metal_Iron_Pipe_Long",
      "support": 15,
      "rotation": 5
    },
    {
      "x": 3,
      "y": 21,
      "z": 4,
      "name": "Metal_Iron_Pipe_Long",
      "rotation": 7
    },
    {
      "x": 3,
      "y": 22,
      "z": 4,
      "name": "Deco_Iron_Chains",
      "rotation": 1
    },
    {
      "x": 3,
      "y": 28,
      "z": 4,
      "name": "Deco_Iron_Chains",
      "rotation": 3
    },
    {
      "x": 3,
      "y": 29,
      "z": 4,
      "name": "Metal_Iron_Pipe_Long",
      "rotation": 7
    },
    {
      "x": 4,
      "y": 0,
      "z": -4,
      "name": "Metal_Iron_Pipe_Long",
      "support": 15
    },
    {
      "x": 4,
      "y": 1,
      "z": -4,
      "name": "Metal_Iron_Pipe_Long",
      "support": 15
    },
    {
      "x": 4,
      "y": 2,
      "z": -4,
      "name": "Metal_Iron_Pipe_Long",
      "support": 15
    },
    {
      "x": 4,
      "y": 3,
      "z": -4,
      "name": "Metal_Iron_Pipe_Long",
      "support": 15
    },
    {
      "x": 4,
      "y": 4,
      "z": -4,
      "name": "Metal_Iron_Pipe_Long",
      "support": 15
    },
    {
      "x": 4,
      "y": 5,
      "z": -4,
      "name": "Metal_Iron"
    },
    {
      "x": 4,
      "y": 6,
      "z": -4,
      "name": "Metal_Iron_Pipe_Long",
      "support": 15
    },
    {
      "x": 4,
      "y": 7,
      "z": -4,
      "name": "Metal_Iron_Pipe_Long",
      "support": 15
    },
    {
      "x": 4,
      "y": 8,
      "z": -4,
      "name": "Metal_Iron_Pipe_Long",
      "support": 15
    },
    {
      "x": 4,
      "y": 9,
      "z": -4,
      "name": "Metal_Iron_Pipe_Long",
      "support": 15
    },
    {
      "x": 4,
      "y": 10,
      "z": -4,
      "name": "Metal_Iron_Pipe_Long",
      "support": 15
    },
    {
      "x": 4,
      "y": 11,
      "z": -4,
      "name": "Metal_Iron_Pipe_Long",
      "support": 15
    },
    {
      "x": 4,
      "y": 12,
      "z": -4,
      "name": "Metal_Iron_Pipe_Long",
      "support": 15
    },
    {
      "x": 4,
      "y": 13,
      "z": -4,
      "name": "Metal_Iron"
    },
    {
      "x": 4,
      "y": 14,
      "z": -4,
      "name": "Metal_Iron_Pipe_Long",
      "support": 15
    },
    {
      "x": 4,
      "y": 15,
      "z": -4,
      "name": "Metal_Iron_Pipe_Long",
      "support": 15
    },
    {
      "x": 4,
      "y": 16,
      "z": -4,
      "name": "Metal_Iron_Pipe_Long",
      "support": 15,
      "rotation": 3
    },
    {
      "x": 4,
      "y": 17,
      "z": -4,
      "name": "Metal_Iron_Pipe_Long",
      "rotation": 3
    },
    {
      "x": 4,
      "y": 18,
      "z": -4,
      "name": "Metal_Iron_Pipe_Long",
      "rotation": 3
    },
    {
      "x": 4,
      "y": 19,
      "z": -4,
      "name": "Metal_Iron_Pipe_Long",
      "rotation": 3
    },
    {
      "x": 4,
      "y": 20,
      "z": -4,
      "name": "Metal_Iron_Pipe_Long",
      "rotation": 3
    },
    {
      "x": 4,
      "y": 21,
      "z": -4,
      "name": "Metal_Iron",
      "rotation": 3
    },
    {
      "x": 4,
      "y": 22,
      "z": -4,
      "name": "Metal_Iron_Pipe_Long",
      "rotation": 3
    },
    {
      "x": 4,
      "y": 23,
      "z": -4,
      "name": "Metal_Iron_Pipe_Long",
      "rotation": 3
    },
    {
      "x": 4,
      "y": 24,
      "z": -4,
      "name": "Metal_Iron_Pipe_Long",
      "rotation": 3
    },
    {
      "x": 4,
      "y": 25,
      "z": -4,
      "name": "Metal_Iron_Pipe_Long",
      "rotation": 3
    },
    {
      "x": 4,
      "y": 26,
      "z": -4,
      "name": "Metal_Iron_Pipe_Long",
      "rotation": 3
    },
    {
      "x": 4,
      "y": 27,
      "z": -4,
      "name": "Metal_Iron_Pipe_Long",
      "rotation": 3
    },
    {
      "x": 4,
      "y": 28,
      "z": -4,
      "name": "Metal_Iron_Pipe_Long",
      "rotation": 3
    },
    {
      "x": 4,
      "y": 29,
      "z": -4,
      "name": "Metal_Iron",
      "rotation": 3
    },
    {
      "x": 4,
      "y": 30,
      "z": -4,
      "name": "Metal_Iron_Pipe_Long",
      "rotation": 3
    },
    {
      "x": 4,
      "y": 31,
      "z": -4,
      "name": "Metal_Iron_Pipe_Long",
      "rotation": 3
    },
    {
      "x": 4,
      "y": 5,
      "z": -3,
      "name": "Metal_Iron_Pipe_Long",
      "support": 15,
      "rotation": 4
    },
    {
      "x": 4,
      "y": 6,
      "z": -3,
      "name": "Deco_Iron_Chains",
      "rotation": 2
    },
    {
      "x": 4,
      "y": 12,
      "z": -3,
      "name": "Deco_Iron_Chains"
    },
    {
      "x": 4,
      "y": 13,
      "z": -3,
      "name": "Metal_Iron_Pipe_Long",
      "support": 15,
      "rotation": 4
    },
    {
      "x": 4,
      "y": 21,
      "z": -3,
      "name": "Metal_Iron_Pipe_Long",
      "rotation": 4
    },
    {
      "x": 4,
      "y": 29,
      "z": -3,
      "name": "Metal_Iron_Pipe_Long",
      "rotation": 4
    },
    {
      "x": 4,
      "y": 5,
      "z": -2,
      "name": "Metal_Iron_Pipe_Long",
      "support": 15,
      "rotation": 4
    },
    {
      "x": 4,
      "y": 7,
      "z": -2,
      "name": "Deco_Iron_Chains",
      "rotation": 2
    },
    {
      "x": 4,
      "y": 11,
      "z": -2,
      "name": "Deco_Iron_Chains"
    },
    {
      "x": 4,
      "y": 13,
      "z": -2,
      "name": "Metal_Iron_Pipe_Long",
      "support": 15,
      "rotation": 4
    },
    {
      "x": 4,
      "y": 21,
      "z": -2,
      "name": "Metal_Iron_Pipe_Long",
      "rotation": 4
    },
    {
      "x": 4,
      "y": 29,
      "z": -2,
      "name": "Metal_Iron_Pipe_Long",
      "rotation": 4
    },
    {
      "x": 4,
      "y": 5,
      "z": -1,
      "name": "Metal_Iron_Pipe_Long",
      "support": 15,
      "rotation": 4
    },
    {
      "x": 4,
      "y": 8,
      "z": -1,
      "name": "Deco_Iron_Chains",
      "rotation": 2
    },
    {
      "x": 4,
      "y": 10,
      "z": -1,
      "name": "Deco_Iron_Chains"
    },
    {
      "x": 4,
      "y": 13,
      "z": -1,
      "name": "Metal_Iron_Pipe_Long",
      "support": 15,
      "rotation": 4
    },
    {
      "x": 4,
      "y": 21,
      "z": -1,
      "name": "Metal_Iron_Pipe_Long",
      "rotation": 4
    },
    {
      "x": 4,
      "y": 29,
      "z": -1,
      "name": "Metal_Iron_Pipe_Long",
      "rotation": 4
    },
    {
      "x": 4,
      "y": 5,
      "z": 0,
      "name": "Metal_Iron_Pipe_Long",
      "support": 15,
      "rotation": 4
    },
    {
      "x": 4,
      "y": 9,
      "z": 0,
      "name": "Deco_Iron_Chains",
      "rotation": 2
    },
    {
      "x": 4,
      "y": 13,
      "z": 0,
      "name": "Metal_Iron_Pipe_Long",
      "support": 15,
      "rotation": 4
    },
    {
      "x": 4,
      "y": 21,
      "z": 0,
      "name": "Metal_Iron_Pipe_Long",
      "rotation": 4
    },
    {
      "x": 4,
      "y": 29,
      "z": 0,
      "name": "Metal_Iron_Pipe_Long",
      "rotation": 4
    },
    {
      "x": 4,
      "y": 5,
      "z": 1,
      "name": "Metal_Iron_Pipe_Long",
      "support": 15,
      "rotation": 4
    },
    {
      "x": 4,
      "y": 8,
      "z": 1,
      "name": "Deco_Iron_Chains"
    },
    {
      "x": 4,
      "y": 10,
      "z": 1,
      "name": "Deco_Iron_Chains",
      "rotation": 2
    },
    {
      "x": 4,
      "y": 13,
      "z": 1,
      "name": "Metal_Iron_Pipe_Long",
      "support": 15,
      "rotation": 4
    },
    {
      "x": 4,
      "y": 21,
      "z": 1,
      "name": "Metal_Iron_Pipe_Long",
      "rotation": 4
    },
    {
      "x": 4,
      "y": 29,
      "z": 1,
      "name": "Metal_Iron_Pipe_Long",
      "rotation": 4
    },
    {
      "x": 4,
      "y": 5,
      "z": 2,
      "name": "Metal_Iron_Pipe_Long",
      "support": 15,
      "rotation": 4
    },
    {
      "x": 4,
      "y": 7,
      "z": 2,
      "name": "Deco_Iron_Chains"
    },
    {
      "x": 4,
      "y": 11,
      "z": 2,
      "name": "Deco_Iron_Chains",
      "rotation": 2
    },
    {
      "x": 4,
      "y": 13,
      "z": 2,
      "name": "Metal_Iron_Pipe_Long",
      "support": 15,
      "rotation": 4
    },
    {
      "x": 4,
      "y": 21,
      "z": 2,
      "name": "Metal_Iron_Pipe_Long",
      "rotation": 4
    },
    {
      "x": 4,
      "y": 29,
      "z": 2,
      "name": "Metal_Iron_Pipe_Long",
      "rotation": 4
    },
    {
      "x": 4,
      "y": 5,
      "z": 3,
      "name": "Metal_Iron_Pipe_Long",
      "support": 15,
      "rotation": 4
    },
    {
      "x": 4,
      "y": 6,
      "z": 3,
      "name": "Deco_Iron_Chains"
    },
    {
      "x": 4,
      "y": 12,
      "z": 3,
      "name": "Deco_Iron_Chains",
      "rotation": 2
    },
    {
      "x": 4,
      "y": 13,
      "z": 3,
      "name": "Metal_Iron_Pipe_Long",
      "support": 15,
      "rotation": 4
    },
    {
      "x": 4,
      "y": 21,
      "z": 3,
      "name": "Metal_Iron_Pipe_Long",
      "rotation": 4
    },
    {
      "x": 4,
      "y": 29,
      "z": 3,
      "name": "Metal_Iron_Pipe_Long",
      "rotation": 4
    },
    {
      "x": 4,
      "y": 0,
      "z": 4,
      "name": "Metal_Iron_Pipe_Long",
      "support": 15
    },
    {
      "x": 4,
      "y": 1,
      "z": 4,
      "name": "Metal_Iron_Pipe_Long",
      "support": 15
    },
    {
      "x": 4,
      "y": 2,
      "z": 4,
      "name": "Metal_Iron_Pipe_Long",
      "support": 15
    },
    {
      "x": 4,
      "y": 3,
      "z": 4,
      "name": "Metal_Iron_Pipe_Long",
      "support": 15
    },
    {
      "x": 4,
      "y": 4,
      "z": 4,
      "name": "Metal_Iron_Pipe_Long",
      "support": 15
    },
    {
      "x": 4,
      "y": 5,
      "z": 4,
      "name": "Metal_Iron"
    },
    {
      "x": 4,
      "y": 6,
      "z": 4,
      "name": "Metal_Iron_Pipe_Long",
      "support": 15
    },
    {
      "x": 4,
      "y": 7,
      "z": 4,
      "name": "Metal_Iron_Pipe_Long",
      "support": 15
    },
    {
      "x": 4,
      "y": 8,
      "z": 4,
      "name": "Metal_Iron_Pipe_Long",
      "support": 15
    },
    {
      "x": 4,
      "y": 9,
      "z": 4,
      "name": "Metal_Iron_Pipe_Long",
      "support": 15
    },
    {
      "x": 4,
      "y": 10,
      "z": 4,
      "name": "Metal_Iron_Pipe_Long",
      "support": 15
    },
    {
      "x": 4,
      "y": 11,
      "z": 4,
      "name": "Metal_Iron_Pipe_Long",
      "support": 15
    },
    {
      "x": 4,
      "y": 12,
      "z": 4,
      "name": "Metal_Iron_Pipe_Long",
      "support": 15
    },
    {
      "x": 4,
      "y": 13,
      "z": 4,
      "name": "Metal_Iron"
    },
    {
      "x": 4,
      "y": 14,
      "z": 4,
      "name": "Metal_Iron_Pipe_Long",
      "support": 15
    },
    {
      "x": 4,
      "y": 16,
      "z": 4,
      "name": "Metal_Iron_Pipe_Long",
      "rotation": 3
    },
    {
      "x": 4,
      "y": 17,
      "z": 4,
      "name": "Metal_Iron_Pipe_Long",
      "rotation": 3
    },
    {
      "x": 4,
      "y": 18,
      "z": 4,
      "name": "Metal_Iron_Pipe_Long",
      "rotation": 3
    },
    {
      "x": 4,
      "y": 19,
      "z": 4,
      "name": "Metal_Iron_Pipe_Long",
      "rotation": 3
    },
    {
      "x": 4,
      "y": 20,
      "z": 4,
      "name": "Metal_Iron_Pipe_Long",
      "rotation": 3
    },
    {
      "x": 4,
      "y": 21,
      "z": 4,
      "name": "Metal_Iron",
      "rotation": 3
    },
    {
      "x": 4,
      "y": 22,
      "z": 4,
      "name": "Metal_Iron_Pipe_Long",
      "rotation": 3
    },
    {
      "x": 4,
      "y": 23,
      "z": 4,
      "name": "Metal_Iron_Pipe_Long",
      "rotation": 3
    },
    {
      "x": 4,
      "y": 24,
      "z": 4,
      "name": "Metal_Iron_Pipe_Long",
      "rotation": 3
    },
    {
      "x": 4,
      "y": 25,
      "z": 4,
      "name": "Metal_Iron_Pipe_Long",
      "rotation": 3
    },
    {
      "x": 4,
      "y": 26,
      "z": 4,
      "name": "Metal_Iron_Pipe_Long",
      "rotation": 3
    },
    {
      "x": 4,
      "y": 27,
      "z": 4,
      "name": "Metal_Iron_Pipe_Long",
      "rotation": 3
    },
    {
      "x": 4,
      "y": 28,
      "z": 4,
      "name": "Metal_Iron_Pipe_Long",
      "rotation": 3
    },
    {
      "x": 4,
      "y": 29,
      "z": 4,
      "name": "Metal_Iron",
      "rotation": 3
    },
    {
      "x": 4,
      "y": 30,
      "z": 4,
      "name": "Metal_Iron_Pipe_Long",
      "rotation": 3
    },
    {
      "x": 4,
      "y": 31,
      "z": 4,
      "name": "Metal_Iron_Pipe_Long",
      "rotation": 3
    },
    {
      "x": 4,
      "y": 32,
      "z": 4,
      "name": "Metal_Iron_Pipe_Long",
      "rotation": 3
    }
  ]
}