{
  "version": 8,
  "blockIdVersion": 11,
  "anchorX": 5,
  "anchorY": 1,
  "anchorZ": 5,
  "blocks": [
    {
      "x": 1,
      "y": 1,
      "z": 1,
      "name": "Deco_Iron_Bars_Corner",
      "rotation": 1
    },
    {
      "x": 1,
      "y": 1,
      "z": 2,
      "name": "Deco_Iron_Bars",
      "rotation": 1
    },
    {
      "x": 1,
      "y": 1,
      "z": 3,
      "name": "Deco_Iron_Bars",
      "rotation": 1
    },
    {
      "x": 1,
      "y": 1,
      "z": 4,
      "name": "Deco_Iron_Bars",
      "rotation": 1
    },
    {
      "x": 1,
      "y": 1,
      "z": 5,
      "name": "Deco_Iron_Bars",
      "rotation": 1
    },
    {
      "x": 1,
      "y": 1,
      "z": 6,
      "name": "Deco_Iron_Bars",
      "rotation": 1
    },
    {
      "x": 1,
      "y": 1,
      "z": 7,
      "name": "Deco_Iron_Bars",
      "rotation": 1
    },
    {
      "x": 1,
      "y": 1,
      "z": 8,
      "name": "Deco_Iron_Bars",
      "rotation": 1
    },
    {
      "x": 1,
      "y": 1,
      "z": 9,
      "name": "Deco_Iron_Bars_Corner",
      "rotation": 2
    },
    {
      "x": 2,
      "y": 1,
      "z": 1,
      "name": "Deco_Iron_Bars"
    },
    {
      "x": 2,
      "y": 1,
      "z": 6,
      "name": "Metal_Iron_Pipe_Large",
      "support": 15
    },
    {
      "x": 2,
      "y": 2,
      "z": 6,
      "name": "Metal_Iron_Pipe_Large",
      "support": 15
    },
    {
      "x": 2,
      "y": 3,
      "z": 6,
      "name": "Metal_Iron_Pipe_Large",
      "support": 15
    },
    {
      "x": 2,
      "y": 4,
      "z": 6,
      "name": "Metal_Iron_Pipe_Large",
      "support": 15
    },
    {
      "x": 2,
      "y": 5,
      "z": 6,
      "name": "Metal_Iron_Pipe_Large",
      "support": 15
    },
    {
      "x": 2,
      "y": 6,
      "z": 6,
      "name": "Metal_Iron_Pipe_Large",
      "support": 15
    },
    {
      "x": 2,
      "y": 7,
      "z": 6,
      "name": "Metal_Iron_Pipe_Long",
      "support": 15
    },
    {
      "x": 2,
      "y": 8,
      "z": 6,
      "name": "Metal_Iron_Pipe_Long",
      "support": 15
    },
    {
      "x": 2,
      "y": 9,
      "z": 6,
      "name": "Metal_Iron_Pipe_Long",
      "support": 15
    },
    {
      "x": 2,
      "y": 10,
      "z": 6,
      "name": "Metal_Iron_Pipe_Long",
      "support": 15
    },
    {
      "x": 2,
      "y": 11,
      "z": 6,
      "name": "Metal_Iron_Pipe_Long",
      "support": 15
    },
    {
      "x": 2,
      "y": 12,
      "z": 6,
      "name": "Metal_Iron_Pipe_Long",
      "support": 15
    },
    {
      "x": 2,
      "y": 13,
      "z": 6,
      "name": "Build_Lightsource_Yellow"
    },
    {
      "x": 2,
      "y": 1,
      "z": 9,
      "name": "Deco_Iron_Bars"
    },
    {
      "x": 3,
      "y": 1,
      "z": 1,
      "name": "Deco_Iron_Bars"
    },
    {
      "x": 3,
      "y": 1,
      "z": 9,
      "name": "Deco_Iron_Bars"
    },
    {
      "x": 4,
      "y": 1,
      "z": 9,
      "name": "Deco_Iron_Bars"
    },
    {
      "x": 5,
      "y": 1,
      "z": 1,
      "name": "Deco_Iron_Bars"
    },
    {
      "x": 5,
      "y": 1,
      "z": 3,
      "name": "Metal_Iron_Pipe_Large",
      "support": 15
    },
    {
      "x": 5,
      "y": 2,
      "z": 3,
      "name": "Metal_Iron_Pipe_Large",
      "support": 15
    },
    {
      "x": 5,
      "y": 3,
      "z": 3,
      "name": "Metal_Iron_Pipe_Large",
      "support": 15
    },
    {
      "x": 5,
      "y": 4,
      "z": 3,
      "name": "Metal_Iron_Pipe_Large",
      "support": 15
    },
    {
      "x": 5,
      "y": 5,
      "z": 3,
      "name": "Metal_Iron_Pipe_Long",
      "support": 15
    },
    {
      "x": 5,
      "y": 6,
      "z": 3,
      "name": "Metal_Iron_Pipe_Long",
      "support": 15
    },
    {
      "x": 5,
      "y": 7,
      "z": 3,
      "name": "Metal_Iron_Pipe_Long",
      "support": 15
    },
    {
      "x": 5,
      "y": 8,
      "z": 3,
      "name": "Metal_Iron_Pipe_Long",
      "support": 15
    },
    {
      "x": 5,
      "y": 9,
      "z": 3,
      "name": "Build_Lightsource_Cyan"
    },
    {
      "x": 5,
      "y": 1,
      "z": 9,
      "name": "Deco_Iron_Bars"
    },
    {
      "x": 6,
      "y": 1,
      "z": 1,
      "name": "Deco_Iron_Bars"
    },
    {
      "x": 6,
      "y": 1,
      "z": 9,
      "name": "Deco_Iron_Bars"
    },
    {
      "x": 7,
      "y": 1,
      "z": 1,
      "name": "Deco_Iron_Bars"
    },
    {
      "x": 7,
      "y": 1,
      "z": 2,
      "name": "Metal_Iron_Ornate"
    },
    {
      "x": 7,
      "y": 2,
      "z": 2,
      "name": "Metal_Iron_Ornate"
    },
    {
      "x": 7,
      "y": 1,
      "z": 3,
      "name": "Metal_Iron_Ornate"
    },
    {
      "x": 7,
      "y": 2,
      "z": 3,
      "name": "Metal_Iron_Ornate"
    },
    {
      "x": 7,
      "y": 1,
      "z": 6,
      "name": "Metal_Iron_Ornate"
    },
    {
      "x": 7,
      "y": 2,
      "z": 6,
      "name": "Metal_Iron_Ornate"
    },
    {
      "x": 7,
      "y": 1,
      "z": 7,
      "name": "Metal_Iron_Ornate"
    },
    {
      "x": 7,
      "y": 2,
      "z": 7,
      "name": "Metal_Iron_Ornate"
    },
    {
      "x": 7,
      "y": 1,
      "z": 9,
      "name": "Deco_Iron_Bars"
    },
    {
      "x": 8,
      "y": 1,
      "z": 1,
      "name": "Deco_Iron_Bars"
    },
    {
      "x": 8,
      "y": 1,
      "z": 2,
      "name": "Metal_Iron_Ornate"
    },
    {
      "x": 8,
      "y": 2,
      "z": 2,
      "name": "Metal_Iron_Ornate"
    },
    {
      "x": 8,
      "y": 1,
      "z": 3,
      "name": "Metal_Iron_Ornate"
    },
    {
      "x": 8,
      "y": 2,
      "z": 3,
      "name": "Metal_Iron_Ornate"
    },
    {
      "x": 8,
      "y": 1,
      "z": 6,
      "name": "Metal_Iron_Ornate"
    },
    {
      "x": 8,
      "y": 2,
      "z": 6,
      "name": "Metal_Iron_Ornate"
    },
    {
      "x": 8,
      "y": 1,
      "z": 7,
      "name": "Metal_Iron_Ornate"
    },
    {
      "x": 8,
      "y": 2,
      "z": 7,
      "name": "Metal_Iron_Ornate"
    },
    {
      "x": 8,
      "y": 1,
      "z": 9,
      "name": "Deco_Iron_Bars"
    },
    {
      "x": 9,
      "y": 1,
      "z": 1,
      "name": "Deco_Iron_Bars_Corner"
    },
    {
      "x": 9,
      "y": 1,
      "z": 2,
      "name": "Deco_Iron_Bars",
      "rotation": 1
    },
    {
      "x": 9,
      "y": 1,
      "z": 3,
      "name": "Deco_Iron_Bars",
      "rotation": 1
    },
    {
      "x": 9,
      "y": 1,
      "z": 4,
      "name": "Deco_Iron_Bars",
      "rotation": 1
    },
    {
      "x": 9,
      "y": 1,
      "z": 5,
      "name": "Deco_Iron_Bars",
      "rotation": 1
    },
    {
      "x": 9,
      "y": 1,
      "z": 6,
      "name": "Deco_Iron_Bars",
      "rotation": 1
    },
    {
      "x": 9,
      "y": 1,
      "z": 7,
      "name": "Deco_Iron_Bars",
      "rotation": 1
    },
    {
      "x": 9,
      "y": 1,
      "z": 8,
      "name": "Deco_Iron_Bars",
      "rotation": 1
    },
    {
      "x": 9,
      "y": 1,
      "z": 9,
      "name": "Deco_Iron_Bars_Corner",
      "rotation": 3
    }
  ]
}