{
  "version": 8,
  "blockIdVersion": 11,
  "anchorX": 5,
  "anchorY": 1,
  "anchorZ": 5,
  "blocks": [
    {
      "x": 0,
      "y": 2,
      "z": 3,
      "name": "AdSign_Fat",
      "rotation": 3
    },
    {
      "x": 0,
      "y": 3,
      "z": 7,
      "name": "AdSign_Fat",
      "rotation": 3
    },
    {
      "x": 1,
      "y": 1,
      "z": 1,
      "name": "Soil_Clay"
    },
    {
      "x": 1,
      "y": 2,
      "z": 1,
      "name": "Soil_Clay"
    },
    {
      "x": 1,
      "y": 3,
      "z": 1,
      "name": "Soil_Clay"
    },
    {
      "x": 1,
      "y": 4,
      "z": 1,
      "name": "Soil_Clay"
    },
    {
      "x": 1,
      "y": 5,
      "z": 1,
      "name": "Soil_Clay"
    },
    {
      "x": 1,
      "y": 6,
      "z": 1,
      "name": "Soil_Clay"
    },
    {
      "x": 1,
      "y": 7,
      "z": 1,
      "name": "Soil_Clay"
    },
    {
      "x": 1,
      "y": 8,
      "z": 1,
      "name": "Soil_Clay"
    },
    {
      "x": 1,
      "y": 9,
      "z": 1,
      "name": "Soil_Clay"
    },
    {
      "x": 1,
      "y": 1,
      "z": 2,
      "name": "Soil_Clay"
    },
    {
      "x": 1,
      "y": 2,
      "z": 2,
      "name": "Soil_Clay"
    },
    {
      "x": 1,
      "y": 3,
      "z": 2,
      "name": "Soil_Clay"
    },
    {
      "x": 1,
      "y": 4,
      "z": 2,
      "name": "Soil_Clay"
    },
    {
      "x": 1,
      "y": 5,
      "z": 2,
      "name": "Soil_Clay"
    },
    {
      "x": 1,
      "y": 6,
      "z": 2,
      "name": "Soil_Clay"
    },
    {
      "x": 1,
      "y": 7,
      "z": 2,
      "name": "Soil_Clay"
    },
    {
      "x": 1,
      "y": 8,
      "z": 2,
      "name": "Soil_Clay"
    },
    {
      "x": 1,
      "y": 9,
      "z": 2,
      "name": "Soil_Clay"
    },
    {
      "x": 1,
      "y": 1,
      "z": 3,
      "name": "Soil_Clay"
    },
    {
      "x": 1,
      "y": 2,
      "z": 3,
      "name": "Soil_Clay"
    },
    {
      "x": 1,
      "y": 3,
      "z": 3,
      "name": "Soil_Clay"
    },
    {
      "x": 1,
      "y": 4,
      "z": 3,
      "name": "Soil_Clay"
    },
    {
      "x": 1,
      "y": 5,
      "z": 3,
      "name": "Soil_Clay"
    },
    {
      "x": 1,
      "y": 6,
      "z": 3,
      "name": "Soil_Clay"
    },
    {
      "x": 1,
      "y": 7,
      "z": 3,
      "name": "Soil_Clay"
    },
    {
      "x": 1,
      "y": 8,
      "z": 3,
      "name": "Soil_Clay"
    },
    {
      "x": 1,
      "y": 9,
      "z": 3,
      "name": "Soil_Clay"
    },
    {
      "x": 1,
      "y": 1,
      "z": 4,
      "name": "Soil_Clay"
    },
    {
      "x": 1,
      "y": 2,
      "z": 4,
      "name": "Soil_Clay"
    },
    {
      "x": 1,
      "y": 3,
      "z": 4,
      "name": "Soil_Clay"
    },
    {
      "x": 1,
      "y": 4,
      "z": 4,
      "name": "Soil_Clay"
    },
    {
      "x": 1,
      "y": 5,
      "z": 4,
      "name": "Soil_Clay"
    },
    {
      "x": 1,
      "y": 6,
      "z": 4,
      "name": "Soil_Clay"
    },
    {
      "x": 1,
      "y": 7,
      "z": 4,
      "name": "Soil_Clay"
    },
    {
      "x": 1,
      "y": 8,
      "z": 4,
      "name": "Soil_Clay"
    },
    {
      "x": 1,
      "y": 9,
      "z": 4,
      "name": "Soil_Clay"
    },
    {
      "x": 1,
      "y": 1,
      "z": 5,
      "name": "Soil_Clay"
    },
    {
      "x": 1,
      "y": 2,
      "z": 5,
      "name": "Soil_Clay"
    },
    {
      "x": 1,
      "y": 3,
      "z": 5,
      "name": "Soil_Clay"
    },
    {
      "x": 1,
      "y": 4,
      "z": 5,
      "name": "Soil_Clay"
    },
    {
      "x": 1,
      "y": 5,
      "z": 5,
      "name": "Soil_Clay"
    },
    {
      "x": 1,
      "y": 6,
      "z": 5,
      "name": "Soil_Clay"
    },
    {
      "x": 1,
      "y": 7,
      "z": 5,
      "name": "Soil_Clay"
    },
    {
      "x": 1,
      "y": 8,
      "z": 5,
      "name": "Soil_Clay"
    },
    {
      "x": 1,
      "y": 9,
      "z": 5,
      "name": "Soil_Clay"
    },
    {
      "x": 1,
      "y": 1,
      "z": 6,
      "name": "Soil_Clay"
    },
    {
      "x": 1,
      "y": 2,
      "z": 6,
      "name": "Soil_Clay"
    },
    {
      "x": 1,
      "y": 3,
      "z": 6,
      "name": "Soil_Clay"
    },
    {
      "x": 1,
      "y": 4,
      "z": 6,
      "name": "Soil_Clay"
    },
    {
      "x": 1,
      "y": 5,
      "z": 6,
      "name": "Soil_Clay"
    },
    {
      "x": 1,
      "y": 6,
      "z": 6,
      "name": "Soil_Clay"
    },
    {
      "x": 1,
      "y": 7,
      "z": 6,
      "name": "Soil_Clay"
    },
    {
      "x": 1,
      "y": 8,
      "z": 6,
      "name": "Soil_Clay"
    },
    {
      "x": 1,
      "y": 9,
      "z": 6,
      "name": "Soil_Clay"
    },
    {
      "x": 1,
      "y": 1,
      "z": 7,
      "name": "Soil_Clay"
    },
    {
      "x": 1,
      "y": 2,
      "z": 7,
      "name": "Soil_Clay"
    },
    {
      "x": 1,
      "y": 3,
      "z": 7,
      "name": "Soil_Clay"
    },
    {
      "x": 1,
      "y": 4,
      "z": 7,
      "name": "Soil_Clay"
    },
    {
      "x": 1,
      "y": 5,
      "z": 7,
      "name": "Soil_Clay"
    },
    {
      "x": 1,
      "y": 6,
      "z": 7,
      "name": "Soil_Clay"
    },
    {
      "x": 1,
      "y": 7,
      "z": 7,
      "name": "Soil_Clay"
    },
    {
      "x": 1,
      "y": 8,
      "z": 7,
      "name": "Soil_Clay"
    },
    {
      "x": 1,
      "y": 9,
      "z": 7,
      "name": "Soil_Clay"
    },
    {
      "x": 1,
      "y": 1,
      "z": 8,
      "name": "Soil_Clay"
    },
    {
      "x": 1,
      "y": 2,
      "z": 8,
      "name": "Soil_Clay"
    },
    {
      "x": 1,
      "y": 3,
      "z": 8,
      "name": "Soil_Clay"
    },
    {
      "x": 1,
      "y": 4,
      "z": 8,
      "name": "Soil_Clay"
    },
    {
      "x": 1,
      "y": 5,
      "z": 8,
      "name": "Soil_Clay"
    },
    {
      "x": 1,
      "y": 6,
      "z": 8,
      "name": "Soil_Clay"
    },
    {
      "x": 1,
      "y": 7,
      "z": 8,
      "name": "Soil_Clay"
    },
    {
      "x": 1,
      "y": 8,
      "z": 8,
      "name": "Soil_Clay"
    },
    {
      "x": 1,
      "y": 9,
      "z": 8,
      "name": "Soil_Clay"
    },
    {
      "x": 1,
      "y": 1,
      "z": 9,
      "name": "Soil_Clay"
    },
    {
      "x": 1,
      "y": 2,
      "z": 9,
      "name": "Soil_Clay"
    },
    {
      "x": 1,
      "y": 3,
      "z": 9,
      "name": "Soil_Clay"
    },
    {
      "x": 1,
      "y": 4,
      "z": 9,
      "name": "Soil_Clay"
    },
    {
      "x": 1,
      "y": 5,
      "z": 9,
      "name": "Soil_Clay"
    },
    {
      "x": 1,
      "y": 6,
      "z": 9,
      "name": "Soil_Clay"
    },
    {
      "x": 1,
      "y": 7,
      "z": 9,
      "name": "Soil_Clay"
    },
    {
      "x": 1,
      "y": 8,
      "z": 9,
      "name": "Soil_Clay"
    },
    {
      "x": 1,
      "y": 9,
      "z": 9,
      "name": "Soil_Clay"
    },
    {
      "x": 2,
      "y": 1,
      "z": 1,
      "name": "Soil_Clay"
    },
    {
      "x": 2,
      "y": 2,
      "z": 1,
      "name": "Soil_Clay"
    },
    {
      "x": 2,
      "y": 3,
      "z": 1,
      "name": "Soil_Clay"
    },
    {
      "x": 2,
      "y": 4,
      "z": 1,
      "name": "Soil_Clay"
    },
    {
      "x": 2,
      "y": 5,
      "z": 1,
      "name": "Soil_Clay"
    },
    {
      "x": 2,
      "y": 9,
      "z": 1,
      "name": "Soil_Clay"
    },
    {
      "x": 2,
      "y": 1,
      "z": 2,
      "name": "Empty"
    },
    {
      "x": 2,
      "y": 2,
      "z": 2,
      "name": "Empty"
    },
    {
      "x": 2,
      "y": 3,
      "z": 2,
      "name": "Empty"
    },
    {
      "x": 2,
      "y": 4,
      "z": 2,
      "name": "Wood_Hardwood_Planks_Half",
      "rotation": 8
    },
    {
      "x": 2,
      "y": 5,
      "z": 2,
      "name": "Empty"
    },
    {
      "x": 2,
      "y": 6,
      "z": 2,
      "name": "Empty"
    },
    {
      "x": 2,
      "y": 7,
      "z": 2,
      "name": "Empty"
    },
    {
      "x": 2,
      "y": 8,
      "z": 2,
      "name": "Empty"
    },
    {
      "x": 2,
      "y": 9,
      "z": 2,
      "name": "Soil_Clay"
    },
    {
      "x": 2,
      "y": 1,
      "z": 3,
      "name": "Empty"
    },
    {
      "x": 2,
      "y": 2,
      "z": 3,
      "name": "Empty"
    },
    {
      "x": 2,
      "y": 3,
      "z": 3,
      "name": "Empty"
    },
    {
      "x": 2,
      "y": 4,
      "z": 3,
      "name": "Wood_Hardwood_Planks_Half",
      "rotation": 8
    },
    {
      "x": 2,
      "y": 5,
      "z": 3,
      "name": "Empty"
    },
    {
      "x": 2,
      "y": 6,
      "z": 3,
      "name": "Empty"
    },
    {
      "x": 2,
      "y": 7,
      "z": 3,
      "name": "Empty"
    },
    {
      "x": 2,
      "y": 8,
      "z": 3,
      "name": "Empty"
    },
    {
      "x": 2,
      "y": 9,
      "z": 3,
      "name": "Soil_Clay"
    },
    {
      "x": 2,
      "y": 1,
      "z": 4,
      "name": "Empty"
    },
    {
      "x": 2,
      "y": 2,
      "z": 4,
      "name": "Empty"
    },
    {
      "x": 2,
      "y": 3,
      "z": 4,
      "name": "Empty"
    },
    {
      "x": 2,
      "y": 4,
      "z": 4,
      "name": "Wood_Hardwood_Planks_Half",
      "rotation": 8
    },
    {
      "x": 2,
      "y": 5,
      "z": 4,
      "name": "Empty"
    },
    {
      "x": 2,
      "y": 6,
      "z": 4,
      "name": "Empty"
    },
    {
      "x": 2,
      "y": 7,
      "z": 4,
      "name": "Empty"
    },
    {
      "x": 2,
      "y": 8,
      "z": 4,
      "name": "Empty"
    },
    {
      "x": 2,
      "y": 9,
      "z": 4,
      "name": "Soil_Clay"
    },
    {
      "x": 2,
      "y": 1,
      "z": 5,
      "name": "Empty"
    },
    {
      "x": 2,
      "y": 2,
      "z": 5,
      "name": "Empty"
    },
    {
      "x": 2,
      "y": 3,
      "z": 5,
      "name": "Empty"
    },
    {
      "x": 2,
      "y": 4,
      "z": 5,
      "name": "Wood_Hardwood_Planks_Half",
      "rotation": 8
    },
    {
      "x": 2,
      "y": 5,
      "z": 5,
      "name": "Empty"
    },
    {
      "x": 2,
      "y": 6,
      "z": 5,
      "name": "Empty"
    },
    {
      "x": 2,
      "y": 7,
      "z": 5,
      "name": "Empty"
    },
    {
      "x": 2,
      "y": 8,
      "z": 5,
      "name": "Empty"
    },
    {
      "x": 2,
      "y": 9,
      "z": 5,
      "name": "Soil_Clay"
    },
    {
      "x": 2,
      "y": 1,
      "z": 6,
      "name": "Empty"
    },
    {
      "x": 2,
      "y": 2,
      "z": 6,
      "name": "Empty"
    },
    {
      "x": 2,
      "y": 3,
      "z": 6,
      "name": "Empty"
    },
    {
      "x": 2,
      "y": 4,
      "z": 6,
      "name": "Wood_Hardwood_Planks_Half",
      "rotation": 8
    },
    {
      "x": 2,
      "y": 5,
      "z": 6,
      "name": "Empty"
    },
    {
      "x": 2,
      "y": 6,
      "z": 6,
      "name": "Empty"
    },
    {
      "x": 2,
      "y": 7,
      "z": 6,
      "name": "Empty"
    },
    {
      "x": 2,
      "y": 8,
      "z": 6,
      "name": "Empty"
    },
    {
      "x": 2,
      "y": 9,
      "z": 6,
      "name": "Soil_Clay"
    },
    {
      "x": 2,
      "y": 1,
      "z": 7,
      "name": "Empty"
    },
    {
      "x": 2,
      "y": 2,
      "z": 7,
      "name": "Empty"
    },
    {
      "x": 2,
      "y": 3,
      "z": 7,
      "name": "Empty"
    },
    {
      "x": 2,
      "y": 4,
      "z": 7,
      "name": "Wood_Hardwood_Planks_Half",
      "rotation": 8
    },
    {
      "x": 2,
      "y": 5,
      "z": 7,
      "name": "Empty"
    },
    {
      "x": 2,
      "y": 6,
      "z": 7,
      "name": "Empty"
    },
    {
      "x": 2,
      "y": 7,
      "z": 7,
      "name": "Empty"
    },
    {
      "x": 2,
      "y": 8,
      "z": 7,
      "name": "Empty"
    },
    {
      "x": 2,
      "y": 9,
      "z": 7,
      "name": "Soil_Clay"
    },
    {
      "x": 2,
      "y": 1,
      "z": 8,
      "name": "Empty"
    },
    {
      "x": 2,
      "y": 2,
      "z": 8,
      "name": "Empty"
    },
    {
      "x": 2,
      "y": 3,
      "z": 8,
      "name": "Empty"
    },
    {
      "x": 2,
      "y": 4,
      "z": 8,
      "name": "Wood_Hardwood_Planks_Half",
      "rotation": 8
    },
    {
      "x": 2,
      "y": 5,
      "z": 8,
      "name": "Empty"
    },
    {
      "x": 2,
      "y": 6,
      "z": 8,
      "name": "Empty"
    },
    {
      "x": 2,
      "y": 7,
      "z": 8,
      "name": "Empty"
    },
    {
      "x": 2,
      "y": 8,
      "z": 8,
      "name": "Empty"
    },
    {
      "x": 2,
      "y": 9,
      "z": 8,
      "name": "Soil_Clay"
    },
    {
      "x": 2,
      "y": 1,
      "z": 9,
      "name": "Soil_Clay"
    },
    {
      "x": 2,
      "y": 2,
      "z": 9,
      "name": "Soil_Clay"
    },
    {
      "x": 2,
      "y": 3,
      "z": 9,
      "name": "Soil_Clay"
    },
    {
      "x": 2,
      "y": 4,
      "z": 9,
      "name": "Soil_Clay"
    },
    {
      "x": 2,
      "y": 5,
      "z": 9,
      "name": "Soil_Clay"
    },
    {
      "x": 2,
      "y": 6,
      "z": 9,
      "name": "Soil_Clay"
    },
    {
      "x": 2,
      "y": 7,
      "z": 9,
      "name": "Soil_Clay"
    },
    {
      "x": 2,
      "y": 8,
      "z": 9,
      "name": "Soil_Clay"
    },
    {
      "x": 2,
      "y": 9,
      "z": 9,
      "name": "Soil_Clay"
    },
    {
      "x": 3,
      "y": 1,
      "z": 1,
      "name": "Soil_Clay"
    },
    {
      "x": 3,
      "y": 2,
      "z": 1,
      "name": "Soil_Clay"
    },
    {
      "x": 3,
      "y": 3,
      "z": 1,
      "name": "Soil_Clay"
    },
    {
      "x": 3,
      "y": 4,
      "z": 1,
      "name": "Soil_Clay"
    },
    {
      "x": 3,
      "y": 5,
      "z": 1,
      "name": "Soil_Clay"
    },
    {
      "x": 3,
      "y": 9,
      "z": 1,
      "name": "Soil_Clay"
    },
    {
      "x": 3,
      "y": 1,
      "z": 2,
      "name": "Empty"
    },
    {
      "x": 3,
      "y": 2,
      "z": 2,
      "name": "Empty"
    },
    {
      "x": 3,
      "y": 3,
      "z": 2,
      "name": "Empty"
    },
    {
      "x": 3,
      "y": 4,
      "z": 2,
      "name": "Wood_Hardwood_Planks_Half",
      "rotation": 8
    },
    {
      "x": 3,
      "y": 5,
      "z": 2,
      "name": "Empty"
    },
    {
      "x": 3,
      "y": 6,
      "z": 2,
      "name": "Empty"
    },
    {
      "x": 3,
      "y": 7,
      "z": 2,
      "name": "Empty"
    },
    {
      "x": 3,
      "y": 8,
      "z": 2,
      "name": "Empty"
    },
    {
      "x": 3,
      "y": 9,
      "z": 2,
      "name": "Soil_Clay"
    },
    {
      "x": 3,
      "y": 1,
      "z": 3,
      "name": "Empty"
    },
    {
      "x": 3,
      "y": 2,
      "z": 3,
      "name": "Empty"
    },
    {
      "x": 3,
      "y": 3,
      "z": 3,
      "name": "Empty"
    },
    {
      "x": 3,
      "y": 4,
      "z": 3,
      "name": "Wood_Hardwood_Planks_Half",
      "rotation": 8
    },
    {
      "x": 3,
      "y": 5,
      "z": 3,
      "name": "Empty"
    },
    {
      "x": 3,
      "y": 6,
      "z": 3,
      "name": "Empty"
    },
    {
      "x": 3,
      "y": 7,
      "z": 3,
      "name": "Empty"
    },
    {
      "x": 3,
      "y": 8,
      "z": 3,
      "name": "Empty"
    },
    {
      "x": 3,
      "y": 9,
      "z": 3,
      "name": "Soil_Clay"
    },
    {
      "x": 3,
      "y": 1,
      "z": 4,
      "name": "Empty"
    },
    {
      "x": 3,
      "y": 2,
      "z": 4,
      "name": "Empty"
    },
    {
      "x": 3,
      "y": 3,
      "z": 4,
      "name": "Empty"
    },
    {
      "x": 3,
      "y": 4,
      "z": 4,
      "name": "Wood_Hardwood_Planks_Half",
      "rotation": 8
    },
    {
      "x": 3,
      "y": 5,
      "z": 4,
      "name": "Empty"
    },
    {
      "x": 3,
      "y": 6,
      "z": 4,
      "name": "Empty"
    },
    {
      "x": 3,
      "y": 7,
      "z": 4,
      "name": "Empty"
    },
    {
      "x": 3,
      "y": 8,
      "z": 4,
      "name": "Empty"
    },
    {
      "x": 3,
      "y": 9,
      "z": 4,
      "name": "Soil_Clay"
    },
    {
      "x": 3,
      "y": 1,
      "z": 5,
      "name": "Empty"
    },
    {
      "x": 3,
      "y": 2,
      "z": 5,
      "name": "Empty"
    },
    {
      "x": 3,
      "y": 3,
      "z": 5,
      "name": "Empty"
    },
    {
      "x": 3,
      "y": 4,
      "z": 5,
      "name": "Wood_Hardwood_Planks_Half",
      "rotation": 8
    },
    {
      "x": 3,
      "y": 5,
      "z": 5,
      "name": "Empty"
    },
    {
      "x": 3,
      "y": 6,
      "z": 5,
      "name": "Empty"
    },
    {
      "x": 3,
      "y": 7,
      "z": 5,
      "name": "Empty"
    },
    {
      "x": 3,
      "y": 8,
      "z": 5,
      "name": "Empty"
    },
    {
      "x": 3,
      "y": 9,
      "z": 5,
      "name": "Soil_Clay"
    },
    {
      "x": 3,
      "y": 1,
      "z": 6,
      "name": "Empty"
    },
    {
      "x": 3,
      "y": 2,
      "z": 6,
      "name": "Empty"
    },
    {
      "x": 3,
      "y": 3,
      "z": 6,
      "name": "Empty"
    },
    {
      "x": 3,
      "y": 4,
      "z": 6,
      "name": "Wood_Hardwood_Planks_Half",
      "rotation": 8
    },
    {
      "x": 3,
      "y": 5,
      "z": 6,
      "name": "Empty"
    },
    {
      "x": 3,
      "y": 6,
      "z": 6,
      "name": "Empty"
    },
    {
      "x": 3,
      "y": 7,
      "z": 6,
      "name": "Empty"
    },
    {
      "x": 3,
      "y": 8,
      "z": 6,
      "name": "Empty"
    },
    {
      "x": 3,
      "y": 9,
      "z": 6,
      "name": "Soil_Clay"
    },
    {
      "x": 3,
      "y": 1,
      "z": 7,
      "name": "Empty"
    },
    {
      "x": 3,
      "y": 2,
      "z": 7,
      "name": "Empty"
    },
    {
      "x": 3,
      "y": 3,
      "z": 7,
      "name": "Empty"
    },
    {
      "x": 3,
      "y": 4,
      "z": 7,
      "name": "Wood_Hardwood_Planks_Half",
      "rotation": 8
    },
    {
      "x": 3,
      "y": 5,
      "z": 7,
      "name": "Empty"
    },
    {
      "x": 3,
      "y": 6,
      "z": 7,
      "name": "Empty"
    },
    {
      "x": 3,
      "y": 7,
      "z": 7,
      "name": "Empty"
    },
    {
      "x": 3,
      "y": 8,
      "z": 7,
      "name": "Empty"
    },
    {
      "x": 3,
      "y": 9,
      "z": 7,
      "name": "Soil_Clay"
    },
    {
      "x": 3,
      "y": 1,
      "z": 8,
      "name": "Empty"
    },
    {
      "x": 3,
      "y": 2,
      "z": 8,
      "name": "Empty"
    },
    {
      "x": 3,
      "y": 3,
      "z": 8,
      "name": "Empty"
    },
    {
      "x": 3,
      "y": 4,
      "z": 8,
      "name": "Wood_Hardwood_Planks_Half",
      "rotation": 8
    },
    {
      "x": 3,
      "y": 5,
      "z": 8,
      "name": "Empty"
    },
    {
      "x": 3,
      "y": 6,
      "z": 8,
      "name": "Empty"
    },
    {
      "x": 3,
      "y": 7,
      "z": 8,
      "name": "Empty"
    },
    {
      "x": 3,
      "y": 8,
      "z": 8,
      "name": "Empty"
    },
    {
      "x": 3,
      "y": 9,
      "z": 8,
      "name": "Soil_Clay"
    },
    {
      "x": 3,
      "y": 1,
      "z": 9,
      "name": "Soil_Clay"
    },
    {
      "x": 3,
      "y": 2,
      "z": 9,
      "name": "Soil_Clay"
    },
    {
      "x": 3,
      "y": 3,
      "z": 9,
      "name": "Soil_Clay"
    },
    {
      "x": 3,
      "y": 4,
      "z": 9,
      "name": "Soil_Clay"
    },
    {
      "x": 3,
      "y": 5,
      "z": 9,
      "name": "Soil_Clay"
    },
    {
      "x": 3,
      "y": 6,
      "z": 9,
      "name": "Soil_Clay"
    },
    {
      "x": 3,
      "y": 7,
      "z": 9,
      "name": "Soil_Clay"
    },
    {
      "x": 3,
      "y": 8,
      "z": 9,
      "name": "Soil_Clay"
    },
    {
      "x": 3,
      "y": 9,
      "z": 9,
      "name": "Soil_Clay"
    },
    {
      "x": 4,
      "y": 4,
      "z": 1,
      "name": "Soil_Clay"
    },
    {
      "x": 4,
      "y": 5,
      "z": 1,
      "name": "Soil_Clay"
    },
    {
      "x": 4,
      "y": 9,
      "z": 1,
      "name": "Soil_Clay"
    },
    {
      "x": 4,
      "y": 1,
      "z": 2,
      "name": "Empty"
    },
    {
      "x": 4,
      "y": 2,
      "z": 2,
      "name": "Empty"
    },
    {
      "x": 4,
      "y": 3,
      "z": 2,
      "name": "Empty"
    },
    {
      "x": 4,
      "y": 4,
      "z": 2,
      "name": "Wood_Hardwood_Planks_Half",
      "rotation": 8
    },
    {
      "x": 4,
      "y": 5,
      "z": 2,
      "name": "Empty"
    },
    {
      "x": 4,
      "y": 6,
      "z": 2,
      "name": "Empty"
    },
    {
      "x": 4,
      "y": 7,
      "z": 2,
      "name": "Empty"
    },
    {
      "x": 4,
      "y": 8,
      "z": 2,
      "name": "Empty"
    },
    {
      "x": 4,
      "y": 9,
      "z": 2,
      "name": "Soil_Clay"
    },
    {
      "x": 4,
      "y": 1,
      "z": 3,
      "name": "Empty"
    },
    {
      "x": 4,
      "y": 2,
      "z": 3,
      "name": "Empty"
    },
    {
      "x": 4,
      "y": 3,
      "z": 3,
      "name": "Empty"
    },
    {
      "x": 4,
      "y": 4,
      "z": 3,
      "name": "Wood_Hardwood_Planks_Half",
      "rotation": 8
    },
    {
      "x": 4,
      "y": 5,
      "z": 3,
      "name": "Empty"
    },
    {
      "x": 4,
      "y": 6,
      "z": 3,
      "name": "Empty"
    },
    {
      "x": 4,
      "y": 7,
      "z": 3,
      "name": "Empty"
    },
    {
      "x": 4,
      "y": 8,
      "z": 3,
      "name": "Empty"
    },
    {
      "x": 4,
      "y": 9,
      "z": 3,
      "name": "Soil_Clay"
    },
    {
      "x": 4,
      "y": 1,
      "z": 4,
      "name": "Empty"
    },
    {
      "x": 4,
      "y": 2,
      "z": 4,
      "name": "Empty"
    },
    {
      "x": 4,
      "y": 3,
      "z": 4,
      "name": "Empty"
    },
    {
      "x": 4,
      "y": 4,
      "z": 4,
      "name": "Wood_Hardwood_Planks_Half",
      "rotation": 8
    },
    {
      "x": 4,
      "y": 5,
      "z": 4,
      "name": "Empty"
    },
    {
      "x": 4,
      "y": 6,
      "z": 4,
      "name": "Empty"
    },
    {
      "x": 4,
      "y": 7,
      "z": 4,
      "name": "Empty"
    },
    {
      "x": 4,
      "y": 8,
      "z": 4,
      "name": "Empty"
    },
    {
      "x": 4,
      "y": 9,
      "z": 4,
      "name": "Soil_Clay"
    },
    {
      "x": 4,
      "y": 1,
      "z": 5,
      "name": "Empty"
    },
    {
      "x": 4,
      "y": 2,
      "z": 5,
      "name": "Empty"
    },
    {
      "x": 4,
      "y": 3,
      "z": 5,
      "name": "Empty"
    },
    {
      "x": 4,
      "y": 4,
      "z": 5,
      "name": "Wood_Hardwood_Planks_Half",
      "rotation": 8
    },
    {
      "x": 4,
      "y": 5,
      "z": 5,
      "name": "Empty"
    },
    {
      "x": 4,
      "y": 6,
      "z": 5,
      "name": "Empty"
    },
    {
      "x": 4,
      "y": 7,
      "z": 5,
      "name": "Empty"
    },
    {
      "x": 4,
      "y": 8,
      "z": 5,
      "name": "Empty"
    },
    {
      "x": 4,
      "y": 9,
      "z": 5,
      "name": "Soil_Clay"
    },
    {
      "x": 4,
      "y": 1,
      "z": 6,
      "name": "Empty"
    },
    {
      "x": 4,
      "y": 2,
      "z": 6,
      "name": "Empty"
    },
    {
      "x": 4,
      "y": 3,
      "z": 6,
      "name": "Empty"
    },
    {
      "x": 4,
      "y": 4,
      "z": 6,
      "name": "Wood_Hardwood_Planks_Half",
      "rotation": 8
    },
    {
      "x": 4,
      "y": 5,
      "z": 6,
      "name": "Empty"
    },
    {
      "x": 4,
      "y": 6,
      "z": 6,
      "name": "Empty"
    },
    {
      "x": 4,
      "y": 7,
      "z": 6,
      "name": "Empty"
    },
    {
      "x": 4,
      "y": 8,
      "z": 6,
      "name": "Empty"
    },
    {
      "x": 4,
      "y": 9,
      "z": 6,
      "name": "Soil_Clay"
    },
    {
      "x": 4,
      "y": 1,
      "z": 7,
      "name": "Empty"
    },
    {
      "x": 4,
      "y": 2,
      "z": 7,
      "name": "Empty"
    },
    {
      "x": 4,
      "y": 3,
      "z": 7,
      "name": "Empty"
    },
    {
      "x": 4,
      "y": 4,
      "z": 7,
      "name": "Wood_Hardwood_Planks_Half",
      "rotation": 8
    },
    {
      "x": 4,
      "y": 5,
      "z": 7,
      "name": "Empty"
    },
    {
      "x": 4,
      "y": 6,
      "z": 7,
      "name": "Empty"
    },
    {
      "x": 4,
      "y": 7,
      "z": 7,
      "name": "Empty"
    },
    {
      "x": 4,
      "y": 8,
      "z": 7,
      "name": "Empty"
    },
    {
      "x": 4,
      "y": 9,
      "z": 7,
      "name": "Soil_Clay"
    },
    {
      "x": 4,
      "y": 1,
      "z": 8,
      "name": "Empty"
    },
    {
      "x": 4,
      "y": 2,
      "z": 8,
      "name": "Empty"
    },
    {
      "x": 4,
      "y": 3,
      "z": 8,
      "name": "Empty"
    },
    {
      "x": 4,
      "y": 4,
      "z": 8,
      "name": "Wood_Hardwood_Planks_Half",
      "rotation": 8
    },
    {
      "x": 4,
      "y": 5,
      "z": 8,
      "name": "Empty"
    },
    {
      "x": 4,
      "y": 6,
      "z": 8,
      "name": "Empty"
    },
    {
      "x": 4,
      "y": 7,
      "z": 8,
      "name": "Empty"
    },
    {
      "x": 4,
      "y": 8,
      "z": 8,
      "name": "Empty"
    },
    {
      "x": 4,
      "y": 9,
      "z": 8,
      "name": "Soil_Clay"
    },
    {
      "x": 4,
      "y": 1,
      "z": 9,
      "name": "Soil_Clay"
    },
    {
      "x": 4,
      "y": 2,
      "z": 9,
      "name": "Soil_Clay"
    },
    {
      "x": 4,
      "y": 3,
      "z": 9,
      "name": "Soil_Clay"
    },
    {
      "x": 4,
      "y": 4,
      "z": 9,
      "name": "Soil_Clay"
    },
    {
      "x": 4,
      "y": 5,
      "z": 9,
      "name": "Soil_Clay"
    },
    {
      "x": 4,
      "y": 6,
      "z": 9,
      "name": "Soil_Clay"
    },
    {
      "x": 4,
      "y": 7,
      "z": 9,
      "name": "Soil_Clay"
    },
    {
      "x": 4,
      "y": 8,
      "z": 9,
      "name": "Soil_Clay"
    },
    {
      "x": 4,
      "y": 9,
      "z": 9,
      "name": "Soil_Clay"
    },
    {
      "x": 5,
      "y": 4,
      "z": 1,
      "name": "Soil_Clay"
    },
    {
      "x": 5,
      "y": 5,
      "z": 1,
      "name": "Soil_Clay"
    },
    {
      "x": 5,
      "y": 6,
      "z": 1,
      "name": "Soil_Clay"
    },
    {
      "x": 5,
      "y": 7,
      "z": 1,
      "name": "Soil_Clay"
    },
    {
      "x": 5,
      "y": 8,
      "z": 1,
      "name": "Soil_Clay"
    },
    {
      "x": 5,
      "y": 9,
      "z": 1,
      "name": "Soil_Clay"
    },
    {
      "x": 5,
      "y": 1,
      "z": 2,
      "name": "Empty"
    },
    {
      "x": 5,
      "y": 2,
      "z": 2,
      "name": "Empty"
    },
    {
      "x": 5,
      "y": 3,
      "z": 2,
      "name": "Empty"
    },
    {
      "x": 5,
      "y": 4,
      "z": 2,
      "name": "Wood_Hardwood_Planks_Half",
      "rotation": 8
    },
    {
      "x": 5,
      "y": 5,
      "z": 2,
      "name": "Empty"
    },
    {
      "x": 5,
      "y": 6,
      "z": 2,
      "name": "Empty"
    },
    {
      "x": 5,
      "y": 7,
      "z": 2,
      "name": "Empty"
    },
    {
      "x": 5,
      "y": 8,
      "z": 2,
      "name": "Empty"
    },
    {
      "x": 5,
      "y": 9,
      "z": 2,
      "name": "Soil_Clay"
    },
    {
      "x": 5,
      "y": 1,
      "z": 3,
      "name": "Empty"
    },
    {
      "x": 5,
      "y": 2,
      "z": 3,
      "name": "Empty"
    },
    {
      "x": 5,
      "y": 3,
      "z": 3,
      "name": "Empty"
    },
    {
      "x": 5,
      "y": 4,
      "z": 3,
      "name": "Wood_Hardwood_Planks_Half",
      "rotation": 8
    },
    {
      "x": 5,
      "y": 5,
      "z": 3,
      "name": "Empty"
    },
    {
      "x": 5,
      "y": 6,
      "z": 3,
      "name": "Empty"
    },
    {
      "x": 5,
      "y": 7,
      "z": 3,
      "name": "Empty"
    },
    {
      "x": 5,
      "y": 8,
      "z": 3,
      "name": "Empty"
    },
    {
      "x": 5,
      "y": 9,
      "z": 3,
      "name": "Soil_Clay"
    },
    {
      "x": 5,
      "y": 1,
      "z": 4,
      "name": "Empty"
    },
    {
      "x": 5,
      "y": 2,
      "z": 4,
      "name": "Empty"
    },
    {
      "x": 5,
      "y": 3,
      "z": 4,
      "name": "Empty"
    },
    {
      "x": 5,
      "y": 4,
      "z": 4,
      "name": "Wood_Hardwood_Planks_Half",
      "rotation": 8
    },
    {
      "x": 5,
      "y": 5,
      "z": 4,
      "name": "Empty"
    },
    {
      "x": 5,
      "y": 6,
      "z": 4,
      "name": "Empty"
    },
    {
      "x": 5,
      "y": 7,
      "z": 4,
      "name": "Empty"
    },
    {
      "x": 5,
      "y": 8,
      "z": 4,
      "name": "Empty"
    },
    {
      "x": 5,
      "y": 9,
      "z": 4,
      "name": "Soil_Clay"
    },
    {
      "x": 5,
      "y": 1,
      "z": 5,
      "name": "Empty"
    },
    {
      "x": 5,
      "y": 2,
      "z": 5,
      "name": "Empty"
    },
    {
      "x": 5,
      "y": 3,
      "z": 5,
      "name": "Empty"
    },
    {
      "x": 5,
      "y": 4,
      "z": 5,
      "name": "Wood_Hardwood_Planks_Half",
      "rotation": 8
    },
    {
      "x": 5,
      "y": 5,
      "z": 5,
      "name": "Empty"
    },
    {
      "x": 5,
      "y": 6,
      "z": 5,
      "name": "Empty"
    },
    {
      "x": 5,
      "y": 7,
      "z": 5,
      "name": "Empty"
    },
    {
      "x": 5,
      "y": 8,
      "z": 5,
      "name": "Empty"
    },
    {
      "x": 5,
      "y": 9,
      "z": 5,
      "name": "Soil_Clay"
    },
    {
      "x": 5,
      "y": 1,
      "z": 6,
      "name": "Empty"
    },
    {
      "x": 5,
      "y": 2,
      "z": 6,
      "name": "Empty"
    },
    {
      "x": 5,
      "y": 3,
      "z": 6,
      "name": "Empty"
    },
    {
      "x": 5,
      "y": 4,
      "z": 6,
      "name": "Wood_Hardwood_Planks_Half",
      "rotation": 8
    },
    {
      "x": 5,
      "y": 5,
      "z": 6,
      "name": "Empty"
    },
    {
      "x": 5,
      "y": 6,
      "z": 6,
      "name": "Empty"
    },
    {
      "x": 5,
      "y": 7,
      "z": 6,
      "name": "Empty"
    },
    {
      "x": 5,
      "y": 8,
      "z": 6,
      "name": "Empty"
    },
    {
      "x": 5,
      "y": 9,
      "z": 6,
      "name": "Soil_Clay"
    },
    {
      "x": 5,
      "y": 1,
      "z": 7,
      "name": "Empty"
    },
    {
      "x": 5,
      "y": 2,
      "z": 7,
      "name": "Empty"
    },
    {
      "x": 5,
      "y": 3,
      "z": 7,
      "name": "Empty"
    },
    {
      "x": 5,
      "y": 4,
      "z": 7,
      "name": "Wood_Hardwood_Planks_Half",
      "rotation": 8
    },
    {
      "x": 5,
      "y": 5,
      "z": 7,
      "name": "Empty"
    },
    {
      "x": 5,
      "y": 6,
      "z": 7,
      "name": "Empty"
    },
    {
      "x": 5,
      "y": 7,
      "z": 7,
      "name": "Empty"
    },
    {
      "x": 5,
      "y": 8,
      "z": 7,
      "name": "Empty"
    },
    {
      "x": 5,
      "y": 9,
      "z": 7,
      "name": "Soil_Clay"
    },
    {
      "x": 5,
      "y": 1,
      "z": 8,
      "name": "Empty"
    },
    {
      "x": 5,
      "y": 2,
      "z": 8,
      "name": "Empty"
    },
    {
      "x": 5,
      "y": 3,
      "z": 8,
      "name": "Empty"
    },
    {
      "x": 5,
      "y": 4,
      "z": 8,
      "name": "Wood_Hardwood_Planks_Half",
      "rotation": 8
    },
    {
      "x": 5,
      "y": 5,
      "z": 8,
      "name": "Empty"
    },
    {
      "x": 5,
      "y": 6,
      "z": 8,
      "name": "Empty"
    },
    {
      "x": 5,
      "y": 7,
      "z": 8,
      "name": "Empty"
    },
    {
      "x": 5,
      "y": 8,
      "z": 8,
      "name": "Empty"
    },
    {
      "x": 5,
      "y": 9,
      "z": 8,
      "name": "Soil_Clay"
    },
    {
      "x": 5,
      "y": 1,
      "z": 9,
      "name": "Soil_Clay"
    },
    {
      "x": 5,
      "y": 2,
      "z": 9,
      "name": "Soil_Clay"
    },
    {
      "x": 5,
      "y": 3,
      "z": 9,
      "name": "Soil_Clay"
    },
    {
      "x": 5,
      "y": 4,
      "z": 9,
      "name": "Soil_Clay"
    },
    {
      "x": 5,
      "y": 5,
      "z": 9,
      "name": "Soil_Clay"
    },
    {
      "x": 5,
      "y": 6,
      "z": 9,
      "name": "Soil_Clay"
    },
    {
      "x": 5,
      "y": 7,
      "z": 9,
      "name": "Soil_Clay"
    },
    {
      "x": 5,
      "y": 8,
      "z": 9,
      "name": "Soil_Clay"
    },
    {
      "x": 5,
      "y": 9,
      "z": 9,
      "name": "Soil_Clay"
    },
    {
      "x": 6,
      "y": 4,
      "z": 1,
      "name": "Soil_Clay"
    },
    {
      "x": 6,
      "y": 5,
      "z": 1,
      "name": "Soil_Clay"
    },
    {
      "x": 6,
      "y": 6,
      "z": 1,
      "name": "Soil_Clay"
    },
    {
      "x": 6,
      "y": 7,
      "z": 1,
      "name": "Soil_Clay"
    },
    {
      "x": 6,
      "y": 8,
      "z": 1,
      "name": "Soil_Clay"
    },
    {
      "x": 6,
      "y": 9,
      "z": 1,
      "name": "Soil_Clay"
    },
    {
      "x": 6,
      "y": 1,
      "z": 2,
      "name": "Empty"
    },
    {
      "x": 6,
      "y": 2,
      "z": 2,
      "name": "Empty"
    },
    {
      "x": 6,
      "y": 3,
      "z": 2,
      "name": "Empty"
    },
    {
      "x": 6,
      "y": 4,
      "z": 2,
      "name": "Wood_Hardwood_Planks_Half",
      "rotation": 8
    },
    {
      "x": 6,
      "y": 5,
      "z": 2,
      "name": "Rock_Crystal_White_Block",
      "rotation": 4
    },
    {
      "x": 6,
      "y": 6,
      "z": 2,
      "name": "Empty"
    },
    {
      "x": 6,
      "y": 7,
      "z": 2,
      "name": "Empty"
    },
    {
      "x": 6,
      "y": 8,
      "z": 2,
      "name": "Empty"
    },
    {
      "x": 6,
      "y": 9,
      "z": 2,
      "name": "Soil_Clay"
    },
    {
      "x": 6,
      "y": 1,
      "z": 3,
      "name": "Empty"
    },
    {
      "x": 6,
      "y": 2,
      "z": 3,
      "name": "Empty"
    },
    {
      "x": 6,
      "y": 3,
      "z": 3,
      "name": "Empty"
    },
    {
      "x": 6,
      "y": 4,
      "z": 3,
      "name": "Wood_Hardwood_Planks_Half",
      "rotation": 8
    },
    {
      "x": 6,
      "y": 5,
      "z": 3,
      "name": "Empty"
    },
    {
      "x": 6,
      "y": 6,
      "z": 3,
      "name": "Empty"
    },
    {
      "x": 6,
      "y": 7,
      "z": 3,
      "name": "Empty"
    },
    {
      "x": 6,
      "y": 8,
      "z": 3,
      "name": "Empty"
    },
    {
      "x": 6,
      "y": 9,
      "z": 3,
      "name": "Soil_Clay"
    },
    {
      "x": 6,
      "y": 1,
      "z": 4,
      "name": "Empty"
    },
    {
      "x": 6,
      "y": 2,
      "z": 4,
      "name": "Empty"
    },
    {
      "x": 6,
      "y": 3,
      "z": 4,
      "name": "Empty"
    },
    {
      "x": 6,
      "y": 4,
      "z": 4,
      "name": "Wood_Hardwood_Planks_Half",
      "rotation": 8
    },
    {
      "x": 6,
      "y": 5,
      "z": 4,
      "name": "Empty"
    },
    {
      "x": 6,
      "y": 6,
      "z": 4,
      "name": "Empty"
    },
    {
      "x": 6,
      "y": 7,
      "z": 4,
      "name": "Empty"
    },
    {
      "x": 6,
      "y": 8,
      "z": 4,
      "name": "Empty"
    },
    {
      "x": 6,
      "y": 9,
      "z": 4,
      "name": "Soil_Clay"
    },
    {
      "x": 6,
      "y": 1,
      "z": 5,
      "name": "Empty"
    },
    {
      "x": 6,
      "y": 2,
      "z": 5,
      "name": "Empty"
    },
    {
      "x": 6,
      "y": 3,
      "z": 5,
      "name": "Empty"
    },
    {
      "x": 6,
      "y": 4,
      "z": 5,
      "name": "Wood_Hardwood_Planks_Half",
      "rotation": 8
    },
    {
      "x": 6,
      "y": 5,
      "z": 5,
      "name": "Empty"
    },
    {
      "x": 6,
      "y": 6,
      "z": 5,
      "name": "Empty"
    },
    {
      "x": 6,
      "y": 7,
      "z": 5,
      "name": "Empty"
    },
    {
      "x": 6,
      "y": 8,
      "z": 5,
      "name": "Empty"
    },
    {
      "x": 6,
      "y": 9,
      "z": 5,
      "name": "Soil_Clay"
    },
    {
      "x": 6,
      "y": 1,
      "z": 6,
      "name": "Empty"
    },
    {
      "x": 6,
      "y": 2,
      "z": 6,
      "name": "Empty"
    },
    {
      "x": 6,
      "y": 3,
      "z": 6,
      "name": "Empty"
    },
    {
      "x": 6,
      "y": 4,
      "z": 6,
      "name": "Wood_Hardwood_Planks_Half",
      "rotation": 8
    },
    {
      "x": 6,
      "y": 5,
      "z": 6,
      "name": "Empty"
    },
    {
      "x": 6,
      "y": 6,
      "z": 6,
      "name": "Empty"
    },
    {
      "x": 6,
      "y": 7,
      "z": 6,
      "name": "Empty"
    },
    {
      "x": 6,
      "y": 8,
      "z": 6,
      "name": "Empty"
    },
    {
      "x": 6,
      "y": 9,
      "z": 6,
      "name": "Soil_Clay"
    },
    {
      "x": 6,
      "y": 1,
      "z": 7,
      "name": "Empty"
    },
    {
      "x": 6,
      "y": 2,
      "z": 7,
      "name": "Empty"
    },
    {
      "x": 6,
      "y": 3,
      "z": 7,
      "name": "Empty"
    },
    {
      "x": 6,
      "y": 4,
      "z": 7,
      "name": "Wood_Hardwood_Planks_Half",
      "rotation": 8
    },
    {
      "x": 6,
      "y": 5,
      "z": 7,
      "name": "Empty"
    },
    {
      "x": 6,
      "y": 6,
      "z": 7,
      "name": "Empty"
    },
    {
      "x": 6,
      "y": 7,
      "z": 7,
      "name": "Empty"
    },
    {
      "x": 6,
      "y": 8,
      "z": 7,
      "name": "Empty"
    },
    {
      "x": 6,
      "y": 9,
      "z": 7,
      "name": "Soil_Clay"
    },
    {
      "x": 6,
      "y": 1,
      "z": 8,
      "name": "Empty"
    },
    {
      "x": 6,
      "y": 2,
      "z": 8,
      "name": "Empty"
    },
    {
      "x": 6,
      "y": 3,
      "z": 8,
      "name": "Empty"
    },
    {
      "x": 6,
      "y": 4,
      "z": 8,
      "name": "Wood_Hardwood_Planks_Half",
      "rotation": 8
    },
    {
      "x": 6,
      "y": 5,
      "z": 8,
      "name": "Empty"
    },
    {
      "x": 6,
      "y": 6,
      "z": 8,
      "name": "Empty"
    },
    {
      "x": 6,
      "y": 7,
      "z": 8,
      "name": "Empty"
    },
    {
      "x": 6,
      "y": 8,
      "z": 8,
      "name": "Empty"
    },
    {
      "x": 6,
      "y": 9,
      "z": 8,
      "name": "Soil_Clay"
    },
    {
      "x": 6,
      "y": 1,
      "z": 9,
      "name": "Soil_Clay"
    },
    {
      "x": 6,
      "y": 2,
      "z": 9,
      "name": "Soil_Clay"
    },
    {
      "x": 6,
      "y": 3,
      "z": 9,
      "name": "Soil_Clay"
    },
    {
      "x": 6,
      "y": 4,
      "z": 9,
      "name": "Soil_Clay"
    },
    {
      "x": 6,
      "y": 5,
      "z": 9,
      "name": "Soil_Clay"
    },
    {
      "x": 6,
      "y": 6,
      "z": 9,
      "name": "Soil_Clay"
    },
    {
      "x": 6,
      "y": 7,
      "z": 9,
      "name": "Soil_Clay"
    },
    {
      "x": 6,
      "y": 8,
      "z": 9,
      "name": "Soil_Clay"
    },
    {
      "x": 6,
      "y": 9,
      "z": 9,
      "name": "Soil_Clay"
    },
    {
      "x": 7,
      "y": 4,
      "z": 1,
      "name": "Soil_Clay"
    },
    {
      "x": 7,
      "y": 5,
      "z": 1,
      "name": "Soil_Clay"
    },
    {
      "x": 7,
      "y": 9,
      "z": 1,
      "name": "Soil_Clay"
    },
    {
      "x": 7,
      "y": 1,
      "z": 2,
      "name": "Empty"
    },
    {
      "x": 7,
      "y": 2,
      "z": 2,
      "name": "Empty"
    },
    {
      "x": 7,
      "y": 3,
      "z": 2,
      "name": "Empty"
    },
    {
      "x": 7,
      "y": 4,
      "z": 2,
      "name": "Wood_Hardwood_Planks_Half",
      "rotation": 8
    },
    {
      "x": 7,
      "y": 5,
      "z": 2,
      "name": "Empty"
    },
    {
      "x": 7,
      "y": 6,
      "z": 2,
      "name": "Empty"
    },
    {
      "x": 7,
      "y": 7,
      "z": 2,
      "name": "Empty"
    },
    {
      "x": 7,
      "y": 8,
      "z": 2,
      "name": "Empty"
    },
    {
      "x": 7,
      "y": 9,
      "z": 2,
      "name": "Soil_Clay"
    },
    {
      "x": 7,
      "y": 1,
      "z": 3,
      "name": "Empty"
    },
    {
      "x": 7,
      "y": 2,
      "z": 3,
      "name": "Empty"
    },
    {
      "x": 7,
      "y": 3,
      "z": 3,
      "name": "Empty"
    },
    {
      "x": 7,
      "y": 4,
      "z": 3,
      "name": "Wood_Hardwood_Planks_Half",
      "rotation": 8
    },
    {
      "x": 7,
      "y": 5,
      "z": 3,
      "name": "Empty"
    },
    {
      "x": 7,
      "y": 6,
      "z": 3,
      "name": "Empty"
    },
    {
      "x": 7,
      "y": 7,
      "z": 3,
      "name": "Empty"
    },
    {
      "x": 7,
      "y": 8,
      "z": 3,
      "name": "Empty"
    },
    {
      "x": 7,
      "y": 9,
      "z": 3,
      "name": "Soil_Clay"
    },
    {
      "x": 7,
      "y": 1,
      "z": 4,
      "name": "Empty"
    },
    {
      "x": 7,
      "y": 2,
      "z": 4,
      "name": "Empty"
    },
    {
      "x": 7,
      "y": 3,
      "z": 4,
      "name": "Empty"
    },
    {
      "x": 7,
      "y": 4,
      "z": 4,
      "name": "Wood_Hardwood_Planks_Half",
      "rotation": 8
    },
    {
      "x": 7,
      "y": 5,
      "z": 4,
      "name": "Empty"
    },
    {
      "x": 7,
      "y": 6,
      "z": 4,
      "name": "Empty"
    },
    {
      "x": 7,
      "y": 7,
      "z": 4,
      "name": "Empty"
    },
    {
      "x": 7,
      "y": 8,
      "z": 4,
      "name": "Empty"
    },
    {
      "x": 7,
      "y": 9,
      "z": 4,
      "name": "Soil_Clay"
    },
    {
      "x": 7,
      "y": 1,
      "z": 5,
      "name": "Empty"
    },
    {
      "x": 7,
      "y": 2,
      "z": 5,
      "name": "Empty"
    },
    {
      "x": 7,
      "y": 3,
      "z": 5,
      "name": "Empty"
    },
    {
      "x": 7,
      "y": 4,
      "z": 5,
      "name": "Wood_Hardwood_Planks_Half",
      "rotation": 8
    },
    {
      "x": 7,
      "y": 5,
      "z": 5,
      "name": "Empty"
    },
    {
      "x": 7,
      "y": 6,
      "z": 5,
      "name": "Empty"
    },
    {
      "x": 7,
      "y": 7,
      "z": 5,
      "name": "Empty"
    },
    {
      "x": 7,
      "y": 8,
      "z": 5,
      "name": "Empty"
    },
    {
      "x": 7,
      "y": 9,
      "z": 5,
      "name": "Soil_Clay"
    },
    {
      "x": 7,
      "y": 1,
      "z": 6,
      "name": "Empty"
    },
    {
      "x": 7,
      "y": 2,
      "z": 6,
      "name": "Empty"
    },
    {
      "x": 7,
      "y": 3,
      "z": 6,
      "name": "Empty"
    },
    {
      "x": 7,
      "y": 4,
      "z": 6,
      "name": "Wood_Hardwood_Planks_Half",
      "rotation": 8
    },
    {
      "x": 7,
      "y": 5,
      "z": 6,
      "name": "Empty"
    },
    {
      "x": 7,
      "y": 6,
      "z": 6,
      "name": "Empty"
    },
    {
      "x": 7,
      "y": 7,
      "z": 6,
      "name": "Empty"
    },
    {
      "x": 7,
      "y": 8,
      "z": 6,
      "name": "Empty"
    },
    {
      "x": 7,
      "y": 9,
      "z": 6,
      "name": "Soil_Clay"
    },
    {
      "x": 7,
      "y": 1,
      "z": 7,
      "name": "Empty"
    },
    {
      "x": 7,
      "y": 2,
      "z": 7,
      "name": "Empty"
    },
    {
      "x": 7,
      "y": 3,
      "z": 7,
      "name": "Empty"
    },
    {
      "x": 7,
      "y": 4,
      "z": 7,
      "name": "Wood_Hardwood_Planks_Half",
      "rotation": 8
    },
    {
      "x": 7,
      "y": 5,
      "z": 7,
      "name": "Empty"
    },
    {
      "x": 7,
      "y": 6,
      "z": 7,
      "name": "Empty"
    },
    {
      "x": 7,
      "y": 7,
      "z": 7,
      "name": "Empty"
    },
    {
      "x": 7,
      "y": 8,
      "z": 7,
      "name": "Empty"
    },
    {
      "x": 7,
      "y": 9,
      "z": 7,
      "name": "Soil_Clay"
    },
    {
      "x": 7,
      "y": 1,
      "z": 8,
      "name": "Empty"
    },
    {
      "x": 7,
      "y": 2,
      "z": 8,
      "name": "Empty"
    },
    {
      "x": 7,
      "y": 3,
      "z": 8,
      "name": "Empty"
    },
    {
      "x": 7,
      "y": 4,
      "z": 8,
      "name": "Wood_Hardwood_Planks_Half",
      "rotation": 8
    },
    {
      "x": 7,
      "y": 5,
      "z": 8,
      "name": "Empty"
    },
    {
      "x": 7,
      "y": 6,
      "z": 8,
      "name": "Empty"
    },
    {
      "x": 7,
      "y": 7,
      "z": 8,
      "name": "Empty"
    },
    {
      "x": 7,
      "y": 8,
      "z": 8,
      "name": "Empty"
    },
    {
      "x": 7,
      "y": 9,
      "z": 8,
      "name": "Soil_Clay"
    },
    {
      "x": 7,
      "y": 1,
      "z": 9,
      "name": "Soil_Clay"
    },
    {
      "x": 7,
      "y": 2,
      "z": 9,
      "name": "Soil_Clay"
    },
    {
      "x": 7,
      "y": 3,
      "z": 9,
      "name": "Soil_Clay"
    },
    {
      "x": 7,
      "y": 4,
      "z": 9,
      "name": "Soil_Clay"
    },
    {
      "x": 7,
      "y": 5,
      "z": 9,
      "name": "Soil_Clay"
    },
    {
      "x": 7,
      "y": 6,
      "z": 9,
      "name": "Soil_Clay"
    },
    {
      "x": 7,
      "y": 7,
      "z": 9,
      "name": "Soil_Clay"
    },
    {
      "x": 7,
      "y": 8,
      "z": 9,
      "name": "Soil_Clay"
    },
    {
      "x": 7,
      "y": 9,
      "z": 9,
      "name": "Soil_Clay"
    },
    {
      "x": 8,
      "y": 1,
      "z": 1,
      "name": "Soil_Clay"
    },
    {
      "x": 8,
      "y": 2,
      "z": 1,
      "name": "Soil_Clay"
    },
    {
      "x": 8,
      "y": 3,
      "z": 1,
      "name": "Soil_Clay"
    },
    {
      "x": 8,
      "y": 4,
      "z": 1,
      "name": "Soil_Clay"
    },
    {
      "x": 8,
      "y": 5,
      "z": 1,
      "name": "Soil_Clay"
    },
    {
      "x": 8,
      "y": 9,
      "z": 1,
      "name": "Soil_Clay"
    },
    {
      "x": 8,
      "y": 1,
      "z": 2,
      "name": "Empty"
    },
    {
      "x": 8,
      "y": 2,
      "z": 2,
      "name": "Empty"
    },
    {
      "x": 8,
      "y": 3,
      "z": 2,
      "name": "Empty"
    },
    {
      "x": 8,
      "y": 4,
      "z": 2,
      "name": "Wood_Hardwood_Planks_Half",
      "rotation": 8
    },
    {
      "x": 8,
      "y": 5,
      "z": 2,
      "name": "Empty"
    },
    {
      "x": 8,
      "y": 6,
      "z": 2,
      "name": "Empty"
    },
    {
      "x": 8,
      "y": 7,
      "z": 2,
      "name": "Empty"
    },
    {
      "x": 8,
      "y": 8,
      "z": 2,
      "name": "Empty"
    },
    {
      "x": 8,
      "y": 9,
      "z": 2,
      "name": "Soil_Clay"
    },
    {
      "x": 8,
      "y": 1,
      "z": 3,
      "name": "Empty"
    },
    {
      "x": 8,
      "y": 2,
      "z": 3,
      "name": "Rock_Crystal_White_Block",
      "rotation": 5
    },
    {
      "x": 8,
      "y": 3,
      "z": 3,
      "name": "Empty"
    },
    {
      "x": 8,
      "y": 4,
      "z": 3,
      "name": "Wood_Hardwood_Planks_Half",
      "rotation": 8
    },
    {
      "x": 8,
      "y": 5,
      "z": 3,
      "name": "Empty"
    },
    {
      "x": 8,
      "y": 6,
      "z": 3,
      "name": "Empty"
    },
    {
      "x": 8,
      "y": 7,
      "z": 3,
      "name": "Empty"
    },
    {
      "x": 8,
      "y": 8,
      "z": 3,
      "name": "Empty"
    },
    {
      "x": 8,
      "y": 9,
      "z": 3,
      "name": "Soil_Clay"
    },
    {
      "x": 8,
      "y": 1,
      "z": 4,
      "name": "Empty"
    },
    {
      "x": 8,
      "y": 2,
      "z": 4,
      "name": "Empty"
    },
    {
      "x": 8,
      "y": 3,
      "z": 4,
      "name": "Empty"
    },
    {
      "x": 8,
      "y": 4,
      "z": 4,
      "name": "Wood_Hardwood_Planks_Half",
      "rotation": 8
    },
    {
      "x": 8,
      "y": 5,
      "z": 4,
      "name": "Empty"
    },
    {
      "x": 8,
      "y": 6,
      "z": 4,
      "name": "Empty"
    },
    {
      "x": 8,
      "y": 7,
      "z": 4,
      "name": "Empty"
    },
    {
      "x": 8,
      "y": 8,
      "z": 4,
      "name": "Empty"
    },
    {
      "x": 8,
      "y": 9,
      "z": 4,
      "name": "Soil_Clay"
    },
    {
      "x": 8,
      "y": 1,
      "z": 5,
      "name": "Empty"
    },
    {
      "x": 8,
      "y": 2,
      "z": 5,
      "name": "Empty"
    },
    {
      "x": 8,
      "y": 3,
      "z": 5,
      "name": "Empty"
    },
    {
      "x": 8,
      "y": 4,
      "z": 5,
      "name": "Wood_Hardwood_Planks_Half",
      "rotation": 8
    },
    {
      "x": 8,
      "y": 5,
      "z": 5,
      "name": "Empty"
    },
    {
      "x": 8,
      "y": 6,
      "z": 5,
      "name": "Empty"
    },
    {
      "x": 8,
      "y": 7,
      "z": 5,
      "name": "Empty"
    },
    {
      "x": 8,
      "y": 8,
      "z": 5,
      "name": "Empty"
    },
    {
      "x": 8,
      "y": 9,
      "z": 5,
      "name": "Soil_Clay"
    },
    {
      "x": 8,
      "y": 1,
      "z": 6,
      "name": "Empty"
    },
    {
      "x": 8,
      "y": 2,
      "z": 6,
      "name": "Empty"
    },
    {
      "x": 8,
      "y": 3,
      "z": 6,
      "name": "Empty"
    },
    {
      "x": 8,
      "y": 4,
      "z": 6,
      "name": "Wood_Hardwood_Planks_Half",
      "rotation": 8
    },
    {
      "x": 8,
      "y": 5,
      "z": 6,
      "name": "Empty"
    },
    {
      "x": 8,
      "y": 6,
      "z": 6,
      "name": "Empty"
    },
    {
      "x": 8,
      "y": 7,
      "z": 6,
      "name": "Empty"
    },
    {
      "x": 8,
      "y": 8,
      "z": 6,
      "name": "Empty"
    },
    {
      "x": 8,
      "y": 9,
      "z": 6,
      "name": "Soil_Clay"
    },
    {
      "x": 8,
      "y": 1,
      "z": 7,
      "name": "Empty"
    },
    {
      "x": 8,
      "y": 2,
      "z": 7,
      "name": "Empty"
    },
    {
      "x": 8,
      "y": 3,
      "z": 7,
      "name": "Empty"
    },
    {
      "x": 8,
      "y": 4,
      "z": 7,
      "name": "Wood_Hardwood_Planks_Half",
      "rotation": 8
    },
    {
      "x": 8,
      "y": 5,
      "z": 7,
      "name": "Empty"
    },
    {
      "x": 8,
      "y": 6,
      "z": 7,
      "name": "Empty"
    },
    {
      "x": 8,
      "y": 7,
      "z": 7,
      "name": "Empty"
    },
    {
      "x": 8,
      "y": 8,
      "z": 7,
      "name": "Empty"
    },
    {
      "x": 8,
      "y": 9,
      "z": 7,
      "name": "Soil_Clay"
    },
    {
      "x": 8,
      "y": 1,
      "z": 8,
      "name": "Empty"
    },
    {
      "x": 8,
      "y": 2,
      "z": 8,
      "name": "Empty"
    },
    {
      "x": 8,
      "y": 3,
      "z": 8,
      "name": "Empty"
    },
    {
      "x": 8,
      "y": 4,
      "z": 8,
      "name": "Wood_Hardwood_Planks_Half",
      "rotation": 8
    },
    {
      "x": 8,
      "y": 5,
      "z": 8,
      "name": "Empty"
    },
    {
      "x": 8,
      "y": 6,
      "z": 8,
      "name": "Empty"
    },
    {
      "x": 8,
      "y": 7,
      "z": 8,
      "name": "Empty"
    },
    {
      "x": 8,
      "y": 8,
      "z": 8,
      "name": "Empty"
    },
    {
      "x": 8,
      "y": 9,
      "z": 8,
      "name": "Soil_Clay"
    },
    {
      "x": 8,
      "y": 1,
      "z": 9,
      "name": "Soil_Clay"
    },
    {
      "x": 8,
      "y": 2,
      "z": 9,
      "name": "Soil_Clay"
    },
    {
      "x": 8,
      "y": 3,
      "z": 9,
      "name": "Soil_Clay"
    },
    {
      "x": 8,
      "y": 4,
      "z": 9,
      "name": "Soil_Clay"
    },
    {
      "x": 8,
      "y": 5,
      "z": 9,
      "name": "Soil_Clay"
    },
    {
      "x": 8,
      "y": 6,
      "z": 9,
      "name": "Soil_Clay"
    },
    {
      "x": 8,
      "y": 7,
      "z": 9,
      "name": "Soil_Clay"
    },
    {
      "x": 8,
      "y": 8,
      "z": 9,
      "name": "Soil_Clay"
    },
    {
      "x": 8,
      "y": 9,
      "z": 9,
      "name": "Soil_Clay"
    },
    {
      "x": 9,
      "y": 1,
      "z": 1,
      "name": "Soil_Clay"
    },
    {
      "x": 9,
      "y": 2,
      "z": 1,
      "name": "Soil_Clay"
    },
    {
      "x": 9,
      "y": 3,
      "z": 1,
      "name": "Soil_Clay"
    },
    {
      "x": 9,
      "y": 4,
      "z": 1,
      "name": "Soil_Clay"
    },
    {
      "x": 9,
      "y": 5,
      "z": 1,
      "name": "Soil_Clay"
    },
    {
      "x": 9,
      "y": 6,
      "z": 1,
      "name": "Soil_Clay"
    },
    {
      "x": 9,
      "y": 7,
      "z": 1,
      "name": "Soil_Clay"
    },
    {
      "x": 9,
      "y": 8,
      "z": 1,
      "name": "Soil_Clay"
    },
    {
      "x": 9,
      "y": 9,
      "z": 1,
      "name": "Soil_Clay"
    },
    {
      "x": 9,
      "y": 1,
      "z": 2,
      "name": "Soil_Clay"
    },
    {
      "x": 9,
      "y": 2,
      "z": 2,
      "name": "Soil_Clay"
    },
    {
      "x": 9,
      "y": 3,
      "z": 2,
      "name": "Soil_Clay"
    },
    {
      "x": 9,
      "y": 4,
      "z": 2,
      "name": "Soil_Clay"
    },
    {
      "x": 9,
      "y": 5,
      "z": 2,
      "name": "Soil_Clay"
    },
    {
      "x": 9,
      "y": 6,
      "z": 2,
      "name": "Soil_Clay"
    },
    {
      "x": 9,
      "y": 7,
      "z": 2,
      "name": "Soil_Clay"
    },
    {
      "x": 9,
      "y": 8,
      "z": 2,
      "name": "Soil_Clay"
    },
    {
      "x": 9,
      "y": 9,
      "z": 2,
      "name": "Soil_Clay"
    },
    {
      "x": 9,
      "y": 1,
      "z": 3,
      "name": "Soil_Clay"
    },
    {
      "x": 9,
      "y": 2,
      "z": 3,
      "name": "Soil_Clay"
    },
    {
      "x": 9,
      "y": 3,
      "z": 3,
      "name": "Soil_Clay"
    },
    {
      "x": 9,
      "y": 4,
      "z": 3,
      "name": "Soil_Clay"
    },
    {
      "x": 9,
      "y": 5,
      "z": 3,
      "name": "Soil_Clay"
    },
    {
      "x": 9,
      "y": 6,
      "z": 3,
      "name": "Soil_Clay"
    },
    {
      "x": 9,
      "y": 7,
      "z": 3,
      "name": "Soil_Clay"
    },
    {
      "x": 9,
      "y": 8,
      "z": 3,
      "name": "Soil_Clay"
    },
    {
      "x": 9,
      "y": 9,
      "z": 3,
      "name": "Soil_Clay"
    },
    {
      "x": 9,
      "y": 1,
      "z": 4,
      "name": "Soil_Clay"
    },
    {
      "x": 9,
      "y": 2,
      "z": 4,
      "name": "Soil_Clay"
    },
    {
      "x": 9,
      "y": 3,
      "z": 4,
      "name": "Soil_Clay"
    },
    {
      "x": 9,
      "y": 4,
      "z": 4,
      "name": "Soil_Clay"
    },
    {
      "x": 9,
      "y": 5,
      "z": 4,
      "name": "Soil_Clay"
    },
    {
      "x": 9,
      "y": 6,
      "z": 4,
      "name": "Soil_Clay"
    },
    {
      "x": 9,
      "y": 7,
      "z": 4,
      "name": "Soil_Clay"
    },
    {
      "x": 9,
      "y": 8,
      "z": 4,
      "name": "Soil_Clay"
    },
    {
      "x": 9,
      "y": 9,
      "z": 4,
      "name": "Soil_Clay"
    },
    {
      "x": 9,
      "y": 1,
      "z": 5,
      "name": "Soil_Clay"
    },
    {
      "x": 9,
      "y": 2,
      "z": 5,
      "name": "Soil_Clay"
    },
    {
      "x": 9,
      "y": 3,
      "z": 5,
      "name": "Soil_Clay"
    },
    {
      "x": 9,
      "y": 4,
      "z": 5,
      "name": "Soil_Clay"
    },
    {
      "x": 9,
      "y": 5,
      "z": 5,
      "name": "Soil_Clay"
    },
    {
      "x": 9,
      "y": 6,
      "z": 5,
      "name": "Soil_Clay"
    },
    {
      "x": 9,
      "y": 7,
      "z": 5,
      "name": "Soil_Clay"
    },
    {
      "x": 9,
      "y": 8,
      "z": 5,
      "name": "Soil_Clay"
    },
    {
      "x": 9,
      "y": 9,
      "z": 5,
      "name": "Soil_Clay"
    },
    {
      "x": 9,
      "y": 1,
      "z": 6,
      "name": "Soil_Clay"
    },
    {
      "x": 9,
      "y": 2,
      "z": 6,
      "name": "Soil_Clay"
    },
    {
      "x": 9,
      "y": 3,
      "z": 6,
      "name": "Soil_Clay"
    },
    {
      "x": 9,
      "y": 4,
      "z": 6,
      "name": "Soil_Clay"
    },
    {
      "x": 9,
      "y": 5,
      "z": 6,
      "name": "Soil_Clay"
    },
    {
      "x": 9,
      "y": 6,
      "z": 6,
      "name": "Soil_Clay"
    },
    {
      "x": 9,
      "y": 7,
      "z": 6,
      "name": "Soil_Clay"
    },
    {
      "x": 9,
      "y": 8,
      "z": 6,
      "name": "Soil_Clay"
    },
    {
      "x": 9,
      "y": 9,
      "z": 6,
      "name": "Soil_Clay"
    },
    {
      "x": 9,
      "y": 1,
      "z": 7,
      "name": "Soil_Clay"
    },
    {
      "x": 9,
      "y": 2,
      "z": 7,
      "name": "Soil_Clay"
    },
    {
      "x": 9,
      "y": 3,
      "z": 7,
      "name": "Soil_Clay"
    },
    {
      "x": 9,
      "y": 4,
      "z": 7,
      "name": "Soil_Clay"
    },
    {
      "x": 9,
      "y": 5,
      "z": 7,
      "name": "Soil_Clay"
    },
    {
      "x": 9,
      "y": 6,
      "z": 7,
      "name": "Soil_Clay"
    },
    {
      "x": 9,
      "y": 7,
      "z": 7,
      "name": "Soil_Clay"
    },
    {
      "x": 9,
      "y": 8,
      "z": 7,
      "name": "Soil_Clay"
    },
    {
      "x": 9,
      "y": 9,
      "z": 7,
      "name": "Soil_Clay"
    },
    {
      "x": 9,
      "y": 1,
      "z": 8,
      "name": "Soil_Clay"
    },
    {
      "x": 9,
      "y": 2,
      "z": 8,
      "name": "Soil_Clay"
    },
    {
      "x": 9,
      "y": 3,
      "z": 8,
      "name": "Soil_Clay"
    },
    {
      "x": 9,
      "y": 4,
      "z": 8,
      "name": "Soil_Clay"
    },
    {
      "x": 9,
      "y": 5,
      "z": 8,
      "name": "Soil_Clay"
    },
    {
      "x": 9,
      "y": 6,
      "z": 8,
      "name": "Soil_Clay"
    },
    {
      "x": 9,
      "y": 7,
      "z": 8,
      "name": "Soil_Clay"
    },
    {
      "x": 9,
      "y": 8,
      "z": 8,
      "name": "Soil_Clay"
    },
    {
      "x": 9,
      "y": 9,
      "z": 8,
      "name": "Soil_Clay"
    },
    {
      "x": 9,
      "y": 1,
      "z": 9,
      "name": "Soil_Clay"
    },
    {
      "x": 9,
      "y": 2,
      "z": 9,
      "name": "Soil_Clay"
    },
    {
      "x": 9,
      "y": 3,
      "z": 9,
      "name": "Soil_Clay"
    },
    {
      "x": 9,
      "y": 4,
      "z": 9,
      "name": "Soil_Clay"
    },
    {
      "x": 9,
      "y": 5,
      "z": 9,
      "name": "Soil_Clay"
    },
    {
      "x": 9,
      "y": 6,
      "z": 9,
      "name": "Soil_Clay"
    },
    {
      "x": 9,
      "y": 7,
      "z": 9,
      "name": "Soil_Clay"
    },
    {
      "x": 9,
      "y": 8,
      "z": 9,
      "name": "Soil_Clay"
    },
    {
      "x": 9,
      "y": 9,
      "z": 9,
      "name": "Soil_Clay"
    }
  ]
}